File: HeatCapacity/ML_PPMS_20200818_2_MKS-Bi2WO6-oxidized LDFZ xtal_4.99 mg-HC-2-300K_0T.dat
[Header]
TITLE,ML_PPMS_20200818_2_MKS-Bi2WO6-oxidized LDFZ xtal_4.99 mg-HC-2-300K_0T.dat
BYAPP,HeatCapacity,3.9.6,1.7
INFO,4.99,MASS:Sample Mass (mg)
INFO,0.2,MASSERR:Sample Mass Error (mg)
INFO,,MOLWGHT:Formula Weight (g/mole)
INFO,,ATOMS:Atoms per Formula Unit
INFO,PPMS Heat Capacity Option 3.9.6 Build 3,APPNAME
DATATYPE,TIME,1
DATATYPE,COMMENT,2
STARTUPAXIS, X, 8, LINEAR, AUTO
STARTUPAXIS, Y1, 10, LINEAR, AUTO
[Data]
Time Stamp (Seconds),Comment (),System Status (Code),Puck Temp (Kelvin),System Temp (Kelvin),Field (Oersted),Pressure (Torr),Sample Temp (Kelvin),Temp Rise (Kelvin),Samp HC (µJ/K),Samp HC Err (µJ/K),Addenda HC (µJ/K),Addenda HC Err (µJ/K),Total HC (µJ/K),Total HC Err (µJ/K),Fit Deviation (ChiSquare),Time Const tau1 (seconds),Time Const tau2 (seconds),Sample Coupling (Percent),Debye Temp (Kelvin),Debye Temp Err (Kelvin),Cal Correction (Factor),Therm Resist (Ohms),Htr Resist (Ohms),Puck Resist (Ohms),Wire Cond (W/K),Meas Time (seconds),Temp Squared (K^2),Samp HC/Temp (µJ/K/K),Addenda Offset HC (µJ/K)
19978769.36,CALFILE: C:\QdPpms\HEATCA~1\TempCal\Standard\Puck1010_1.cal|Addenda #61 measured on 8/17/2020 from 2.0477 to 301.56 K
19978769.59,,5905,,2.0019,0.056,9.3E-6,2.0423547,0.020697717,0.033897742,0.002552,0.16960271,0.001262,0.20350045,0.002218,0.13030535,0.12419365,,,,,1,,,,1.6385737E-6,0.32172555,4.1712128,0.016597382,0
19978818.3,,5905,,2.0014,0.056,9.4E-6,2.0436496,0.022371322,0.033346188,0.00263,0.16979321,0.001271,0.2031394,0.002302,0.11099046,0.12334549,,,,,1,,,,1.6469139E-6,0.37651018,4.1765037,0.016316979,0
19978968.11,,5905,,2.1512,0.056,9.4E-6,2.1932468,0.023015356,0.037966593,0.002489,0.20142151,0.001974,0.2393881,0.001515,2.486261,0.12984252,,,,,1,,,,1.8436803E-6,0.38563601,4.8103316,0.01731068,0
19979124.8,,5905,,2.316,0.056,9.3E-6,2.3571724,0.026185532,0.040094041,0.002682,0.23983985,0.001593,0.27993389,0.002682,0.056996605,0.13477031,0.00057524782,96.633929,,,1,,,,2.0786091E-6,0.38255487,5.5562618,0.01700938,0
19979162.53,,5905,,2.3166,0.056,9.3E-6,2.3566682,0.025053018,0.049479448,0.001588,0.24008631,0.001588,0.28956576,0,0.50246377,0.14596557,,,,,1,,,,1.983795E-6,0.43724776,5.5538852,0.020995508,0
19979322.5,,5905,,2.4936,0.056,9.4E-6,2.5302042,0.02639452,0.065545268,0.005281,0.28645708,0.001006,0.35200235,0.005184,0.1066947,0.16639131,,,,,1,,,,2.1155093E-6,0.46069993,6.4019333,0.025905129,0
19979482.55,,5905,,2.6798,0.056,9.3E-6,2.7392417,0.026684655,0.079206315,0.002063,0.34998097,0.001603,0.42918729,0.001299,1.8955932,0.18055927,,,,,1,,,,2.3769884E-6,0.46301514,7.5034453,0.028915416,0
19979518.92,,5905,,2.6781,0.056,9.3E-6,2.7422833,0.031234067,0.065818543,0.001678,0.35035655,0.001608,0.41617509,0.001678,8.6471502,0.16762132,0.00047144558,97.929057,,,1,,,,2.4841461E-6,0.54686903,7.5201175,0.024001365,0
19979687.78,,5905,,2.8841,0.056,9.4E-6,2.9443021,0.033435535,0.094542496,0.002424,0.41904508,0.0024,0.51358757,0.002424,1.6942346,0.20308889,0.0040737281,88.121328,,,1,,,,2.5406699E-6,0.62725919,8.6689148,0.032110325,0
19979850.41,,5905,,3.1024,0.056,9.3E-6,3.157801,0.032832371,0.13375812,0.004353,0.50092347,0.002269,0.63468159,0.004353,0.018217158,0.23822792,0.0083000053,82.399343,,,1,,,,2.6903751E-6,0.61300493,9.9717073,0.042357996,0
19979891.22,,5905,,3.1041,0.056,9.4E-6,3.1605694,0.034493452,0.12255042,0.002444,0.50195017,0.00226,0.62450058,0.002444,0.45990331,0.23450946,0.00722642,83.440277,,,1,,,,2.6840128E-6,0.65958926,9.9891986,0.038774791,0
19980067.98,,5905,,3.3394,0.056,9.3E-6,3.3938959,0.035505335,0.16037813,0.003069,0.60801963,0.001275,0.76839776,0.002791,2.3265127,0.25961656,,,,,1,,,,2.959741E-6,0.74761615,11.518529,0.047254876,0
19980224.66,,5905,,3.5925,0.056,9.4E-6,3.6077943,0.034208912,0.1854023,0.003615,0.72521534,0.001945,0.91061764,0.003047,0.79970705,0.2750716,,,,,1,,,,3.3104749E-6,0.70679221,13.016179,0.051389378,0
19980264.7,,5905,,3.5887,0.056,9.3E-6,3.6095584,0.036669353,0.1964777,0.003421,0.72599759,0.001953,0.92247529,0.002809,1.9658121,0.27428889,,,,,1,,,,3.3631522E-6,0.84543383,13.028912,0.054432614,0
19980440.11,,5905,,3.8655,0.056,9.3E-6,3.8837998,0.039975354,0.35753496,0.008756,0.89262278,0.003198,1.2501577,0.008151,1.2512989,0.34626857,,,,,1,,,,3.6103703E-6,1.0562673,15.083901,0.09205803,0
19980616.58,,5905,,4.1561,0.056,9.4E-6,4.1823241,0.040663407,0.37701678,0.007906,1.0933156,0.00259,1.4703324,0.007469,0.21147447,0.36704017,,,,,1,,,,4.0059169E-6,1.016923,17.491835,0.090145281,0
19980660.13,,5905,,4.1577,0.056,9.3E-6,4.1830297,0.042334388,0.36606361,0.004117,1.0931509,0.002591,1.4592145,0.004117,0.34217865,0.35615605,0.004051133,94.25103,,,1,,,,4.1130303E-6,1.0664086,17.497738,0.087511598,0
19980827.58,,5905,,4.4711,0.056,9.4E-6,4.5007399,0.045408954,0.49425146,0.009492,1.3687949,0.002812,1.8630463,0.009066,0.45457646,0.43053455,,,,,1,,,,4.3272864E-6,1.2497111,20.256659,0.1098156,0
19980999.08,,5905,,4.8148,0.056,9.3E-6,4.8373429,0.047829594,0.55991238,0.01046,1.6920007,0.003522,2.2519131,0.009851,4.29385,0.48158056,,,,,1,,,,4.6760881E-6,1.3018014,23.399886,0.11574792,0
19981040.77,,5905,,4.815,0.056,9.3E-6,4.8382754,0.049403557,0.51910285,0.004959,1.6917349,0.003522,2.2108377,0.004959,0.11128646,0.44943094,0.0040727588,95.172599,,,1,,,,4.9330754E-6,1.3940633,23.408909,0.10729089,0
19981213.91,,5905,,5.1781,0.056,9.4E-6,5.2052078,0.053871275,0.69413813,0.009344,2.046754,0.003626,2.7408921,0.008612,0.30566195,0.54311999,,,,,1,,,,5.0465682E-6,1.5602874,27.094188,0.13335455,0
19981403.41,,5905,,5.5719,0.056,9.3E-6,5.5999049,0.055556598,0.83321353,0.005301,2.4777509,0.004531,3.3109644,0.005301,1.1501496,0.58584335,0.0054891129,95.231599,,,1,,,,5.669712E-6,1.5576057,31.358935,0.14879066,0
19981447.69,,5905,,5.5718,0.056,9.4E-6,5.601635,0.058640102,0.79657525,0.005294,2.4788696,0.004534,3.2754449,0.005294,0.82940045,0.56529425,0.0042791403,96.030919,,,1,,,,5.8085023E-6,1.7824014,31.378315,0.14220406,0
19981626.14,,5905,,5.9935,0.056,9.3E-6,6.0287506,0.061379562,1.1844701,0.01505,3.0174346,0.006246,4.2019047,0.0137,0.31077941,0.67242753,,,,,1,,,,6.2488588E-6,1.9733031,36.345834,0.19647025,0
19981808.77,,5905,,6.4487,0.056,9.4E-6,6.4795179,0.065209015,1.4772786,0.009025,3.6520131,0.007494,5.1292917,0.009025,1.0445294,0.7537034,0.0019776536,98.733917,,,1,,,,6.812709E-6,2.0394537,41.984152,0.22799206,0
19981859.81,,5905,,6.4508,0.056,9.3E-6,6.4808846,0.066744463,1.4742761,0.0161,3.6546547,0.007496,5.1289308,0.01424,0.32178646,0.72678176,,,,,1,,,,7.0570439E-6,2.3338751,42.001865,0.2274807,0
19982046.41,,5905,,6.9376,0.056,9.3E-6,6.9763154,0.071202157,2.0752029,0.02063,4.4253673,0.007074,6.5005702,0.01938,1.1537429,0.87586435,,,,,1,,,,7.4218915E-6,2.5145118,48.668976,0.29746403,0
19982234.77,,5905,,7.4657,0.056,9.2E-6,7.5067137,0.075755514,2.6478365,0.01105,5.3562483,0.00719,8.0040848,0.01105,0.38942845,0.96837523,0.0021526384,99.003658,,,1,,,,8.2746019E-6,2.6248745,56.350751,0.35272911,0
19982283.27,,5905,,7.4675,0.056,9.4E-6,7.5078098,0.077756899,2.7362979,0.008974,5.3585706,0.007193,8.0948685,0.008974,1.862073,0.97055206,0.0022485371,98.972844,,,1,,,,8.350392E-6,2.8861877,56.367208,0.36446021,0
19982476.19,,5905,,8.0336,0.056,9.3E-6,8.073226,0.084671687,3.5946193,0.01167,6.4955605,0.009108,10.09018,0.01167,1.5152218,1.124276,0.0053785199,97.945888,,,1,,,,8.9988268E-6,3.3426246,65.176978,0.44525191,0
19982670.34,,5905,,8.6436,0.056,9.4E-6,8.6904454,0.084504882,4.9206561,0.01854,7.865615,0.01163,12.786271,0.01854,0.20616595,1.2961999,0.0071406686,97.710369,,,1,,,,9.8988523E-6,3.3145688,75.523842,0.56621449,0
19982724.33,,5905,,8.644,0.056,9.4E-6,8.6949032,0.091488112,5.0531387,0.01879,7.8706728,0.01164,12.923811,0.01879,0.32822387,1.2962392,0.0022340677,99.279814,,,1,,,,9.9813127E-6,3.9084204,75.601342,0.581161,0
19982926.33,,5905,,9.2997,0.056,9.2E-6,9.3493325,0.098061995,6.7039924,0.01943,9.4731309,0.01493,16.177123,0.01943,0.5110806,1.5012631,0.0076223348,97.93603,,,1,,,,1.0814875E-5,4.4239709,87.410019,0.71705572,0
19983133.05,,5905,,10.0041,0.056,9.4E-6,10.054706,0.098943097,8.9808544,0.02595,11.397331,0.0202,20.378185,0.02595,1.3705008,1.7234118,0.0087862138,97.957374,,,1,,,,1.1872462E-5,4.4813367,101.09711,0.8931991,0
19983188.59,,5905,,10.0046,0.056,9.2E-6,10.058281,0.10631509,9.0177398,0.02627,11.403,0.02022,20.42074,0.02627,2.0083702,1.743671,0.0090679546,97.917689,,,1,,,,1.1760171E-5,5.1057316,101.16901,0.89654882,0
19983521,,5905,,10.7662,0.056,9.3E-6,10.845501,0.10890532,11.318302,0.08824,13.817776,0.02643,25.136079,0.08419,1.6795538,1.8318972,,,,,1,,,,1.3721337E-5,5.7080622,117.62489,1.0435942,0
19983737.77,,5905,,11.5841,0.056,9.4E-6,11.656949,0.1163144,15.132515,0.03399,16.536755,0.02445,31.66927,0.03399,1.8210952,2.2535856,0.01111278,98.044523,,,1,,,,1.4117149E-5,5.8113504,135.88446,1.298154,0
19983798.08,,5905,,11.584,0.056,9.4E-6,11.661508,0.12327161,15.168466,0.03479,16.554216,0.02442,31.722683,0.03479,1.0029773,2.244565,0.010527447,98.139207,,,1,,,,1.4194668E-5,6.6765411,135.99078,1.3007294,0
19984024.59,,5905,,12.4634,0.056,9.3E-6,12.546863,0.1330405,19.761242,0.04175,19.831486,0.02811,39.592728,0.04175,1.348948,2.5863793,0.014115133,97.840458,,,1,,,,1.5392803E-5,7.6463439,157.42376,1.5749947,0
19984263.25,,5905,,13.4077,0.056,9.3E-6,13.5086,0.13423456,24.800313,0.06786,23.804327,0.05233,48.60464,0.06786,1.2326082,2.8869463,0.01308422,98.20187,,,1,,,,1.6916631E-5,7.6082148,182.48228,1.8358907,0
19984341.59,,5905,,13.4068,0.056,9.3E-6,13.513959,0.14305217,24.737386,0.06445,23.821722,0.05243,48.559109,0.06445,1.4312549,2.872134,0.011558851,98.40193,,,1,,,,1.6978524E-5,8.6353191,182.6271,1.8305062,0
19984593.75,,5905,,14.4262,0.056,9.2E-6,14.530886,0.15526469,30.915263,0.07851,28.398913,0.06612,59.314175,0.07851,1.0903644,3.2514125,0.013469815,98.352304,,,1,,,,1.8325959E-5,9.8520671,211.14664,2.1275553,0
19984853.06,,5905,,15.521,0.056,9.3E-6,15.633069,0.15667656,38.342048,0.09623,33.917934,0.07371,72.259982,0.09623,1.0483201,3.6435012,0.016819108,98.161323,,,1,,,,1.9937647E-5,9.7222871,244.39284,2.4526245,0
19984942.92,,5905,,15.5213,0.056,9.3E-6,15.638567,0.16586894,38.327429,0.0954,33.941958,0.07376,72.269388,0.0954,2.0459397,3.6486635,0.017355052,98.106017,,,1,,,,1.9915152E-5,10.873116,244.56479,2.4508274,0
19985211.31,,5905,,16.6971,0.056,9.4E-6,16.832545,0.18043172,46.692606,0.1157,40.648133,0.0886,87.340739,0.1157,1.3833481,4.0750744,0.017431536,98.293183,,,1,,,,2.1539745E-5,12.2651,283.33458,2.773948,0
19985486.61,,5905,,17.9672,0.056,9.4E-6,18.106756,0.18428826,56.939771,0.1093,48.463167,0.09303,105.40294,0.1093,0.76008577,4.5778925,0.023127057,97.982971,,,1,,,,2.316336E-5,12.229255,327.85462,3.1446699,0
19985584.67,,5905,,17.9662,0.056,9.4E-6,18.113332,0.19351651,56.898988,0.1134,48.498685,0.09303,105.39767,0.1134,3.0742847,4.5568599,0.021968296,98.074717,,,1,,,,2.3262424E-5,13.544543,328.0928,3.1412767,0
19985872.94,,5905,,19.3313,0.056,9.4E-6,19.478074,0.20951397,67.448384,0.1217,57.497965,0.09797,124.94635,0.1217,1.6263956,5.0018343,0.022099073,98.234413,,,1,,,,2.5111522E-5,15.110902,379.39539,3.462785,0
19986173.97,,5905,,20.7979,0.056,9.2E-6,20.942618,0.21337181,79.85915,0.1443,67.839615,0.1222,147.69876,0.1443,1.8161244,5.4887533,0.025966678,98.109823,,,1,,,,2.7061633E-5,14.982166,438.59326,3.8132362,0
19986300.94,,5905,,20.7982,0.056,9.2E-6,20.952545,0.22679652,79.786197,0.1394,67.899092,0.1224,147.68529,0.1394,1.5866817,5.5381555,0.027309989,98.030734,,,1,,,,2.6824001E-5,16.7408,439.00915,3.8079477,0
19986628.47,,5905,,22.3766,0.056,9.4E-6,22.542793,0.24434975,93.618901,0.1851,79.879951,0.1678,173.49885,0.1851,2.2127938,6.0783902,0.029024424,98.093085,,,1,,,,2.8705893E-5,18.281659,508.1775,4.1529416,0
19986963.97,,5905,,24.0755,0.056,9.2E-6,24.241786,0.25180033,108.33461,0.2356,93.621493,0.2098,201.95611,0.2356,1.0303586,6.6708753,0.036871554,97.797833,,,1,,,,3.0471564E-5,18.22536,587.66419,4.4689204,0
19987108.13,,5905,,24.0748,0.056,9.3E-6,24.250898,0.26410873,108.38849,0.2273,93.679453,0.2099,202.06795,0.2273,0.92920765,6.6475806,0.033274878,98.003982,,,1,,,,3.0576244E-5,19.961673,588.10608,4.4694631,0
19987459.2,,5905,,25.903,0.056,9.3E-6,26.094815,0.28548923,124.78063,0.2607,109.64007,0.2391,234.4207,0.2607,1.6073207,7.2430525,0.037659587,97.930055,,,1,,,,3.2559752E-5,21.881524,680.93938,4.7818169,0
19987821.72,,5905,,27.8701,0.056,9.2E-6,28.061419,0.29416235,142.68131,0.3087,127.75172,0.2752,270.43304,0.3087,0.78956988,7.9423849,0.05173659,97.415987,,,1,,,,3.4302423E-5,21.735263,787.44321,5.084608,0
19987984.55,,5905,,27.8699,0.056,9.2E-6,28.073186,0.30665225,142.41378,0.2981,127.84117,0.2754,270.25495,0.2981,0.81676702,7.8656557,0.044546623,97.75049,,,1,,,,3.4579682E-5,23.64969,788.10379,5.0729467,0
19988361.67,,5905,,29.9871,0.056,9.3E-6,30.203114,0.33167002,161.53174,0.3562,148.7337,0.3294,310.26544,0.3562,0.82122213,8.5761181,0.051239517,97.631729,,,1,,,,3.6417146E-5,25.848499,912.2281,5.3481818,0
19988753.28,,5905,,32.2635,0.056,9.4E-6,32.47789,0.3405144,182.65329,0.4983,172.5463,0.3994,355.1996,0.4983,0.33939978,9.3224088,0.06248842,97.349727,,,1,,,,3.8377852E-5,25.712282,1054.8133,5.6239274,0
19988934.72,,5905,,32.2644,0.056,9.3E-6,32.495603,0.35359607,181.13821,0.4309,172.72737,0.3999,353.86558,0.4309,1.0506088,9.2252636,0.0576404,97.528448,,,1,,,,3.8614636E-5,27.701126,1055.9642,5.5742374,0
19989351.73,,5905,,34.7131,0.056,9.2E-6,34.960893,0.38214658,203.38873,0.5188,200.16301,0.475,403.55174,0.5188,2.1863472,10.003758,0.068938742,97.279799,,,1,,,,4.0628546E-5,30.510682,1222.264,5.8176069,0
19989802.28,,5905,,37.3459,0.056,9.3E-6,37.592126,0.39086921,225.32132,0.6636,231.3794,0.5397,456.70073,0.6636,0.43994323,10.956002,0.094793177,96.598197,,,1,,,,4.2045451E-5,29.714365,1413.168,5.9938435,0
19990004.78,,5905,,37.3473,0.056,9.2E-6,37.616535,0.40623082,224.2741,0.5793,231.62241,0.5401,455.89651,0.5793,0.35280965,10.676103,0.070052942,97.409421,,,1,,,,4.2979187E-5,32.392626,1415.0037,5.9621148,0
19990493.53,,5905,,40.1846,0.056,9.2E-6,40.460716,0.43906755,248.28894,0.6301,267.58516,0.5959,515.8741,0.6301,1.180294,11.547488,0.082888786,97.168043,,,1,,,,4.4977947E-5,35.504529,1637.0695,6.1365434,0
19991021.83,,5905,,43.2352,0.056,9.3E-6,43.508424,0.44762875,274.82298,0.8341,309.03956,0.6589,583.86254,0.8341,0.27863663,12.630618,0.11415756,96.443365,,,1,,,,4.6607133E-5,34.495965,1892.9829,6.3165464,0
19991249.25,,5905,,43.2332,0.056,9.3E-6,43.537504,0.46527954,272.65115,0.7063,309.39176,0.6595,582.04291,0.7063,0.62903029,12.36247,0.092295955,97.050917,,,1,,,,4.7397756E-5,37.40526,1895.5142,6.2624434,0
19991810.69,,5905,,46.5154,0.056,9.4E-6,46.829902,0.50475059,299.088,0.7996,358.03293,0.7452,657.12093,0.7996,1.4033685,13.426409,0.11680608,96.561893,,,1,,,,4.930661E-5,41.118236,2193.0397,6.3866886,0
19992407.61,,5905,,50.0476,0.056,9.2E-6,50.349469,0.51471813,328.54375,1.069,415.41514,0.8022,743.95889,1.069,0.34672437,14.755641,0.15708997,95.792416,,,1,,,,5.0855195E-5,39.987689,2535.0691,6.5252674,0
19992660.47,,5905,,50.0471,0.056,9.4E-6,50.392605,0.53481775,324.42184,0.845,416.06817,0.8024,740.49001,0.845,0.25726245,14.301681,0.11101302,96.906492,,,1,,,,5.2096187E-5,43.284012,2539.4146,6.4378859,0
19993307.23,,5905,,53.8469,0.056,9.3E-6,54.202338,0.57745855,354.74043,0.8563,484.45465,0.8056,839.19508,0.8563,3.1399907,15.53443,0.13586244,96.496167,,,1,,,,5.4375241E-5,47.6192,2937.8935,6.544744,0
19994007.91,,5905,,57.9333,0.056,9.3E-6,58.273363,0.58720684,384.92075,1.215,563.54001,0.8612,948.46076,1.215,0.26924838,17.046895,0.19225476,95.464105,,,1,,,,5.6078749E-5,46.291356,3395.7848,6.6054322,0
19994295.48,,5905,,57.9328,0.056,9.3E-6,58.321105,0.61086504,381.60922,0.9124,564.38271,0.862,945.99192,0.9124,0.26712907,16.592308,0.13756641,96.63283,,,1,,,,5.7339885E-5,50.177731,3401.3513,6.5432439,0
19995066.28,,5905,,62.334,0.056,9.4E-6,62.727529,0.66124762,413.99608,0.9878,658.39755,0.9228,1072.3936,0.9878,2.5867973,18.057134,0.16245871,96.302096,,,1,,,,5.9731887E-5,55.369865,3934.7428,6.5999106,0
19995889.75,,5905,,67.0675,0.056,9.4E-6,67.444424,0.66940841,447.72356,1.354,770.39417,0.9368,1218.1177,1.354,0.39903208,19.88854,0.24590809,94.878653,,,1,,,,6.1699474E-5,53.773418,4548.7503,6.6384074,0
19996218,,5905,,67.0718,0.056,9.4E-6,67.497392,0.69958074,442.83556,1.014,771.53475,0.9369,1214.3703,1.014,0.39912559,19.38646,0.17406229,96.231401,,,1,,,,6.2969309E-5,58.519884,4555.898,6.5607802,0
19997093.63,,5905,,72.1578,0.056,9.3E-6,72.602182,0.75018454,478.68602,1.07,904.35195,0.9809,1383.038,1.07,3.488305,21.131473,0.20449066,95.858274,,,1,,,,6.5791282E-5,63.420205,5271.0768,6.5932732,0
19998030.22,,5905,,77.6363,0.056,9.2E-6,78.049789,0.75468108,522.85005,3.501,1057.2918,1.033,1580.1418,3.345,0.54817849,22.865165,,,,,1,,,,6.910695E-5,62.834792,6091.7695,6.6989298,0
19998401.58,,5905,,77.6375,0.056,9.2E-6,78.117945,0.80438082,509.98379,1.17,1059.0178,1.034,1569.0016,1.17,0.19682013,22.656545,0.18344575,96.413477,,,1,,,,6.9525979E-5,68.623736,6102.4133,6.5283821,0
19999408.14,,5905,,83.5299,0.056,9.3E-6,84.025359,0.87166049,550.81143,1.204,1239.0588,1.102,1789.8702,1.204,2.5257052,24.7199,0.24105297,95.585965,,,1,,,,7.2725828E-5,75.784619,7060.261,6.5552999,0
20000458.45,,5905,,89.8714,0.056,9.2E-6,90.302096,0.86724341,603.52676,4.495,1451.0053,1.237,2054.5321,4.321,0.43710247,26.817805,,,,,1,,,,7.6610746E-5,73.434696,8154.4686,6.6834192,0
20000885.23,,5905,,89.8721,0.056,9.3E-6,90.379868,0.92490403,586.52612,1.426,1453.3631,1.239,2039.8892,1.426,0.24635162,26.480558,0.20504342,96.335577,,,1,,,,7.7277612E-5,80.063151,8168.5206,6.489566,0
20002013.95,,5905,,96.6947,0.056,9.3E-6,97.194344,0.99703517,631.83097,1.401,1700.2887,1.262,2332.1197,1.401,1.5786566,28.826516,0.27837271,95.306469,,,1,,,,8.1197193E-5,87.170899,9446.7406,6.5006969,0
20003184.59,,5905,,104.036,0.056,9.2E-6,104.48382,1.0039944,685.6301,5.119,1978.0648,1.211,2663.6949,4.974,0.33392854,31.182151,,,,,1,,,,8.5423708E-5,85.91889,10916.868,6.5620697,0
20003668.8,,5905,,104.039,0.056,9.4E-6,104.56697,1.0642966,666.17895,1.531,1980.8288,1.211,2647.0078,1.531,0.097433068,30.680098,0.23840051,96.017373,,,1,,,,8.650613E-5,92.50871,10934.252,6.3708352,0
20004922.92,,5905,,111.938,0.056,9.4E-6,112.47699,1.130774,720.86339,3.053,2295.8572,1.336,3016.7206,2.745,1.5431895,32.968901,,,,,1,,,,9.1502007E-5,100.30216,12651.073,6.4089855,0
20006223.66,,5905,,120.433,0.056,9.3E-6,120.93118,1.153106,778.34456,6.48,2649.6732,1.476,3428.0178,6.31,0.34761136,35.709999,,,,,1,,,,9.599602E-5,98.200542,14624.351,6.4362603,0
20006770.86,,5905,,120.434,0.056,9.3E-6,121.01513,1.1990335,761.15269,2.733,2653.0239,1.477,3414.1766,2.3,0.1813639,34.912709,,,,,1,,,,9.7791797E-5,105.11364,14644.661,6.2897317,0
20008155.39,,5905,,129.585,0.056,9.2E-6,130.18683,1.3151445,811.96823,1.96,3049.4528,1.595,3861.4211,1.96,0.59600992,37.660584,0.42542829,93.59416,,,1,,,,0.00010284601,113.49251,16948.612,6.2369459,0
20009602.61,,5905,,139.414,0.056,9.3E-6,139.98572,1.350981,864.93033,3.866,3478.7078,1.771,4343.6381,3.866,0.29351839,40.673021,0.86141386,88.163724,,,1,,,,0.00010737495,112.25104,19596.001,6.1787042,0
20010213.22,,5905,,139.416,0.056,9.3E-6,140.09128,1.4049878,842.05075,2.118,3482.6649,1.773,4324.7157,2.118,0.15730809,39.154376,0.28167574,95.598399,,,1,,,,0.00011064713,118.50185,19625.567,6.0107292,0
20011633.81,,5905,,150,0.056,9.3E-6,150.7079,1.5223785,907.88913,2.311,3952.8526,1.908,4860.7417,2.311,0.38467696,41.380459,0.34697119,94.74918,,,1,,,,0.00011769369,126.9511,22712.872,6.0241641,0
20012556.03,,5905,,149.999,0.056,9.4E-6,150.74846,1.5159586,892.47897,2.658,3954.6467,1.909,4847.1256,2.658,0.098242275,41.009165,0.24101123,96.225407,,,1,,,,0.00011835427,123.64099,22725.1,5.9203188,0
20013224.02,,5905,,150,0.056,9.4E-6,150.76079,1.5054922,894.71639,2.082,3955.1754,1.909,4849.8918,2.082,0.44051293,41.081732,0.24306945,96.206241,,,1,,,,0.00011821409,123.22023,22728.814,5.9346758,0
20014311.75,,5905,,152.564,0.056,9.3E-6,153.34408,1.5496378,902.74444,2.25,4069.3716,1.943,4972.116,2.25,0.34050358,41.492821,0.31093785,95.183715,,,1,,,,0.00012003214,128.66493,23514.407,5.8870511,0
20015431.45,,5905,,155.129,0.056,9.2E-6,155.86443,1.5275232,927.40783,4.014,4181.0088,1.985,5108.4166,4.014,0.28975221,43.0168,0.80704285,88.703873,,,1,,,,0.00011926199,123.51538,24293.721,5.9500928,0
20016121.39,,5905,,155.128,0.056,9.3E-6,155.94128,1.55627,913.57754,2.097,4183.8875,1.987,5097.465,2.097,1.2749271,41.923183,0.30355878,95.29429,,,1,,,,0.00012178487,125.85897,24317.682,5.8584716,0
20017222.52,,5905,,157.693,0.056,9.2E-6,158.52468,1.5993708,927.60814,2.474,4296.6692,2.043,5224.2773,2.474,0.15933066,42.293241,0.33780059,94.797,,,1,,,,0.00012374058,130.60311,25130.073,5.8515063,0
20018362.19,,5905,,160.255,0.056,9.3E-6,161.04819,1.5825335,946.6301,4.201,4406.5166,2.113,5353.1467,4.201,0.18690424,43.477972,0.63354873,90.847516,,,1,,,,0.00012351684,126.20342,25936.519,5.8779308,0
20019012.19,,5905,,160.255,0.056,9.3E-6,161.11397,1.6018373,924.31721,3.039,4408.9255,2.115,5333.2427,3.039,0.067425982,42.386029,0.25570657,95.949594,,,1,,,,0.000125986,127.05343,25957.711,5.7370396,0
20020120.36,,5905,,162.82,0.056,9.4E-6,163.69545,1.6518851,935.92149,2.924,4519.6457,2.202,5455.5672,2.924,0.066301135,42.829422,0.26462417,95.82347,,,1,,,,0.00012754337,131.89146,26796.201,5.7174556,0
20021270.03,,5905,,165.384,0.056,9.2E-6,166.2057,1.6345666,967.07482,4.769,4627.2909,2.296,5594.3657,4.769,0.18567105,44.273438,0.78372669,88.908967,,,1,,,,0.00012683897,128.3279,27624.336,5.8185417,0
20021978.5,,5905,,165.385,0.056,9.2E-6,166.28322,1.6572151,944.64535,2.447,4630.1363,2.299,5574.7816,2.447,0.69736095,43.125039,0.32068126,94.966849,,,1,,,,0.00012946838,129.4399,27650.109,5.6809422,0
20023141,,5905,,167.949,0.056,9.3E-6,168.86066,1.6911307,962.36008,3.436,4739.1855,2.402,5701.5455,3.436,0.064943276,43.366677,0.33624073,94.747256,,,1,,,,0.00013168225,132.62946,28513.921,5.6991374,0
20024296.83,,5905,,170.515,0.056,9.4E-6,171.37782,1.6740611,987.53136,3.932,4845.7765,2.506,5833.3078,3.932,0.4031424,44.647489,0.85775104,87.895793,,,1,,,,0.00013117834,129.0636,29370.357,5.7623056,0
20025013.97,,5905,,170.514,0.056,9.4E-6,171.4404,1.6752559,966.55079,3.979,4848.3566,2.509,5814.9074,3.088,2.7091639,43.286042,,,,,1,,,,0.00013433678,131.00473,29391.811,5.6378239,0
20026138.17,,5905,,173.075,0.056,9.2E-6,174.0213,1.7434971,979.42437,3.516,4956.12,2.614,5935.5444,3.516,0.10816966,43.88774,0.3482319,94.538421,,,1,,,,0.00013545824,134.19402,30283.413,5.6281867,0
20027315.92,,5905,,175.644,0.056,9.3E-6,176.53785,1.7368734,1002.8561,4.767,5061.8041,2.713,6064.6602,4.767,0.1881668,44.951049,0.6731112,90.158716,,,1,,,,0.00013532582,131.86426,31165.611,5.6806862,0
20028038.7,,5905,,175.644,0.056,9.3E-6,176.61256,1.758192,978.873,2.812,5064.5558,2.716,6043.4288,2.812,1.1594514,43.92544,0.27950173,95.51151,,,1,,,,0.00013775451,132.48062,31191.995,5.5424881,0
20029176.92,,5905,,178.206,0.056,9.3E-6,179.16928,1.7645589,1014.3253,4.771,5171.7336,2.809,6186.059,3.856,0.17633301,44.113746,,,,,1,,,,0.00014022974,135.85301,32101.63,5.6612682,0
20030263.16,,5905,,180.768,0.056,9.4E-6,181.67889,1.7743006,1042.1697,5.594,5276.5384,2.894,6318.708,5.594,0.28395672,45.826882,1.085443,85.205041,,,1,,,,0.0001385493,132.03855,33007.219,5.7363278,0
20030991.5,,5905,,180.768,0.056,9.3E-6,181.75056,1.766342,1013.3848,4.559,5279.4409,2.896,6292.8258,3.52,1.0664759,44.186656,,,,,1,,,,0.00014241462,132.34365,33033.265,5.5756905,0
20032135.5,,5905,,183.333,0.056,9.3E-6,184.32986,1.8087259,1037.6584,4.548,5386.5076,2.978,6424.166,3.437,0.096343374,44.434951,,,,,1,,,,0.00014457462,136.55381,33977.497,5.6293558,0
20033269.58,,5905,,185.897,0.056,9.3E-6,186.85689,1.8173227,1047.9995,5.295,5491.1186,3.053,6539.1182,5.295,0.18319119,45.395917,0.67849344,89.95194,,,1,,,,0.00014446598,132.54345,34915.498,5.6085678,0
20033951.61,,5905,,185.897,0.056,9.3E-6,186.91492,1.8059327,1022.7795,4.558,5493.6042,3.055,6516.3837,3.384,0.064884872,44.119824,,,,,1,,,,0.00014769741,133.05775,34937.188,5.4718986,0
20035053.67,,5905,,188.463,0.056,9.4E-6,189.49453,1.8608478,1035.6202,4.456,5599.9192,3.128,6635.5394,3.174,0.070868513,44.484934,,,,,1,,,,0.00014916375,137.97335,35908.176,5.4651722,0
20036140.41,,5905,,191.027,0.056,9.3E-6,191.99949,1.8552166,1068.1572,6.19,5703.0639,3.198,6771.2211,6.19,0.24195564,45.92095,1.060318,85.081583,,,1,,,,0.00014811253,132.38796,36863.805,5.5633336,0
20036824.03,,5905,,191.028,0.056,9.2E-6,192.07513,1.8455648,1033.0079,4.829,5706.0127,3.2,6739.0206,3.616,0.080336182,44.152817,,,,,1,,,,0.00015262946,133.05122,36892.855,5.3781449,0
20037972.05,,5905,,193.591,0.056,9.4E-6,194.65769,1.8877746,1072.1227,5.183,5811.4591,3.271,6883.5818,4.02,0.22629245,44.543017,,,,,1,,,,0.00015453784,136.93155,37891.615,5.5077337,0
20039161.56,,5905,,196.157,0.056,9.2E-6,197.1879,1.9149006,1070.3558,5.454,5914.3024,3.342,6984.6582,5.454,0.22254017,45.842384,0.7371449,88.915811,,,1,,,,0.0001528158,134.14383,38883.067,5.4281007,0
20039895.14,,5905,,196.153,0.056,9.4E-6,197.24364,1.9014274,1060.7611,4.889,5916.7069,3.343,6977.468,3.567,0.82380383,44.731695,,,,,1,,,,0.00015598488,134.07744,38905.054,5.377923,0
20041005.64,,5905,,198.717,0.056,9.2E-6,199.82447,1.9554527,1067.8032,5.383,6020.7718,3.416,7088.5751,4.161,0.20763994,44.871228,,,,,1,,,,0.00015797596,139.27447,39929.821,5.343706,0
20042148.53,,5905,,201.285,0.056,9.2E-6,202.34698,1.9575226,1081.0563,5.451,6121.9565,3.486,7203.0128,5.451,0.19067798,45.880336,0.76041446,88.439971,,,1,,,,0.00015746569,134.01755,40944.302,5.3425867,0
20042883.48,,5905,,201.283,0.056,9.3E-6,202.40029,1.9480322,1067.9969,4.866,6124.2452,3.487,7192.2421,3.394,0.68093347,44.838097,,,,,1,,,,0.00016040471,134.30681,40965.878,5.2766572,0
20044044.25,,5905,,203.841,0.056,9.3E-6,204.9787,1.9973581,1083.2505,5.337,6226.7411,3.556,7309.9916,3.98,0.99123526,44.992366,,,,,1,,,,0.00016247182,138.7228,42016.266,5.2846978,0
20045145.23,,5905,,206.412,0.056,9.4E-6,207.48692,2.0029943,1095.1816,6.12,6325.7922,3.618,7420.9738,6.12,0.22991995,46.012786,0.90878224,86.347887,,,1,,,,0.00016184729,134.46429,43050.822,5.2783162,0
20045833.41,,5905,,206.41,0.056,9.3E-6,207.54926,1.9890256,1083.1075,4.852,6328.2773,3.619,7411.3848,3.232,0.039695557,44.740498,,,,,1,,,,0.00016565271,134.51094,43076.694,5.2185563,0
20046936.78,,5905,,208.974,0.056,9.3E-6,210.12195,2.0390717,1088.2755,4.767,6428.7673,3.676,7517.0428,3.034,0.051903358,44.85164,,,,,1,,,,0.00016759795,138.44421,44151.233,5.1792567,0
20048084.61,,5905,,211.539,0.056,9.4E-6,212.63776,2.0462656,1120.1331,6.085,6526.3118,3.724,7646.4449,6.085,0.23205018,46.081361,0.95579582,85.681888,,,1,,,,0.00016654127,134.60796,45214.819,5.2677993,0
20048822.47,,5905,,211.537,0.056,9.3E-6,212.70382,2.0411022,1095.4779,5.201,6528.8358,3.725,7624.3137,3.63,0.91998064,44.748251,,,,,1,,,,0.00017038238,135.50261,45242.917,5.1502503,0
20049926.11,,5905,,214.105,0.056,9.2E-6,215.27621,2.0780144,1129.8293,5.589,6627.2986,3.763,7757.1279,4.133,0.07108801,44.931972,,,,,1,,,,0.00017264161,138.38089,46343.846,5.2482777,0
20051069.22,,5905,,216.666,0.056,9.4E-6,217.78891,2.0918311,1120.3808,6.73,6722.6186,3.788,7842.9994,6.73,0.19183958,46.011943,1.0339381,84.392442,,,1,,,,0.00017111387,134.45351,47432.009,5.1443429,0
20051805.3,,5905,,216.668,0.056,9.4E-6,217.85608,2.082498,1125.8537,5.701,6725.1214,3.788,7850.9751,4.26,0.53131679,44.874141,,,,,1,,,,0.00017495544,134.98053,47461.272,5.1678785,0
20052959.48,,5905,,219.232,0.056,9.3E-6,220.43242,2.1270609,1137.041,5.654,6821.4114,3.8,7958.4524,4.187,9.6696457,44.855373,,,,,1,,,,0.00017742473,138.44554,48590.452,5.1582295,0
20054100.84,,5905,,221.795,0.056,9.4E-6,222.95493,2.1332436,1159.0456,6.38,6914.692,3.799,8073.7375,6.38,0.24588874,45.937372,0.94923696,85.523644,,,1,,,,0.00017638141,134.07608,49708.9,5.1985644,0
20054833.28,,5905,,221.798,0.056,9.4E-6,223.01162,2.1266626,1130.3605,5.093,6916.8134,3.799,8047.1739,3.392,0.39065058,44.644748,,,,,1,,,,0.00018024906,134.572,49734.182,5.068617,0
20055936.5,,5905,,224.362,0.056,9.4E-6,225.59315,2.1675673,1151.0366,5.193,7010.8313,3.791,8161.8679,3.548,0.053171075,44.684315,,,,,1,,,,0.00018265622,137.33595,50892.271,5.1022673,0
20057073.25,,5905,,226.924,0.056,9.3E-6,228.11227,2.1522379,1183.5774,10.28,7101.6724,3.781,8285.2498,9.562,0.27167211,45.200265,,,,,1,,,,0.00018330091,133.48422,52035.206,5.188574,0
20057798.83,,5905,,226.93,0.056,9.4E-6,228.16767,2.1671873,1154.5829,5.079,7103.5386,3.781,8258.1215,3.392,0.39328661,44.572904,,,,,1,,,,0.00018527223,134.00258,52060.488,5.0602387,0
20058852,,5905,,229.49,0.056,9.4E-6,230.74775,2.215413,1146.5368,4.765,7194.9792,3.773,8341.516,2.911,0.037997026,44.435692,,,,,1,,,,0.00018772108,137.07115,53244.524,4.9687887,0
20059897.19,,5905,,232.053,0.056,9.3E-6,233.26713,2.1955747,1210.7323,10.53,7283.3556,3.771,8494.0879,9.827,0.19274651,45.063894,,,,,1,,,,0.00018848988,132.87814,54413.556,5.1903254,0
20060668.98,,5905,,232.052,0.056,9.3E-6,233.32642,2.2127189,1149.8424,4.879,7285.3414,3.771,8435.1839,3.096,0.69261088,44.308193,,,,,1,,,,0.00019037526,133.06832,54441.217,4.9280422,0
20061760.3,,5905,,234.616,0.056,9.4E-6,235.90524,2.2522788,1169.0214,6.105,7374.2245,3.781,8543.2459,4.793,1.3715444,44.331243,,,,,1,,,,0.00019271388,135.03316,55651.284,4.9554701,0
20062849,,5905,,237.179,0.056,9.2E-6,238.44127,2.2680732,1192.0433,6.043,7460.3426,3.806,8652.3859,6.043,0.23997443,45.041938,0.76909684,87.370887,,,1,,,,0.00019263243,132.4904,56854.238,4.9993163,0
20063571.47,,5905,,237.177,0.056,9.4E-6,238.48159,2.2507529,1173.7471,5.096,7461.8459,3.807,8635.593,3.387,0.26143243,44.088203,,,,,1,,,,0.00019587083,131.84635,56873.467,4.9217515,0
20064688.03,,5905,,239.744,0.056,9.2E-6,241.0662,2.2896883,1177.8558,5.259,7548.3339,3.854,8726.1897,3.579,1.1357068,43.992402,,,,,1,,,,0.00019835675,133.38246,58112.915,4.8860264,0
20065720.31,,5905,,242.306,0.056,9.4E-6,243.59832,2.3215272,1199.7134,6.753,7631.7107,3.924,8831.4241,6.753,0.1832681,45.008336,0.79601336,86.842042,,,1,,,,0.00019677607,131.6209,59340.142,4.9249659,0
20066436.89,,5905,,242.3,0.056,9.2E-6,243.64372,2.2994392,1176.7303,5.199,7633.3504,3.926,8810.0807,3.408,0.12342957,43.941095,,,,,1,,,,0.00020049752,130.76983,59362.26,4.8297174,0
20067435.23,,5905,,244.871,0.056,9.2E-6,246.23084,2.3456951,1183.0656,4.996,7717.1067,4.026,8900.1723,2.958,0.036140557,43.580882,,,,,1,,,,0.00020422194,134.33494,60629.628,4.8047009,0
20068461.91,,5905,,247.436,0.056,9.3E-6,248.75333,2.3616701,1217.2187,6.523,7797.698,4.147,9014.9167,6.523,0.33231876,44.682755,0.94779434,84.540936,,,1,,,,0.00020244104,131.03188,61878.221,4.893276,0
20069174.7,,5905,,247.432,0.056,9.3E-6,248.80623,2.3436376,1192.8819,5.604,7799.4504,4.15,8992.3322,3.767,0.37458546,43.515548,,,,,1,,,,0.00020664642,130.38129,61904.54,4.7944212,0
20070209.09,,5905,,250,0.056,9.4E-6,251.37758,2.3773462,1215.995,6.431,7880.0955,4.291,9096.0905,4.79,2.3311888,43.443991,,,,,1,,,,0.00020937511,131.74724,63190.685,4.8373249,0
20071209.88,,5905,,250.009,0.056,9.2E-6,251.447,2.4665173,1198.7133,6.662,7881.9581,4.295,9080.6714,5.092,0.3110107,43.259162,,,,,1,,,,0.00020991325,141.70435,63225.594,4.7672601,0
20071958.52,,5905,,249.999,0.056,9.4E-6,251.39719,2.3642273,1199.8442,5.495,7880.7606,4.293,9080.6048,3.43,0.20585929,43.30079,,,,,1,,,,0.00020970991,129.90617,63200.549,4.7727033,0
20073107.06,,5905,,259.999,0.056,9.3E-6,261.40654,2.4799576,1226.0771,6.853,8182.3113,4.922,9408.3884,4.768,0.10876482,42.688461,,,,,1,,,,0.00022039653,131.48068,68333.38,4.6903078,0
20074237.19,,5905,,270.003,0.056,9.3E-6,271.36682,2.5194062,1276.7118,8.774,8462.6048,5.439,9739.3166,8.774,0.23078114,42.9751,1.1310233,81.105719,,,1,,,,0.00022755882,127.73537,73639.953,4.7047453,0
20074925.48,,5905,,270.003,0.056,9.3E-6,271.48122,2.5407699,1255.693,8.716,8465.8631,5.443,9721.556,6.807,1.1548271,41.884563,,,,,1,,,,0.00023210356,126.17047,73702.05,4.6253402,0
20076047.36,,5905,,279.997,0.056,9.2E-6,281.52896,2.6384646,1359.2853,14.27,8728.5718,5.58,10087.857,13.14,2.7333524,41.10055,,,,,1,,,,0.00024544336,127.06783,79258.557,4.8282256,0
20077097.86,,5905,,290,0.056,9.2E-6,291.43716,2.6544046,1444.3472,10.39,8969.5213,5.212,10413.868,10.39,0.35697514,42.416044,2.7370028,64.41136,,,1,,,,0.00024830885,122.51366,84935.617,4.9559473,0
20077725.41,,5905,,290.003,0.056,9.4E-6,291.59696,2.6861154,1392.5601,10.64,8972.7171,5.203,10365.277,9.283,0.44878474,40.048454,,,,,1,,,,0.00025881841,120.95303,85028.785,4.7756331,0
20078801.83,,5905,,300,0.056,9.3E-6,301.61557,2.8058523,1254.9686,5.999,9197.0188,4.213,10451.987,4.271,0.070254671,38.901299,,,,,1,,,,0.00026867965,118.23546,90971.952,4.1608216,0
20079140.58,,5905,,299.998,0.056,9.4E-6,301.62605,2.7866031,1277.4826,6.29,9197.3087,4.211,10474.791,4.672,0.8468243,38.889943,,,,,1,,,,0.00026934447,116.7039,90978.274,4.235319,0