File: HeatCapacity/ML_PPMS_08212020_1_MKS-Bi2WO6-flux-HC-2-300K-hc_2.80mg.dat
[Header]
TITLE,ML_PPMS_08212020_1_MKS-Bi2WO6-flux-HC-2-300K-hc_2.80mg.dat
BYAPP,HeatCapacity,3.9.6,1.7
INFO,2.80,MASS:Sample Mass (mg)
INFO,0.2,MASSERR:Sample Mass Error (mg)
INFO,,MOLWGHT:Formula Weight (g/mole)
INFO,,ATOMS:Atoms per Formula Unit
INFO,PPMS Heat Capacity Option 3.9.6 Build 3,APPNAME
DATATYPE,TIME,1
DATATYPE,COMMENT,2
STARTUPAXIS, X, 8, LINEAR, AUTO
STARTUPAXIS, Y1, 10, LINEAR, AUTO
[Data]
Time Stamp (Seconds),Comment (),System Status (Code),Puck Temp (Kelvin),System Temp (Kelvin),Field (Oersted),Pressure (Torr),Sample Temp (Kelvin),Temp Rise (Kelvin),Samp HC (µJ/K),Samp HC Err (µJ/K),Addenda HC (µJ/K),Addenda HC Err (µJ/K),Total HC (µJ/K),Total HC Err (µJ/K),Fit Deviation (ChiSquare),Time Const tau1 (seconds),Time Const tau2 (seconds),Sample Coupling (Percent),Debye Temp (Kelvin),Debye Temp Err (Kelvin),Cal Correction (Factor),Therm Resist (Ohms),Htr Resist (Ohms),Puck Resist (Ohms),Wire Cond (W/K),Meas Time (seconds),Temp Squared (K^2),Samp HC/Temp (µJ/K/K),Addenda Offset HC (µJ/K)
20218461.25,CALFILE: C:\QdPpms\HEATCA~1\TempCal\Standard\Puck1074_1.cal|Addenda #294 measured on 8/21/2020 from 1.989 to 298.34 K
20218461.48,,5905,2.01069,1.9857,-0.07,9.3E-6,1.9950219,0.020507807,0.026075653,0.001193,0.2221182,0.0007493,0.24819385,0.0009286,2.5339751,0.14492432,,,,,1,,,,1.7125756E-6,0.4472468,3.9801125,0.013070359,0
20218479.75,,5905,2.00914,1.9845,-0.07,9.2E-6,1.9934928,0.020170054,0.027319813,0.001163,0.22178838,0.0007447,0.2491082,0.0008928,3.6283737,0.14524047,,,,,1,,,,1.7151431E-6,0.43477296,3.9740136,0.013704495,0
20218497.84,,5905,2.0085,1.984,-0.07,9.4E-6,1.9926172,0.020152086,0.027270952,0.00122,0.22158805,0.0007418,0.248859,0.0009679,5.2259911,0.14394061,,,,,1,,,,1.7289005E-6,0.43572142,3.9705235,0.013685996,0
20218686.28,,5905,2.15783,2.1353,-0.07,9.2E-6,2.1360457,0.020797041,0.033820873,0.001578,0.25603098,0.001088,0.28985186,0.001143,1.8024825,0.15648682,,,,,1,,,,1.8522445E-6,0.43182183,4.5626912,0.015833403,0
20218705.38,,5905,2.15707,2.1345,-0.07,9.2E-6,2.1356914,0.0216598,0.034969253,0.001536,0.25591926,0.001087,0.29088852,0.001085,3.7993581,0.15757292,,,,,1,,,,1.8460565E-6,0.46946047,4.5611778,0.016373739,0
20218724.27,,5905,2.15678,2.1342,-0.07,9.4E-6,2.1348152,0.021665378,0.033704012,0.001542,0.25566777,0.001086,0.28937178,0.001094,1.9474647,0.15564796,,,,,1,,,,1.8591427E-6,0.47271876,4.5574361,0.015787789,0
20218913.48,,5905,2.31957,2.3011,-0.07,9.3E-6,2.2930278,0.02206225,0.04088902,0.004539,0.2986948,0.00118,0.33958382,0.004383,0.099135773,0.1660778,,,,,1,,,,2.0447274E-6,0.46694389,5.2579765,0.01783189,0
20218932.08,,5905,2.31898,2.3018,-0.07,9.3E-6,2.2938662,0.02271452,0.036831077,0.002112,0.2988919,0.00118,0.33572298,0.001751,0.38131872,0.16278466,,,,,1,,,,2.0623748E-6,0.4982334,5.2618221,0.016056332,0
20218956.92,,5905,2.31856,2.3013,-0.07,9.2E-6,2.2933238,0.022770116,0.045035294,0.002817,0.29877539,0.00118,0.34381069,0.002558,0.44417853,0.17374519,,,,,1,,,,1.9788214E-6,0.48835398,5.2593339,0.019637565,0
20219146.39,,5905,2.49465,2.4787,-0.07,9.3E-6,2.4645643,0.023891928,0.044601514,0.002702,0.35181715,0.001096,0.39641866,0.00247,0.34431689,0.17670165,,,,,1,,,,2.243435E-6,0.52123556,6.0740773,0.018097119,0
20219167.97,,5905,2.49446,2.4798,-0.07,9.3E-6,2.4646467,0.023974046,0.043359852,0.003144,0.3518396,0.001096,0.39519945,0.002947,0.19049513,0.17481902,,,,,1,,,,2.2606205E-6,0.53010495,6.0744834,0.017592725,0
20219186.42,,5905,2.49445,2.4807,-0.07,9.3E-6,2.4640414,0.024228021,0.054751364,0.002923,0.35170198,0.001096,0.40645335,0.002709,0.59057431,0.1890763,,,,,1,,,,2.1496789E-6,0.52445705,6.0715,0.022220148,0
20219390.27,,5905,2.69041,2.6485,-0.07,9.4E-6,2.6547744,0.025635543,0.061202595,0.001981,0.42038438,0.001162,0.48158698,0.001605,2.2801187,0.20078183,,,,,1,,,,2.3985586E-6,0.56722891,7.0478271,0.023053784,0
20219413.02,,5905,2.68845,2.6464,-0.07,9.3E-6,2.6545523,0.026352703,0.06405029,0.002287,0.42023787,0.001161,0.48428816,0.001971,1.1115852,0.2021223,,,,,1,,,,2.3960155E-6,0.60234549,7.0466482,0.024128471,0
20219431.94,,5905,2.68827,2.6476,-0.07,9.3E-6,2.6531065,0.026539555,0.061415512,0.001987,0.41968891,0.00116,0.48110442,0.001613,1.8310273,0.20195682,,,,,1,,,,2.3822143E-6,0.60636689,7.0389741,0.023148529,0
20219635.23,,5905,2.89558,2.851,-0.07,9.2E-6,2.854919,0.027210333,0.077846573,0.002482,0.50139982,0.001624,0.5792464,0.001877,0.24498117,0.22331214,,,,,1,,,,2.5938867E-6,0.60587045,8.1505625,0.027267524,0
20219654.59,,5905,2.89358,2.8468,-0.07,9.4E-6,2.8546523,0.028512927,0.07869494,0.003729,0.50120918,0.001623,0.57990412,0.003357,0.25868094,0.22423989,,,,,1,,,,2.5860881E-6,0.66993643,8.1490397,0.027567259,0
20219673.48,,5905,2.89334,2.8487,-0.07,9.3E-6,2.8546033,0.030701101,0.06171871,0.002165,0.50064738,0.001618,0.56236609,0.002165,0.56320797,0.21198746,5.4975733E-6,99.973464,,,1,,,,2.6528356E-6,0.67271968,8.1487599,0.021620766,0
20219870.45,,5905,3.11366,3.0719,-0.07,9.2E-6,3.0677258,0.029416947,0.093317665,0.002239,0.59894122,0.00214,0.69225888,0.002239,1.1379899,0.25265304,0.010740105,73.013363,,,1,,,,2.7591843E-6,0.63596238,9.4109416,0.030419168,0
20219895.92,,5905,3.11238,3.0713,-0.07,9.3E-6,3.0691474,0.031951828,0.093321844,0.002218,0.5993385,0.00214,0.69266034,0.002218,0.87391916,0.24681685,0.007116304,80.023245,,,1,,,,2.8194701E-6,0.75795912,9.4196657,0.030406439,0
20219914.42,,5905,3.11122,3.0683,-0.07,9.3E-6,3.0686324,0.031771087,0.080360689,0.002215,0.5988383,0.00214,0.67919899,0.002215,5.0737626,0.23106978,0.0018887015,92.718986,,,1,,,,2.9426253E-6,0.74045054,9.4165048,0.026187786,0
20220088.59,Error: Warning:  Measured time constant less than time constant calculated from addenda table.  Changing time constant to addenda table value
20220129.27,,5905,3.34773,3.3121,-0.07,9.3E-6,3.2980983,0.031736487,0.11013377,0.002175,0.71872508,0.001973,0.82885885,0.002175,1.5025075,0.26461716,0.002495452,92.413937,,,1,,,,3.1368773E-6,0.69640134,10.877452,0.033393113,0
20220148.48,,5905,3.34659,3.3097,-0.07,9.2E-6,3.297822,0.032319237,0.10746863,0.004419,0.71892302,0.001973,0.82639165,0.003954,0.74408822,0.26629279,,,,,1,,,,3.1033197E-6,0.79385149,10.87563,0.03258776,0
20220226.03,,5905,3.32752,3.3336,-0.07,9.4E-6,3.2789052,0.032938006,0.12600016,0.002743,0.70690171,0.00196,0.83290187,0.002743,0.14108958,0.26795897,0.0052339556,86.713593,,,1,,,,3.1194359E-6,0.79887837,10.751219,0.038427508,0
20220402.98,Error: Warning:  Measured time constant less than time constant calculated from addenda table.  Changing time constant to addenda table value
20220421.41,,5905,3.58747,3.5988,-0.07,9.3E-6,3.5315384,0.031926674,0.14801931,0.003791,0.91123818,0.003376,1.0592575,0.003791,0.80172828,0.34104905,0.050599244,43.293171,,,1,,,,3.1996516E-6,0.83239211,12.471763,0.04191355,0
20220440.5,,5905,3.5873,3.599,-0.07,9.4E-6,3.5322999,0.033824343,0.18343567,0.003593,0.91236972,0.003387,1.0958054,0.003593,2.9654466,0.37213571,0.079811587,36.506993,,,1,,,,3.1305352E-6,1.0231471,12.477143,0.051930944,0
20220460.45,,5905,3.588,3.5997,-0.07,9.3E-6,3.5339005,0.036215075,0.14664353,0.003554,0.91204192,0.003383,1.0586854,0.003554,0.97817204,0.31721101,0.040389329,47.160097,,,1,,,,3.4199918E-6,1.1164071,12.488453,0.041496224,0
20220641.94,Error: Warning:  Measured time constant less than time constant calculated from addenda table.  Changing time constant to addenda table value
20220661.33,,5905,3.86036,3.8754,-0.07,9.4E-6,3.7975173,0.03376705,0.21243761,0.005134,1.1560782,0.004955,1.3685158,0.005134,1.2334277,0.36513451,0.026531959,63.666389,,,1,,,,3.8036223E-6,0.95900301,14.421138,0.055941182,0
20220702.47,,5905,3.86038,3.8753,-0.07,9.3E-6,3.7985533,0.036671127,0.26805663,0.005159,1.1576734,0.004957,1.42573,0.005159,2.6859607,0.42943829,0.060541664,49.957597,,,1,,,,3.4577775E-6,1.1627906,14.429007,0.070568084,0
20220934.8,,5905,4.1551,4.1721,-0.07,9.3E-6,4.0848759,0.038926517,0.29967503,0.005011,1.3964465,0.004697,1.6961216,0.005011,2.0745925,0.44095796,0.045296395,57.363506,,,1,,,,3.9462076E-6,1.2372144,16.686211,0.073362089,0
20221161.8,,5905,4.46774,4.4826,-0.07,9.3E-6,4.3977439,0.041568559,0.32718222,0.004159,1.6575688,0.003942,1.984751,0.004159,0.99955286,0.43033483,0.0071511991,89.164985,,,1,,,,4.6275971E-6,1.2900533,19.340152,0.074397743,0
20221203.05,,5905,4.47051,4.4862,-0.07,9.4E-6,4.3966304,0.041407992,0.37630445,0.00458,1.6579758,0.00394,2.0342802,0.00458,0.89290044,0.50064663,0.047223768,60.343068,,,1,,,,4.1644597E-6,1.2868822,19.330359,0.085589284,0
20221432.36,,5905,4.8082,4.83,-0.07,9.4E-6,4.7285703,0.046232763,0.45977494,0.004069,1.9712461,0.003448,2.4310211,0.004069,0.27682292,0.48638591,0.010273358,87.786114,,,1,,,,5.0235459E-6,1.567478,22.359377,0.097233394,0
20221659.27,,5905,5.17262,5.1944,-0.07,9.4E-6,5.0819252,0.048228424,0.60974875,0.00449,2.3742564,0.003836,2.9840051,0.00449,5.2829473,0.59977135,0.035149119,72.861111,,,1,,,,5.0575167E-6,1.561609,25.825964,0.11998381,0
20221702.38,,5905,5.17317,5.1941,-0.07,9.3E-6,5.0845735,0.049481357,0.56972235,0.004581,2.3758487,0.003838,2.945571,0.004581,0.21373241,0.54474535,0.0083853258,90.957343,,,1,,,,5.42767E-6,1.6691244,25.852888,0.11204919,0
20221956.34,,5905,5.56644,5.5876,-0.07,9.3E-6,5.4708681,0.055446889,0.64564606,0.004619,2.8676989,0.00403,3.513345,0.004619,1.5009344,0.60031855,0.0038768908,95.860673,,,1,,,,5.8610579E-6,1.9145045,29.930398,0.11801529,0
20222190.66,,5905,5.98835,6.0062,-0.07,9.2E-6,5.8807372,0.054600708,0.89406282,0.006907,3.4645542,0.004915,4.3586171,0.006907,0.2714052,0.68650282,0.0074242121,93.746729,,,1,,,,6.3670304E-6,1.7770928,34.58307,0.15203244,0
20222234.47,,5905,5.98932,6.0058,-0.07,9.3E-6,5.8827721,0.057159311,0.94241513,0.01016,3.4677945,0.004923,4.4102096,0.008889,1.5966921,0.70092473,,,,,1,,,,6.2919875E-6,1.9970394,34.607007,0.16019916,0
20222476.36,,5905,6.44344,6.4703,-0.07,9.3E-6,6.3259686,0.062528136,1.2728468,0.01735,4.1977767,0.006703,5.4706235,0.016,0.51652714,0.78719208,,,,,1,,,,6.9495409E-6,2.3646617,40.017878,0.2012098,0
20222722.52,,5905,6.93224,6.959,-0.07,9.4E-6,6.8024108,0.062275658,1.6164559,0.00977,5.0485814,0.007833,6.6650373,0.00977,0.49710872,0.8628674,0.0082700477,95.012089,,,1,,,,7.7483725E-6,2.240485,46.272793,0.23762985,0
20222768.13,,5905,6.93515,6.9625,-0.07,9.3E-6,6.8074732,0.068837421,1.6092916,0.008838,5.0541299,0.007838,6.6634215,0.008838,1.4050401,0.87374666,0.0074898411,95.506006,,,1,,,,7.647375E-6,2.6959128,46.341692,0.23640072,0
20223011.72,,5905,7.45944,7.4898,-0.07,9.4E-6,7.325783,0.072869083,2.0547534,0.009566,6.1037855,0.007943,8.1585389,0.009566,0.59129344,0.96825112,0.0069707151,96.302396,,,1,,,,8.4467272E-6,2.9187401,53.667097,0.28048243,0
20223260.78,,5905,8.0235,8.0596,-0.07,9.2E-6,7.8749493,0.075037062,2.6964493,0.009201,7.3661253,0.007717,10.062575,0.009201,0.99058594,1.1070721,0.0098254169,95.644066,,,1,,,,9.11935E-6,2.9401252,62.014826,0.34240847,0
20223309.67,,5905,8.02511,8.0625,-0.07,9.3E-6,7.8782617,0.075801433,2.6538539,0.02007,7.3751572,0.007726,10.029011,0.01853,1.4622837,1.0643944,,,,,1,,,,9.4222698E-6,3.2314006,62.067008,0.33685779,0
20223565.25,,5905,8.6366,8.6698,-0.07,9.4E-6,8.4758613,0.084156732,3.540669,0.01354,8.9223691,0.01049,12.463038,0.01354,0.2919039,1.2163339,0.00668271,97.358406,,,1,,,,1.0268958E-5,3.7493029,71.840224,0.4177356,0
20223820.17,,5905,9.28914,9.3289,-0.07,9.3E-6,9.1117446,0.085876367,4.7008919,0.01502,10.732983,0.01357,15.433875,0.01502,1.7782466,1.4027312,0.013354946,95.663461,,,1,,,,1.1049449E-5,3.6757052,83.023889,0.51591568,0
20223872.02,,5905,9.29104,9.3302,-0.07,9.3E-6,9.1170729,0.091377158,4.5829478,0.01604,10.749249,0.01359,15.332197,0.01604,0.94740009,1.3883006,0.0097268758,96.745885,,,1,,,,1.1077284E-5,4.2197283,83.121018,0.50267754,0
20224135.61,,5905,9.99762,10.0389,-0.07,9.4E-6,9.8072322,0.098116769,5.9283695,0.02002,12.905587,0.01669,18.833956,0.02002,2.8952468,1.5491816,0.0089903373,97.366155,,,1,,,,1.2190133E-5,4.7036674,96.181803,0.60448957,0
20224697,,5905,10.766,10.7778,-0.07,9.2E-6,10.552775,0.098908758,7.7985044,0.0238,15.48256,0.01977,23.281064,0.0238,0.93932779,1.7530879,0.013600523,96.60874,,,1,,,,1.333275E-5,4.6509085,111.36107,0.73900032,0
20224753.13,,5905,10.7655,10.7771,-0.07,9.4E-6,10.555313,0.10496075,7.9214365,0.02338,15.485637,0.01978,23.407073,0.02338,1.4139969,1.7680801,0.015373951,96.228848,,,1,,,,1.3298638E-5,5.2169139,111.41463,0.75046913,0
20225027.64,,5905,11.5806,11.5972,-0.07,9.4E-6,11.350213,0.11442547,10.128314,0.02744,18.504305,0.02348,28.632619,0.02744,1.2661224,1.9830388,0.016385626,96.480569,,,1,,,,1.4505214E-5,5.947149,128.82734,0.89234568,0
20225308.78,,5905,12.4581,12.4743,-0.07,9.4E-6,12.20719,0.11723579,12.622583,0.03343,22.119418,0.02847,34.742001,0.03343,1.670852,2.215037,0.020269739,96.155468,,,1,,,,1.5768164E-5,5.8745002,149.0155,1.0340285,0
20225368.67,,5905,12.4603,12.4746,-0.07,9.4E-6,12.211244,0.12310927,12.622051,0.03339,22.138754,0.02849,34.760805,0.03339,0.96581352,2.2036457,0.017111284,96.723055,,,1,,,,1.5845244E-5,6.583434,149.11449,1.0336417,0
20225663.58,,5905,13.408,13.4105,-0.07,9.2E-6,13.141475,0.13254042,15.811788,0.04079,26.517601,0.0356,42.32939,0.04079,1.4656547,2.4547404,0.019974609,96.607401,,,1,,,,1.732913E-5,7.354371,172.69838,1.2031973,0
20225969.2,,5905,14.4213,14.4377,-0.07,9.3E-6,14.134452,0.13557303,19.342627,0.05731,31.593243,0.04978,50.93587,0.05731,1.2354583,2.726942,0.024176365,96.333702,,,1,,,,1.8782186E-5,7.344589,199.78274,1.3684737,0
20226043.19,,5905,14.4225,14.4372,-0.07,9.4E-6,14.138299,0.13966708,19.404891,0.09364,31.610492,0.04984,51.015384,0.07927,3.3923635,2.6952448,,,,,1,,,,1.8927922E-5,8.0859139,199.89149,1.3725054,0
20226353.16,,5905,15.5179,15.5341,-0.07,9.3E-6,15.214924,0.15453264,23.643831,0.07206,37.643387,0.06583,61.287218,0.07206,1.6048213,3.0283688,0.02218987,96.973181,,,1,,,,2.0332411E-5,9.1114176,231.49393,1.5539894,0
20226672.23,,5905,16.6963,16.7109,-0.07,9.3E-6,16.372237,0.15830731,28.558359,0.08636,44.81607,0.07833,73.374429,0.08636,1.6126973,3.3655799,0.028709332,96.498858,,,1,,,,2.1922285E-5,9.0896707,268.05013,1.7443163,0
20226757.5,,5905,16.6969,16.7101,-0.07,9.3E-6,16.377515,0.16617612,28.680164,0.08643,44.843093,0.07837,73.523256,0.08643,1.4014964,3.3786599,0.030298351,96.326632,,,1,,,,2.1888493E-5,10.04143,268.22301,1.7511914,0
20227087.88,,5905,17.9639,17.9736,-0.07,9.3E-6,17.626585,0.18030014,34.014133,0.09558,53.158044,0.08778,87.172178,0.09558,1.8847069,3.7317907,0.035736905,96.084345,,,1,,,,2.3505688E-5,11.150423,310.69648,1.9297064,0
20227419.94,,5905,19.3282,19.3399,-0.07,9.4E-6,18.962572,0.18491029,40.15908,0.1091,62.724841,0.1031,102.88392,0.1091,1.2538239,4.0815432,0.039955936,96.00008,,,1,,,,2.5368726E-5,11.0884,359.57914,2.1178076,0
20227514.7,,5905,19.33,19.3396,-0.07,9.4E-6,18.968557,0.19428036,40.127187,0.1092,62.761407,0.1032,102.88859,0.1092,1.9567339,4.074016,0.039605777,96.025964,,,1,,,,2.5415379E-5,12.304477,359.80617,2.115458,0
20227860.05,,5905,20.796,20.8115,-0.07,9.3E-6,20.418745,0.20990324,47.345651,0.1364,73.927414,0.1286,121.27306,0.1364,0.86445779,4.523726,0.047814161,95.690974,,,1,,,,2.69942E-5,13.343099,416.92515,2.3187346,0
20228213.36,,5905,22.3774,22.389,-0.07,9.4E-6,21.975099,0.21782474,54.863847,0.1549,86.933731,0.1475,141.79758,0.1549,2.0374606,4.9397429,0.053559388,95.57015,,,1,,,,2.8906845E-5,13.487795,482.90496,2.4966371,0
20228317.69,,5905,22.3761,22.3897,-0.07,9.3E-6,21.981435,0.22719042,54.742447,0.1542,86.978257,0.1476,141.7207,0.1542,0.97502669,4.9073355,0.050859455,95.75758,,,1,,,,2.9072273E-5,14.732018,483.18346,2.4903947,0
20228685.63,,5905,24.0744,24.0889,-0.07,9.3E-6,23.656307,0.23774525,63.73988,0.3206,101.88783,0.1737,165.62771,0.2695,6.8874269,5.234511,,,,,1,,,,3.1641487E-5,15.800595,559.62086,2.6944138,0
20229068.42,,5905,25.9015,25.9209,-0.07,9.3E-6,25.458608,0.24658086,73.022303,0.4261,118.86588,0.2108,191.88818,0.3703,17.148884,5.7403492,,,,,1,,,,3.3427964E-5,15.771822,648.14072,2.8682755,0
20229199.8,,5905,25.9009,25.9214,-0.07,9.3E-6,25.465716,0.25699685,73.116137,0.4009,118.92749,0.211,192.04363,0.3408,10.931308,5.729317,,,,,1,,,,3.3519463E-5,17.183877,648.5027,2.8711597,0
20229604.17,,5905,27.8678,27.8837,-0.07,9.2E-6,27.412446,0.28406697,81.700022,0.2667,138.14397,0.2562,219.84399,0.2667,0.4581813,6.3711299,0.079419273,94.859289,,,1,,,,3.4767824E-5,18.670081,751.4422,2.9803988,0
20230019.06,,5905,29.9831,30.004,-0.07,9.4E-6,29.496693,0.29702721,92.025645,0.3103,160.09876,0.3022,252.12441,0.3103,2.4891786,6.917122,0.093465842,94.407712,,,1,,,,3.6740941E-5,19.111282,870.0549,3.1198631,0
20230168.59,,5905,29.9861,30.0034,-0.07,9.2E-6,29.506671,0.30978068,91.642884,0.311,160.17973,0.3023,251.82262,0.311,1.419834,6.8858342,0.089208748,94.623133,,,1,,,,3.6849972E-5,20.682522,870.64362,3.1058361,0
20230601.11,,5905,32.2601,32.2903,-0.07,9.2E-6,31.766028,0.33464217,103.76215,0.3627,185.51821,0.353,289.28036,0.3627,1.4434081,7.487309,0.10030502,94.416203,,,1,,,,3.8934094E-5,22.538872,1009.0805,3.2664503,0
20231042.48,,5905,34.7066,34.7432,-0.07,9.3E-6,34.181686,0.34418993,116.28405,0.4373,214.23805,0.4214,330.5221,0.4373,1.2947078,8.1690558,0.12789608,93.469616,,,1,,,,4.0815766E-5,22.317641,1168.3877,3.40194,0
20231206.03,,5905,34.7122,34.7414,-0.07,9.4E-6,34.197842,0.36003912,115.2057,0.4305,214.40276,0.4218,329.60846,0.4305,1.6519597,8.0786978,0.11651768,93.944802,,,1,,,,4.1125706E-5,24.357722,1169.4924,3.3688002,0
20231665,,5905,37.3479,37.3744,-0.07,9.2E-6,36.804412,0.38839863,127.28199,0.5029,247.09542,0.4917,374.37741,0.5029,1.7791736,8.754721,0.1353395,93.455341,,,1,,,,4.3114549E-5,26.44304,1354.5647,3.4583352,0
20232138.58,,5905,40.1802,40.2193,-0.07,9.4E-6,39.603874,0.39910266,140.68364,0.582,284.51568,0.5576,425.19931,0.582,0.77359984,9.5425625,0.16768465,92.523426,,,1,,,,4.4959472E-5,26.067091,1568.4668,3.5522696,0
20232324.05,,5905,40.1845,40.2119,-0.07,9.4E-6,39.626321,0.41619986,139.14962,0.5708,284.78526,0.558,423.93488,0.5708,0.85262542,9.3954117,0.13999868,93.580725,,,1,,,,4.5460026E-5,28.389927,1570.2453,3.5115454,0
20232819.7,,5905,43.2353,43.2636,-0.07,9.2E-6,42.646175,0.44793643,153.45584,0.6263,328.19032,0.6128,481.64616,0.6263,2.1848518,10.244678,0.17212473,92.708179,,,1,,,,4.7396118E-5,30.831303,1818.6963,3.5983494,0
20233324.78,,5905,46.5152,46.5405,-0.07,9.3E-6,45.878201,0.45986167,166.83415,0.6894,378.34167,0.6647,545.17582,0.6894,0.88466368,11.088812,0.19694983,92.16645,,,1,,,,4.956295E-5,30.523102,2104.8093,3.636458,0
20233530.41,,5905,46.5184,46.5384,-0.07,9.2E-6,45.897542,0.47891419,166.18367,0.6851,378.58875,0.665,544.77242,0.6851,0.56369085,10.988575,0.1776626,92.817218,,,1,,,,4.9939182E-5,33.149768,2106.5843,3.6207532,0
20234061.33,,5905,50.0495,50.0682,-0.07,9.4E-6,49.400234,0.51484732,180.59064,0.7358,437.70207,0.716,618.29271,0.7358,0.65390832,11.897861,0.19657305,92.504238,,,1,,,,5.2332026E-5,36.15786,2440.3831,3.6556637,0
20234604.5,,5905,53.8491,53.8671,-0.07,9.4E-6,53.160367,0.52798723,197.10984,0.8245,507.15873,0.7669,704.26857,0.8245,0.34438366,13.12992,0.26524202,90.754712,,,1,,,,5.4075373E-5,35.705252,2826.0246,3.7078345,0
20234837.89,,5905,53.8471,53.8601,-0.07,9.2E-6,53.181862,0.54733537,195.48873,0.7997,507.47554,0.7671,702.96427,0.7997,0.14011625,12.858368,0.20167572,92.669773,,,1,,,,5.5009581E-5,38.585259,2828.3104,3.6758534,0
20235412.38,,5905,57.9413,57.9576,-0.07,9.2E-6,57.239276,0.58687319,210.59784,0.8318,588.62828,0.8122,799.22613,0.8318,0.41400209,13.994092,0.22943385,92.123139,,,1,,,,5.7456431E-5,41.84671,3276.3347,3.6792542,0
20235999.78,,5905,62.3382,62.3517,-0.07,9.4E-6,61.569352,0.60517083,229.35444,1.052,683.7683,0.856,913.12275,1.052,0.22204292,15.613609,0.36133238,88.886091,,,1,,,,5.8954845E-5,41.853456,3790.7851,3.7251398,0
20236268.55,,5905,62.3383,62.3462,-0.07,9.4E-6,61.601703,0.62945368,226.86025,0.9042,684.34944,0.8563,911.20969,0.9042,0.16144372,15.183657,0.2353717,92.269519,,,1,,,,6.0329118E-5,45.644346,3794.7698,3.6826945,0
20236913.55,,5905,67.0695,67.0994,-0.07,9.3E-6,66.312948,0.68221346,244.2499,0.9265,798.16936,0.9009,1042.4193,0.9265,0.35830138,16.583427,0.26514233,91.741909,,,1,,,,6.3174815E-5,51.049039,4397.4071,3.6832913,0
20237592.45,,5905,72.1648,72.1964,-0.07,9.3E-6,71.339299,0.68410651,268.73961,2.431,930.35272,0.9319,1199.0923,2.245,0.43664795,18.086022,,,,,1,,,,6.6299395E-5,49.475139,5089.2956,3.7670627,0
20237896.3,,5905,72.1535,72.1848,-0.07,9.3E-6,71.376693,0.72299034,258.43754,1.02,931.15287,0.9321,1189.5904,1.02,0.15780369,17.921785,0.25156702,92.318724,,,1,,,,6.6641169E-5,54.062259,5094.6323,3.6207553,0
20238621.23,,5905,77.6408,77.6689,-0.07,9.3E-6,76.812997,0.77901909,278.83505,1.025,1085.936,0.9504,1364.771,1.025,0.17770358,19.629349,0.28767892,91.671953,,,1,,,,6.9794657E-5,59.286614,5900.2364,3.6300505,0
20239388.2,,5905,83.538,83.5756,-0.07,9.2E-6,82.640818,0.79041088,307.36192,2.861,1266.0957,0.9609,1573.4576,2.694,0.38937896,21.542905,,,,,1,,,,7.3038319E-5,58.584018,6829.5048,3.7192507,0
20239740.3,,5905,83.5312,83.5614,-0.07,9.4E-6,82.681705,0.83512321,295.07708,1.166,1267.1299,0.961,1562.207,1.166,0.12228775,21.285926,0.26855165,92.349553,,,1,,,,7.3611242E-5,64.032515,6836.2643,3.5688315,0
20240565.72,,5905,89.8783,89.9423,-0.07,9.2E-6,88.996035,0.90176894,316.90331,1.111,1480.238,0.993,1797.1413,1.111,0.20731134,23.223727,0.29115556,92.014091,,,1,,,,7.7595342E-5,70.540598,7920.2943,3.5608699,0
20241442.09,,5905,96.7025,96.7812,-0.07,9.3E-6,95.736377,0.91176666,349.31607,3.281,1724.5187,1.033,2073.8347,3.114,0.34889378,25.457939,,,,,1,,,,8.1461218E-5,69.476036,9165.4539,3.6487288,0
20241875.98,,5905,96.6993,96.7689,-0.07,9.3E-6,95.780406,0.96304549,337.28312,1.1,1725.7962,1.033,2063.0794,1.1,0.49821012,25.241693,0.32231187,91.420658,,,1,,,,8.1940667E-5,75.660636,9173.8861,3.5214209,0
20242813.95,,5905,104.036,104.135,-0.07,9.2E-6,103.10218,1.0453643,362.19807,1.465,2005.9633,1.077,2368.1614,1.465,0.085631906,27.33275,0.2892108,92.422201,,,1,,,,8.6809854E-5,84.034364,10630.06,3.5130011,0
20243807.42,,5905,111.941,112.058,-0.07,9.4E-6,110.91515,1.0570071,394.03768,4.021,2315.7838,1.101,2709.8215,3.868,0.2667956,29.78587,,,,,1,,,,9.0976745E-5,81.929946,12302.171,3.5526046,0
20244335.33,,5905,111.937,112.037,-0.07,9.3E-6,110.965,1.1110017,380.48771,1.163,2317.3125,1.102,2697.8002,1.163,1.2450646,29.445014,0.2982302,92.260499,,,1,,,,9.1776081E-5,88.236316,12313.232,3.4288984,0
20245366.16,,5905,120.429,120.554,-0.07,9.4E-6,119.43827,1.2007527,406.55458,1.784,2669.9601,1.224,3076.5147,1.784,0.062833219,31.584946,0.29501766,92.448844,,,1,,,,9.7544711E-5,96.5313,14265.501,3.4038886,0
20246420.58,,5905,129.584,129.714,-0.07,9.2E-6,128.49936,1.2234816,434.65269,2.174,3061.2851,1.379,3495.9378,2.174,0.33540386,34.501397,0.96019175,79.50869,,,1,,,,0.00010174271,93.615182,16512.085,3.3825281,0
20246983.22,,5905,129.605,129.691,-0.07,9.3E-6,128.553,1.2542009,426.63258,2.494,3063.2414,1.38,3489.874,2.078,16.518026,33.373241,,,,,1,,,,0.00010457102,100.42839,16525.874,3.318729,0
20248117.88,,5905,139.418,139.511,-0.07,9.3E-6,138.33081,1.3638651,452.59025,2.463,3489.761,1.408,3942.3512,2.02,2.7800735,35.408813,,,,,1,,,,0.00011133814,109.1774,19135.414,3.2717963,0
20249085.89,,5905,150.016,150.148,-0.07,9.4E-6,148.86636,1.4159641,484.28123,3.374,3951.0922,1.512,4435.3735,3.374,0.085029021,37.755572,0.69381147,84.047437,,,1,,,,0.00011774681,105.75061,22161.193,3.2531274,0
20249660.08,,5905,149.999,150.135,-0.07,9.4E-6,148.91687,1.443818,473.69363,2.59,3953.2303,1.512,4426.924,2.103,0.056838043,36.988608,,,,,1,,,,0.00011968344,111.42881,22176.233,3.1809266,0
20250578.31,,5905,150.004,150.122,-0.07,9.4E-6,148.93274,1.4441381,482.81225,2.603,3953.878,1.512,4436.6902,2.119,0.044620251,37.021259,,,,,1,,,,0.00011984169,111.73287,22180.962,3.241814,0
20251513.38,,5905,152.573,152.684,-0.07,9.3E-6,151.46869,1.4748071,494.28848,3.291,4064.9744,1.548,4559.2629,3.291,0.17809288,38.444043,0.93321949,79.829786,,,1,,,,0.00011895577,111.50454,22942.764,3.2633046,0
20252133.31,,5905,152.559,152.684,-0.07,9.2E-6,151.49596,1.467422,476.52553,2.441,4066.0898,1.549,4542.6153,1.887,0.35806119,37.360759,,,,,1,,,,0.00012158788,112.08685,22951.026,3.1454669,0
20253121,,5905,155.151,155.25,-0.07,9.3E-6,154.05664,1.5014542,484.11823,2.586,4177.5973,1.588,4661.7156,2.042,1.0521474,37.833801,,,,,1,,,,0.00012321563,114.78122,23733.449,3.142469,0
20254070.09,,5905,157.687,157.816,-0.07,9.2E-6,156.5808,1.5256086,488.59509,3.641,4286.7668,1.629,4775.3619,3.641,0.15744984,38.974252,0.94293456,79.056846,,,1,,,,0.00012287431,113.61418,24517.548,3.1204023,0
20254702.22,,5905,157.683,157.805,-0.07,9.4E-6,156.61277,1.5146696,486.30336,2.893,4288.079,1.63,4774.3824,2.39,0.098049994,37.993667,,,,,1,,,,0.00012566259,114.23373,24527.559,3.1051323,0
20255638.72,,5905,160.253,160.335,-0.07,9.4E-6,159.13986,1.5524973,490.98967,2.308,4396.1726,1.668,4887.1623,1.595,0.076236403,38.2717,,,,,1,,,,0.00012769651,117.96958,25325.495,3.0852715,0
20256594.22,,5905,162.831,162.917,-0.07,9.3E-6,161.6956,1.5578949,510.02544,5.474,4504.9733,1.701,5014.9987,5.203,0.17634992,39.24952,,,,,1,,,,0.00012777223,115.32109,26145.466,3.1542321,0
20257233.39,,5905,162.819,162.929,-0.07,9.4E-6,161.72425,1.5678956,496.56466,2.837,4506.099,1.701,5002.6637,2.271,0.23270026,38.834432,,,,,1,,,,0.00012882031,116.02704,26154.734,3.0704403,0
20258207.53,,5905,165.379,165.471,-0.07,9.4E-6,164.28954,1.6088197,497.73728,3.02,4614.3021,1.734,5112.0394,2.473,0.74524841,39.046697,,,,,1,,,,0.00013092117,119.9137,26991.054,3.0296345,0
20259178.7,,5905,167.949,168.019,-0.07,9.3E-6,166.78377,1.6059376,516.9982,5.785,4719.3003,1.772,5236.2985,5.507,0.2280114,39.691658,,,,,1,,,,0.00013192441,117.20147,27816.825,3.0998113,0
20259868.45,,5905,167.956,167.998,-0.07,9.3E-6,166.80945,1.6106907,516.25854,3.155,4720.2648,1.772,5236.5234,2.61,5.1821653,39.216607,,,,,1,,,,0.00013352821,117.99039,27825.392,3.0948999,0
20260799.33,,5905,170.506,170.586,-0.07,9.3E-6,169.368,1.6389794,519.19772,2.826,4827.6577,1.825,5346.8554,2.158,0.063816077,39.471254,,,,,1,,,,0.00013546201,119.56763,28685.52,3.0655006,0
20261776.41,,5905,173.09,173.169,-0.07,9.4E-6,171.92509,1.6505192,524.87308,4.979,4935.1516,1.899,5460.0246,4.603,0.10530958,40.019106,,,,,1,,,,0.00013643545,118.62051,29558.237,3.0529173,0
20262425.28,,5905,173.074,173.167,-0.07,9.3E-6,171.9593,1.6578837,521.34846,2.95,4936.5712,1.9,5457.9196,2.256,0.17918965,39.760157,,,,,1,,,,0.00013727108,118.65759,29570.002,3.031813,0
20263410.73,,5905,175.65,175.735,-0.07,9.3E-6,174.52114,1.6934412,514.61537,3.425,5044.3593,2.001,5558.9747,2.779,0.58107109,39.910279,,,,,1,,,,0.00013928679,121.15152,30457.628,2.948728,0
20264391.63,,5905,178.204,178.268,-0.07,9.4E-6,177.01244,1.6912383,546.85364,5.354,5150.1831,2.145,5697.0367,4.905,0.30841932,40.437747,,,,,1,,,,0.00014088413,119.46182,31333.404,3.0893515,0
20265002.98,,5905,178.2,178.26,-0.07,9.3E-6,177.04461,1.6942716,530.9045,3.127,5151.479,2.147,5682.3835,2.273,0.031359914,39.918395,,,,,1,,,,0.00014235,119.3293,31344.794,2.9987047,0
20265989.55,,5905,180.757,180.857,-0.07,9.2E-6,179.63504,1.7313615,531.78777,3.618,5262.3015,2.351,5794.0892,2.75,0.59760409,40.226195,,,,,1,,,,0.00014403772,121.70558,32268.748,2.9603788,0
20266975.48,,5905,183.335,183.422,-0.07,9.3E-6,182.16899,1.7394396,541.25379,5.513,5371.1922,2.582,5912.446,4.87,0.13448253,40.778947,,,,,1,,,,0.00014498771,120.45347,33185.541,2.9711632,0
20267678.08,,5905,183.336,183.435,-0.07,9.3E-6,182.20171,1.7445022,529.04506,3.611,5372.5293,2.585,5901.5743,2.521,0.2700307,40.284037,,,,,1,,,,0.00014649908,120.71778,33197.463,2.9036229,0
20268668.39,,5905,185.898,185.953,-0.07,9.4E-6,184.72127,1.7761496,523.24972,3.712,5480.4385,2.826,6003.6882,2.406,0.27943684,40.412531,,,,,1,,,,0.00014856006,122.46262,34121.946,2.8326447,0
20269614.48,,5905,188.451,188.521,-0.07,9.2E-6,187.25569,1.7840553,531.68982,4.679,5588.4791,3.061,6120.1689,3.539,0.089897674,40.940935,,,,,1,,,,0.00014948777,120.96972,35064.692,2.8393788,0
20270322.14,,5905,188.467,188.507,-0.07,9.3E-6,187.28165,1.7930439,540.35952,4.268,5589.5169,3.063,6129.8764,2.972,0.42253678,40.762855,,,,,1,,,,0.00015037898,121.74429,35074.415,2.8852775,0
20271321.53,,5905,191.023,191.112,-0.07,9.3E-6,189.87589,1.8224965,521.63401,4.424,5698.4618,3.272,6220.0958,2.977,1.2470088,40.521683,,,,,1,,,,0.00015350043,123.5261,36052.852,2.7472368,0
20272314.78,,5905,193.609,193.674,-0.07,9.3E-6,192.40241,1.8307791,535.76545,7.331,5803.0282,3.427,6338.7937,6.481,0.24864916,41.128313,,,,,1,,,,0.00015412238,122.01111,37018.688,2.7846088,0
20272982.25,,5905,193.598,193.666,-0.07,9.4E-6,192.4268,1.8265313,533.62392,4.294,5803.9214,3.428,6337.5454,2.586,0.75476576,40.584835,,,,,1,,,,0.0001561555,121.62275,37028.075,2.7731268,0
20273975.8,,5905,196.149,196.191,-0.07,9.2E-6,194.95212,1.8593797,513.73797,4.187,5905.8543,3.513,6419.5923,2.279,0.19357841,40.517872,,,,,1,,,,0.00015843854,122.95762,38006.33,2.6352007,0
20274921.05,,5905,198.74,198.782,-0.07,9.3E-6,197.51743,1.8586818,530.59551,6.571,6007.2098,3.523,6537.8053,5.546,0.096476336,40.887819,,,,,1,,,,0.00015989616,120.81256,39013.133,2.6863225,0
20275540.73,,5905,198.717,198.783,-0.07,9.3E-6,197.54538,1.8570939,528.49343,5.08,6008.2071,3.523,6536.7005,3.66,0.083007496,40.337983,,,,,1,,,,0.00016204827,120.97297,39024.176,2.6753014,0
20276532.33,,5905,201.293,201.361,-0.07,9.4E-6,200.1066,1.8864288,540.97823,4.725,6107.2404,3.471,6648.2187,3.205,0.46684724,40.308752,,,,,1,,,,0.00016493239,122.64791,40042.653,2.7034502,0
20277525.08,,5905,203.836,203.928,-0.07,9.3E-6,202.63714,1.9045486,562.9103,6.098,6203.7584,3.376,6766.6687,5.078,0.17960308,41.120434,,,,,1,,,,0.00016455733,121.53508,41061.812,2.7779226,0
20278238.52,,5905,203.83,203.922,-0.07,9.4E-6,202.67409,1.9185374,549.86358,4.071,6205.0834,3.375,6754.947,2.277,0.96874841,40.784556,,,,,1,,,,0.00016562512,122.62711,41076.786,2.7130433,0
20279237.45,,5905,206.412,206.448,-0.07,9.4E-6,205.18964,1.9437076,565.37358,4.171,6299.5142,3.253,6864.8878,2.611,0.11884574,40.826272,,,,,1,,,,0.00016814878,123.55095,42102.788,2.755371,0
20280233.89,,5905,208.97,209.067,-0.07,9.4E-6,207.75629,1.9560242,576.62544,7.666,6394.9811,3.116,6971.6066,7.004,0.40230193,41.225337,,,,,1,,,,0.00016910975,122.54879,43162.674,2.7754897,0
20280944.94,,5905,208.984,209.053,-0.07,9.4E-6,207.79219,1.964283,555.48665,4.053,6396.2733,3.115,6951.7599,2.594,1.7553039,40.861391,,,,,1,,,,0.00017013028,122.4192,43177.596,2.6732797,0
20281900.63,,5905,211.525,211.617,-0.07,9.2E-6,210.34245,1.9911601,556.5602,4.553,6490.2459,2.984,7046.8061,3.439,0.048322705,40.689077,,,,,1,,,,0.00017318668,123.67038,44243.945,2.6459719,0
20282897.36,,5905,214.093,214.197,-0.07,9.2E-6,212.86368,1.9912148,608.85809,7.768,6582.9605,2.876,7191.8186,7.216,0.45918742,41.227243,,,,,1,,,,0.00017444335,121.80081,45310.944,2.8603193,0
20283565.45,,5905,214.117,214.162,-0.07,9.3E-6,212.90237,2.0031279,561.28358,4.427,6584.2609,2.874,7145.5445,3.366,0.46757318,40.651026,,,,,1,,,,0.00017577771,122.19227,45327.418,2.6363426,0
20284562.75,,5905,216.677,216.69,-0.07,9.2E-6,215.40953,2.0320735,598.22099,5.386,6676.2139,2.803,7274.4349,4.598,0.32444377,40.882605,,,,,1,,,,0.00017793472,123.25009,46401.266,2.7771333,0
20285515.42,,5905,219.234,219.275,-0.07,9.2E-6,217.93515,2.0301047,618.82573,8.047,6769.0734,2.776,7387.8992,7.553,0.36190407,41.089203,,,,,1,,,,0.00017980147,121.28272,47495.729,2.8394949,0
20286225.67,,5905,219.226,219.285,-0.07,9.4E-6,217.96373,2.0409889,624.74311,4.114,6770.0523,2.776,7394.7954,3.036,0.10482535,40.831737,,,,,1,,,,0.00018110411,122.34034,47508.187,2.866271,0
20287220.14,,5905,221.792,221.877,-0.07,9.4E-6,220.5615,2.0700159,614.68134,5.575,6865.5131,2.77,7480.1944,4.839,2.3824036,40.683453,,,,,1,,,,0.00018386331,123.18523,48647.377,2.7868931,0
20288214.59,,5905,224.349,224.418,-0.07,9.2E-6,223.0902,2.0856133,618.73676,7.49,6958.2784,2.78,7577.0151,6.955,0.27218434,40.974592,,,,,1,,,,0.00018491984,122.55763,49769.236,2.7734825,0
20288836.06,,5905,224.358,224.429,-0.07,9.4E-6,223.11899,2.0750778,633.17016,4.517,6959.28,2.78,7592.4501,3.56,0.040858563,40.488908,,,,,1,,,,0.00018751926,121.6132,49782.085,2.8378138,0
20289863.98,,5905,226.924,226.956,-0.07,9.4E-6,225.63149,2.1109603,613.29039,4.454,7050.9772,2.804,7664.2676,3.461,0.41579826,40.500978,,,,,1,,,,0.00018923661,122.4059,50909.569,2.7181064,0
20290868.63,,5905,229.489,229.513,-0.07,9.4E-6,228.15208,2.1122704,649.4947,7.003,7142.3835,2.841,7791.8782,6.401,0.66232667,40.698234,,,,,1,,,,0.00019145495,121.31273,52053.372,2.8467621,0
20291528.72,,5905,229.487,229.509,-0.07,9.2E-6,228.18143,2.1161109,624.64407,4.336,7143.4367,2.841,7768.0808,3.276,0.17891364,40.255444,,,,,1,,,,0.0001929697,121.0831,52066.766,2.7374886,0
20292525.2,,5905,232.043,232.118,-0.07,9.3E-6,230.77814,2.1521133,621.7505,4.795,7236.554,2.888,7858.3045,3.828,0.82082949,40.231337,,,,,1,,,,0.00019532795,122.23229,53258.549,2.6941482,0
20293468.31,,5905,234.62,234.674,-0.07,9.4E-6,233.29535,2.1517021,646.84078,8.05,7325.8989,2.941,7972.7397,7.493,0.75314218,40.503735,,,,,1,,,,0.00019683962,120.2935,54426.718,2.7726262,0
20294127.25,,5905,234.622,234.667,-0.07,9.2E-6,233.3346,2.163396,627.50723,4.765,7327.2706,2.942,7954.7778,3.748,0.53254583,40.268804,,,,,1,,,,0.00019754194,120.18274,54445.036,2.6893021,0
20295128.75,,5905,237.181,237.234,-0.07,9.2E-6,235.88167,2.1955238,618.16262,4.616,7416.2015,3.001,8034.3642,3.507,0.14258413,40.140881,,,,,1,,,,0.00020015415,120.93417,55640.163,2.6206471,0
20296067.14,,5905,239.751,239.742,-0.07,9.4E-6,238.3665,2.1934375,639.59447,5.835,7501.4431,3.062,8141.0375,4.968,0.28796803,40.245534,,,,,1,,,,0.00020228425,119.394,56818.587,2.6832398,0
20296766.78,,5905,239.748,239.744,-0.07,9.4E-6,238.39963,2.2088956,625.19751,4.544,7502.4937,3.063,8127.6912,3.357,1.0209565,39.926068,,,,,1,,,,0.00020356853,120.18796,56834.385,2.6224768,0
20297708.44,,5905,242.308,242.311,-0.07,9.3E-6,240.96024,2.2296314,610.13467,4.648,7588.5084,3.126,8198.6431,3.44,0.053495387,39.724417,,,,,1,,,,0.000206388,119.71751,58061.838,2.5320968,0
20298691.25,,5905,244.872,244.929,-0.07,9.4E-6,243.5312,2.2388448,633.09748,7.004,7673.4498,3.204,8306.5473,6.228,0.33754476,39.958087,,,,,1,,,,0.00020788151,118.73819,59307.447,2.5996565,0
20299341.2,,5905,244.883,244.93,-0.07,9.4E-6,243.57253,2.2490818,620.64179,5.053,7674.7711,3.206,8295.4129,3.905,0.3532503,39.610669,,,,,1,,,,0.0002094237,118.98723,59327.576,2.5480779,0
20300276.94,,5905,247.44,247.496,-0.07,9.4E-6,246.13041,2.2740625,617.95825,4.572,7757.9989,3.306,8375.9571,3.158,0.027273058,39.442735,,,,,1,,,,0.00021235741,119.08663,60580.178,2.5106945,0
20301206.33,,5905,249.99,250.069,-0.07,9.2E-6,248.65124,2.2753457,670.56541,8.149,7839.0565,3.42,8509.6219,7.396,0.27948812,39.774137,,,,,1,,,,0.00021394862,117.73523,61827.437,2.6968111,0
20301809,,5905,249.993,250.048,-0.07,9.3E-6,248.69213,2.2841192,631.84414,4.697,7840.2886,3.422,8472.1327,3.217,0.030647335,39.229254,,,,,1,,,,0.00021596467,117.90089,61847.773,2.5406681,0
20302841.23,,5905,250,250.053,-0.07,9.4E-6,248.69418,2.2849413,627.1984,4.527,7840.3692,3.422,8467.5676,2.963,0.1716283,39.3091,,,,,1,,,,0.00021540986,117.76615,61848.793,2.5219666,0
20303881,,5905,260,260.077,-0.07,9.3E-6,258.57987,2.3722952,659.90834,10.86,8145.0408,3.893,8804.9492,10.13,0.16270992,39.063827,,,,,1,,,,0.00022539904,117.73987,66863.551,2.5520484,0
20304475.25,,5905,259.999,260.055,-0.07,9.3E-6,258.64553,2.3701845,620.34047,4.793,8146.9709,3.896,8767.3114,2.791,0.011160226,38.628785,,,,,1,,,,0.00022696317,115.92145,66897.509,2.3984195,0
20305131.86,,5905,270.006,270.012,-0.07,9.2E-6,268.4624,2.4423965,654.12225,7.705,8426.8498,4.124,9080.972,7.705,0.2279805,39.266478,3.3580945,43.509519,,,1,,,,0.00023297008,115.88636,72072.06,2.4365507,0