File: HeatCapacity/ML_PPMS_20200809_MKS_LP_unox_BWO_5pt14mg_HC_2-300K_0T.dat
[Header]
TITLE,ML_PPMS_20200809_MKS_LP_unox_BWO_5pt14mg_HC_2-300K_0T.dat
BYAPP,HeatCapacity,3.9.6,1.7
INFO,5.14,MASS:Sample Mass (mg)
INFO,0.01,MASSERR:Sample Mass Error (mg)
INFO,697.80,MOLWGHT:Formula Weight (g/mole)
INFO,,ATOMS:Atoms per Formula Unit
INFO,PPMS Heat Capacity Option 3.9.6 Build 3,APPNAME
DATATYPE,TIME,1
DATATYPE,COMMENT,2
STARTUPAXIS, X, 8, LINEAR, AUTO
STARTUPAXIS, Y1, 10, LINEAR, AUTO
[Data]
Time Stamp (Seconds),Comment (),System Status (Code),Puck Temp (Kelvin),System Temp (Kelvin),Field (Oersted),Pressure (Torr),Sample Temp (Kelvin),Temp Rise (Kelvin),Samp HC (µJ/K),Samp HC Err (µJ/K),Addenda HC (µJ/K),Addenda HC Err (µJ/K),Total HC (µJ/K),Total HC Err (µJ/K),Fit Deviation (ChiSquare),Time Const tau1 (seconds),Time Const tau2 (seconds),Sample Coupling (Percent),Debye Temp (Kelvin),Debye Temp Err (Kelvin),Cal Correction (Factor),Therm Resist (Ohms),Htr Resist (Ohms),Puck Resist (Ohms),Wire Cond (W/K),Meas Time (seconds),Temp Squared (K^2),Samp HC/Temp (µJ/K/K),Addenda Offset HC (µJ/K)
19147371.86,CALFILE: C:\QdPpms\HEATCA~1\TempCal\Standard\Puck1074_1.cal|Addenda #292 measured on 8/8/2020 from 1.9802 to 298.26 K
19147371.98,,5905,2.00023,1.9842,0.009,9.4E-6,1.9808261,0.020746621,0.028770527,0.001074,0.26625903,0.0007234,0.29502956,0.000794,2.3887366,0.17470003,,,,,1,,,,1.6887779E-6,0.53927548,3.9236719,0.01452451,0
19147389.58,,5905,1.99992,1.9839,0.009,9.3E-6,1.9799804,0.020354417,0.029322967,0.001032,0.26602669,0.0007223,0.29534966,0.0007367,2.8142182,0.17392796,,,,,1,,,,1.6981149E-6,0.5241001,3.9203222,0.014809726,0
19147407.69,,5905,2.00046,1.9841,0.009,9.3E-6,1.9805033,0.02039426,0.028946194,0.001079,0.26617848,0.000723,0.29512467,0.0008013,2.9294286,0.17476511,,,,,1,,,,1.6886933E-6,0.52178387,3.9223934,0.014615575,0
19147687.38,,5905,2.15318,2.1459,0.009,9.2E-6,2.1449439,0.021470239,0.045096991,0.002794,0.31832175,0.0009361,0.36341874,0.002633,1.1061686,0.20756411,,,,,1,,,,1.7508747E-6,0.52429532,4.6007845,0.021024788,0
19147705.95,,5905,2.15335,2.1469,0.009,9.3E-6,2.1446528,0.02260208,0.043178736,0.004037,0.31806643,0.0009352,0.36124517,0.003927,0.080994035,0.19443691,,,,,1,,,,1.8579043E-6,0.62269234,4.5995356,0.020133206,0
19147726.86,,5905,2.15298,2.146,0.009,9.3E-6,2.1443326,0.022015819,0.041857811,0.002322,0.31800599,0.000935,0.35986381,0.002126,0.2077861,0.19445286,,,,,1,,,,1.8506481E-6,0.58331072,4.5981622,0.019520205,0
19147923.41,,5905,2.31538,2.3148,0.009,9.3E-6,2.3002458,0.02250724,0.046897436,0.002661,0.37746122,0.001128,0.42435866,0.00241,0.25617664,0.21033616,,,,,1,,,,2.017526E-6,0.58335858,5.2911309,0.02038801,0
19147945.52,,5905,2.31563,2.3152,0.009,9.4E-6,2.299239,0.023307673,0.050082146,0.001624,0.37699811,0.001127,0.42708026,0.00117,0.22583966,0.21210679,,,,,1,,,,2.0135153E-6,0.63100847,5.2865,0.021782053,0
19147964.73,,5905,2.31582,2.3164,0.009,9.4E-6,2.299325,0.023362074,0.05000792,0.002783,0.37700498,0.001127,0.4270129,0.002545,0.12675444,0.21119074,,,,,1,,,,2.02193E-6,0.63632036,5.2868956,0.021748957,0
19148160.3,,5905,2.49663,2.4865,0.009,9.2E-6,2.4671287,0.023794617,0.060889386,0.00229,0.45094015,0.00129,0.51182953,0.001893,1.8201623,0.23531123,,,,,1,,,,2.1751173E-6,0.63357221,6.086724,0.024680263,0
19148181.73,,5905,2.49493,2.4858,0.009,9.4E-6,2.4668291,0.025300057,0.063580782,0.002446,0.45073787,0.00129,0.51431865,0.002079,3.579962,0.24075998,,,,,1,,,,2.1362298E-6,0.70593369,6.0852459,0.025774295,0
19148203.05,,5905,2.49359,2.4833,0.009,9.4E-6,2.4660829,0.024818232,0.067612524,0.002821,0.45030467,0.001289,0.51791719,0.002509,0.19930578,0.23133083,,,,,1,,,,2.2388594E-6,0.72227995,6.0815648,0.027416971,0
19148394.09,,5905,2.68294,2.6784,0.009,9.3E-6,2.647201,0.025370381,0.07886126,0.002515,0.53936175,0.001315,0.61822301,0.002143,0.23047519,0.26288946,,,,,1,,,,2.3516462E-6,0.69399249,7.007673,0.029790432,0
19148414.14,,5905,2.68169,2.6751,0.009,9.2E-6,2.6481407,0.026943694,0.073877935,0.002202,0.53971834,0.001315,0.61359628,0.001766,1.1564397,0.25978782,,,,,1,,,,2.3619132E-6,0.78866839,7.0126492,0.02789804,0
19148433.3,,5905,2.68289,2.6765,0.009,9.4E-6,2.6482895,0.026743863,0.079133794,0.002231,0.53983346,0.001316,0.61896725,0.001802,1.2884649,0.262941,,,,,1,,,,2.3540157E-6,0.77936346,7.0134374,0.029881096,0
19148644.55,,5905,2.88969,2.8542,0.009,9.4E-6,2.8519917,0.02731783,0.074667632,0.005614,0.65490687,0.001485,0.7295745,0.005414,0.10308267,0.27390518,,,,,1,,,,2.6636024E-6,0.78882301,8.1338567,0.026180873,0
19148670.42,,5905,2.89313,2.8596,0.009,9.4E-6,2.8523428,0.029476804,0.081486785,0.001683,0.65455818,0.001485,0.73604496,0.001683,1.4775569,0.27631524,1.9567514E-6,99.992808,,,1,,,,2.6637895E-6,0.82171554,8.1358595,0.02856837,0
19148695.75,,5905,2.89115,2.8554,0.009,9.4E-6,2.8505878,0.027909864,0.081062962,0.008941,0.65403573,0.001484,0.73509869,0.008817,0.012388499,0.27704942,,,,,1,,,,2.6533125E-6,0.82894571,8.1258506,0.02843728,0
19148902.06,,5905,3.1106,3.0833,0.009,9.4E-6,3.0635401,0.028289415,0.12505892,0.003847,0.79218406,0.001929,0.91724298,0.003328,0.45042465,0.32296418,,,,,1,,,,2.8400765E-6,0.83114827,9.3852777,0.040821702,0
19148923.63,,5905,3.10927,3.0805,0.009,9.3E-6,3.0641884,0.030479266,0.12999078,0.00307,0.79243649,0.001931,0.92242727,0.002387,0.5058514,0.32748809,,,,,1,,,,2.8166742E-6,0.96889253,9.3892504,0.04242258,0
19148942.31,,5905,3.10864,3.0832,0.009,9.4E-6,3.0642619,0.030543227,0.1054449,0.00193,0.79236107,0.00193,0.89780598,0,0.073464203,0.31120551,,,,,1,,,,2.8849296E-6,0.98246428,9.3897008,0.034411193,0
19149139.5,,5905,3.34448,3.3189,0.009,9.3E-6,3.2937218,0.030647411,0.13397864,0.004669,0.95994587,0.002877,1.0939245,0.003677,1.4508087,0.35202268,,,,,1,,,,3.1075399E-6,0.93361653,10.848603,0.040676975,0
19149158.58,,5905,3.34421,3.3198,0.009,9.2E-6,3.2925994,0.032183963,0.17451166,0.00518,0.95891385,0.002872,1.1334255,0.004311,1.2062434,0.36911377,,,,,1,,,,3.0706671E-6,1.056068,10.841211,0.053001182,0
19149180.53,,5905,3.34319,3.3193,0.009,9.4E-6,3.2938477,0.032023341,0.11977612,0.006487,0.95952961,0.002875,1.0793057,0.005815,2.3401411,0.32553151,,,,,1,,,,3.3155185E-6,1.1073413,10.849432,0.036363588,0
19149358.05,Error: Warning:  Measured time constant less than time constant calculated from addenda table.  Changing time constant to addenda table value
19149380.05,,5905,3.59572,3.5778,0.009,9.3E-6,3.5384253,0.033788947,0.14429929,0.005694,1.217843,0.003861,1.3621423,0.004185,0.54707831,0.41170469,,,,,1,,,,3.3085421E-6,1.103018,12.520454,0.040780651,0
19149406.42,,5905,3.59619,3.5771,0.009,9.3E-6,3.5393407,0.036438051,0.17200559,0.004022,1.2177333,0.003861,1.3897389,0.004022,0.80372951,0.41355018,3.6877917E-6,99.991778,,,1,,,,3.3605126E-6,1.2351141,12.526932,0.048598201,0
19149426.23,,5905,3.59525,3.5764,0.009,9.4E-6,3.5381145,0.035726009,0.14534154,0.00516,1.2171949,0.003859,1.3625364,0.003425,1.1929463,0.41301923,,,,,1,,,,3.2989661E-6,1.2406505,12.518255,0.041078811,0
19149607.25,Error: Warning:  Measured time constant less than time constant calculated from addenda table.  Changing time constant to addenda table value
19149630.61,,5905,3.86813,3.8583,0.009,9.4E-6,3.8026412,0.035465301,0.15369783,0.007266,1.53739,0.004544,1.6910878,0.00567,0.79673945,0.44512829,,,,,1,,,,3.799102E-6,1.2739352,14.46008,0.040418703,0
19149679.06,,5905,3.86716,3.8586,0.009,9.4E-6,3.80211,0.035624177,0.22467453,0.004862,1.5378005,0.004544,1.7624751,0.004862,1.8735612,0.49835224,0.075654744,40.955091,,,1,,,,3.6347782E-6,1.4105841,14.45604,0.059092066,0
19149905.17,,5905,4.16052,4.1566,0.009,9.4E-6,4.0918797,0.042051376,0.1756239,0.00991,1.8851902,0.004512,2.0608141,0.008823,0.23435046,0.52083098,,,,,1,,,,3.956781E-6,1.678372,16.74348,0.042920103,0
19150132.11,,5905,4.47595,4.469,0.009,9.3E-6,4.4001738,0.041263465,0.36855883,0.00778,2.2734773,0.004108,2.6420361,0.006606,0.20910775,0.61642241,,,,,1,,,,4.2860805E-6,1.5937877,19.361529,0.083760061,0
19150178.05,,5905,4.47478,4.4692,0.009,9.2E-6,4.3997164,0.042344327,0.40305952,0.009965,2.2726798,0.004109,2.6757393,0.009078,2.3160989,0.62260971,,,,,1,,,,4.297619E-6,1.7049169,19.357504,0.091610342,0
19150423.11,,5905,4.81045,4.8047,0.009,9.4E-6,4.7260029,0.04481558,0.61250637,0.02637,2.7393667,0.00406,3.351873,0.02606,1.4867443,0.7278054,,,,,1,,,,4.6054523E-6,1.8581183,22.335103,0.12960347,0
19150668.53,,5905,5.17872,5.1759,0.009,9.4E-6,5.0855965,0.050417746,0.71210037,0.007141,3.341884,0.00488,4.0539843,0.007141,0.13923984,0.77244216,0.023917942,82.182545,,,1,,,,5.2845065E-6,2.3661428,25.863292,0.14002298,0
19150716.86,,5905,5.17908,5.175,0.009,9.2E-6,5.0854105,0.051351075,0.62512293,0.01016,3.3415974,0.004879,3.9667203,0.008912,0.18241023,0.7611188,,,,,1,,,,5.2116967E-6,2.3652648,25.8614,0.12292477,0
19150951.56,,5905,5.57041,5.5701,0.009,9.4E-6,5.4681933,0.054934171,0.82408942,0.006409,4.0469837,0.005354,4.8710732,0.006409,0.3150334,0.84518411,0.010449749,91.876808,,,1,,,,5.7780955E-6,2.5958728,29.901138,0.15070598,0
19151188.02,,5905,5.99263,5.9987,0.009,9.4E-6,5.8781244,0.053938335,1.1886918,0.0168,4.8968175,0.006394,6.0855092,0.01553,0.59477662,0.94993816,,,,,1,,,,6.4062162E-6,2.529677,34.552347,0.20222297,0
19151236.66,,5905,5.99292,5.9966,0.009,9.3E-6,5.8800775,0.057304776,1.1376989,0.01699,4.8970084,0.006394,6.0347073,0.01574,0.14052642,0.92090087,,,,,1,,,,6.5530477E-6,2.9365909,34.575312,0.19348366,0
19151498.38,,5905,6.43575,6.4667,0.009,9.2E-6,6.3190448,0.062291804,0.95042406,0.08487,5.9159616,0.008294,6.8663857,0.08447,55.953622,0.92556677,,,,,1,,,,7.4185741E-6,3.2645287,39.930327,0.15040629,0
19151752.53,,5905,6.93176,6.963,0.009,9.3E-6,6.7924675,0.062604283,2.1647176,0.01201,7.1025707,0.01043,9.2672883,0.01201,1.6479597,1.2126968,0.016457462,92.898149,,,1,,,,7.6742002E-6,3.1310025,46.137615,0.31869384,0
19151802.13,,5905,6.93318,6.9632,0.009,9.2E-6,6.7964817,0.067272368,2.0903506,0.01211,7.1144314,0.01045,9.204782,0.01211,1.0978375,1.2181617,0.020251845,91.268375,,,1,,,,7.5942044E-6,3.6003258,46.192163,0.30756363,0
19152055.67,,5905,7.45642,7.4936,0.009,9.3E-6,7.3146438,0.074367457,2.7414038,0.01632,8.6059343,0.01198,11.347338,0.01632,0.073087609,1.3556602,0.010047587,96.094299,,,1,,,,8.390346E-6,4.2565079,53.504014,0.37478296,0
19152311.98,,5905,8.02254,8.0606,0.009,9.4E-6,7.8614565,0.073596305,3.7778934,0.01499,10.398776,0.01301,14.176669,0.01499,1.9560034,1.5759218,0.015071028,95.304299,,,1,,,,9.027576E-6,3.9811964,61.802498,0.48055897,0
19152365.36,,5905,8.02468,8.0648,0.009,9.2E-6,7.8662178,0.07787077,3.8430013,0.01522,10.41528,0.01302,14.258282,0.01522,0.68360534,1.5447552,0.013384435,95.758444,,,1,,,,9.2600848E-6,4.6658496,61.877383,0.48854499,0
19152633.38,,5905,8.6365,8.6736,0.009,9.2E-6,8.4619932,0.083974445,5.3454094,0.01697,12.492437,0.01541,17.837847,0.01697,0.67020407,1.7805185,0.014390635,96.266553,,,1,,,,1.005352E-5,5.2751331,71.605329,0.63169626,0
19152899.42,,5905,9.28568,9.3244,0.009,9.4E-6,9.093057,0.085054357,7.1040825,0.02219,14.913005,0.01812,22.017088,0.02219,0.42050004,2.0105519,0.017381698,96.164097,,,1,,,,1.0996644E-5,5.2443046,82.683686,0.78126448,0
19152957.61,,5905,9.288,9.3291,0.009,9.3E-6,9.0967105,0.090468008,7.441681,0.02243,14.923506,0.01813,22.365187,0.02243,0.30223216,2.0588346,0.016313143,96.527435,,,1,,,,1.0906646E-5,5.9489328,82.750142,0.81806286,0
19153239.34,,5905,9.99584,10.0439,0.009,9.2E-6,9.7899637,0.096759548,9.2744324,0.02845,17.85885,0.02102,27.133283,0.02845,3.0154214,2.2087613,0.0098761941,98.042277,,,1,,,,1.2313177E-5,6.6512744,95.843389,0.94734083,0
19153762.08,,5905,10.7654,10.778,0.009,9.4E-6,10.53322,0.094611124,12.200234,0.02987,21.362733,0.02346,33.562966,0.02987,1.0513303,2.521603,0.017887879,97.001377,,,1,,,,1.3364929E-5,6.0901224,110.94872,1.1582625,0
19153832.14,,5905,10.7661,10.7774,0.009,9.2E-6,10.537784,0.10516502,12.386384,0.0286,21.382133,0.02347,33.768517,0.0286,0.96246556,2.5446806,0.019630659,96.756971,,,1,,,,1.3330548E-5,7.6147066,111.0449,1.1754259,0
19154123.58,,5905,11.5801,11.5979,0.009,9.3E-6,11.331779,0.11413109,15.927281,0.03731,25.395789,0.03009,41.323071,0.03731,1.4667443,2.848189,0.017798041,97.409797,,,1,,,,1.4566217E-5,8.6036177,128.40922,1.4055411,0
19154423.8,,5905,12.4582,12.4731,0.009,9.2E-6,12.185885,0.11684194,20.421117,0.04546,30.098285,0.03789,50.519402,0.04546,2.883188,3.2001769,0.01998811,97.450786,,,1,,,,1.5854342E-5,8.6510221,148.49579,1.6758009,0
19154504.36,,5905,12.459,12.4739,0.009,9.3E-6,12.19069,0.12343412,20.661127,0.0458,30.121818,0.03791,50.782945,0.0458,1.7835798,3.2343641,0.022638056,97.154593,,,1,,,,1.5777716E-5,9.6490791,148.61291,1.6948284,0
19154815.88,,5905,13.4076,13.4092,0.009,9.4E-6,13.12032,0.13282629,26.07544,0.04921,35.775487,0.04146,61.850927,0.04921,1.6185402,3.5903244,0.021486,97.583915,,,1,,,,1.7303381E-5,10.784345,172.14278,1.9874089,0
19155131.95,,5905,14.4219,14.4371,0.009,9.3E-6,14.10792,0.1349512,32.564085,0.06423,42.209085,0.05291,74.77317,0.06423,2.1446812,4.0411173,0.031044888,96.934174,,,1,,,,1.8614952E-5,10.66741,199.03342,2.308213,0
19155224.73,,5905,14.4232,14.4388,0.009,9.4E-6,14.11447,0.14336123,32.70654,0.06535,42.247663,0.05299,74.954204,0.06535,1.9450903,4.034417,0.026567309,97.365969,,,1,,,,1.8675031E-5,12.040802,199.21827,2.3172347,0
19155567.66,,5905,15.5168,15.5374,0.009,9.2E-6,15.18987,0.15537672,40.353539,0.08841,49.827789,0.06774,90.181328,0.08841,0.59025243,4.5127473,0.03282344,97.108773,,,1,,,,2.0103697E-5,13.470232,230.73215,2.6566086,0
19155902.33,,5905,16.6952,16.7113,0.009,9.2E-6,16.344926,0.1583416,48.747017,0.09702,58.724858,0.08082,107.47187,0.09702,1.527707,4.9291811,0.029455365,97.622468,,,1,,,,2.1913096E-5,13.354718,267.1566,2.9823945,0
19156012.89,,5905,16.6975,16.7111,0.009,9.2E-6,16.351032,0.16641949,48.947355,0.09642,58.769297,0.08088,107.71665,0.09642,0.67898621,4.9422649,0.032438491,97.392842,,,1,,,,2.1916271E-5,14.804845,267.35624,2.9935331,0
19156369.39,,5905,17.9655,17.9715,0.009,9.3E-6,17.595543,0.17934195,58.697189,0.1111,69.079244,0.09078,127.77643,0.1111,2.1340617,5.4397861,0.034516012,97.482023,,,1,,,,2.3618096E-5,16.251106,309.60314,3.3359123,0
19156741.38,,5905,19.3288,19.343,0.009,9.3E-6,18.931985,0.18102269,71.364187,0.2692,80.809609,0.1043,152.1738,0.2481,13.294516,5.9251113,,,,,1,,,,2.5682859E-5,16.325588,358.42007,3.7695036,0
19156875.72,,5905,19.3312,19.3411,0.009,9.4E-6,18.938552,0.19009905,70.710276,0.2499,80.864941,0.1043,151.57522,0.2271,3.9312477,5.9045015,,,,,1,,,,2.5671129E-5,17.95467,358.66876,3.7336685,0
19157265.84,,5905,20.7986,20.8112,0.009,9.2E-6,20.387351,0.2110164,82.776353,0.1391,94.261808,0.1257,177.03816,0.1391,5.1216635,6.5403492,0.041584974,97.481895,,,1,,,,2.7222454E-5,19.822546,415.64409,4.0601818,0
19157662.77,,5905,22.3758,22.3896,0.009,9.3E-6,21.937219,0.21711508,96.956431,0.1669,109.79792,0.1508,206.75435,0.1669,0.95350338,7.1755596,0.050569193,97.213922,,,1,,,,2.8996584E-5,19.585764,481.24159,4.4197229,0
19157811.53,,5905,22.3771,22.3897,0.009,9.3E-6,21.94331,0.22742064,97.020287,0.1708,109.85739,0.1509,206.87768,0.1708,1.0730716,7.1874517,0.052253203,97.127315,,,1,,,,2.8971788E-5,21.472002,481.50885,4.4214062,0
19158227.67,,5905,24.0759,24.0921,0.009,9.3E-6,23.622377,0.24520861,112.50968,0.1997,127.60365,0.1823,240.11333,0.1997,0.5024945,7.7838608,0.055614425,97.175804,,,1,,,,3.104585E-5,23.375253,558.01671,4.7628431,0
19158652.39,,5905,25.9,25.9223,0.009,9.3E-6,25.420493,0.25421546,128.87694,0.2426,147.54678,0.2202,276.42372,0.2426,1.1036629,8.4815621,0.064518255,96.994783,,,1,,,,3.2812324E-5,23.389844,646.20146,5.0698048,0
19158818.36,,5905,25.9026,25.9215,0.009,9.3E-6,25.42866,0.26572891,128.98824,0.2413,147.62196,0.2203,276.6102,0.2413,0.35721454,8.4730858,0.061495062,97.13059,,,1,,,,3.2857002E-5,25.456366,646.61674,5.0725537,0
19159260.42,,5905,27.8685,27.885,0.009,9.3E-6,27.369246,0.28703139,146.85143,0.2839,170.11792,0.265,316.96935,0.2839,2.6150018,9.1898097,0.075384744,96.761418,,,1,,,,3.474125E-5,27.533735,749.07564,5.3655637,0
19159714.3,,5905,29.9811,30.0131,0.009,9.2E-6,29.45566,0.29805733,166.35278,0.3397,195.66739,0.304,362.02018,0.3397,0.62869464,9.965881,0.085339069,96.618875,,,1,,,,3.6596711E-5,27.440681,867.63592,5.647566,0
19159904.28,,5905,29.9842,30.0122,0.009,9.3E-6,29.465606,0.31003921,166.69294,0.3296,195.77158,0.3041,362.46453,0.3296,0.51008649,9.9163691,0.078786299,96.858866,,,1,,,,3.6804869E-5,29.693168,868.22191,5.6572041,0
19160379.77,,5905,32.2611,32.2903,0.009,9.3E-6,31.721632,0.33579596,186.57811,0.3678,224.8979,0.3417,411.47601,0.3678,1.5185868,10.61661,0.084557349,96.845488,,,1,,,,3.9019422E-5,32.297415,1006.2619,5.8817312,0
19160862.61,,5905,34.7067,34.744,0.009,9.3E-6,34.130048,0.34662646,210.50797,0.4584,257.66962,0.3969,468.17759,0.4584,0.57970474,11.603399,0.1133029,96.143876,,,1,,,,4.0678736E-5,31.860164,1164.8602,6.1678193,0
19161088.25,,5905,34.7149,34.7353,0.009,9.2E-6,34.144454,0.36007511,210.53006,0.426,257.8275,0.3972,468.35756,0.426,1.2725469,11.482527,0.096579337,96.66788,,,1,,,,4.1075231E-5,34.395878,1165.8437,6.1658641,0
19161597.06,,5905,37.3513,37.3759,0.009,9.2E-6,36.761295,0.39056501,232.0299,0.4832,294.9813,0.4587,527.01121,0.4832,1.6952254,12.317121,0.11102357,96.421796,,,1,,,,4.3097489E-5,37.40959,1351.3928,6.311799,0
19162132.44,,5905,40.1796,40.2231,0.009,9.2E-6,39.552921,0.4018292,257.45253,0.6342,336.84257,0.5191,594.29509,0.6342,0.50732793,13.408174,0.14859403,95.609144,,,1,,,,4.470967E-5,36.631488,1564.4336,6.5090648,0
19162367.84,,5905,40.1901,40.2097,0.009,9.2E-6,39.569105,0.41604691,254.25835,0.6007,337.03228,0.5194,591.29063,0.6007,0.16432391,13.06857,0.113479,96.534059,,,1,,,,4.5548265E-5,39.418969,1565.714,6.4256786,0
19162912.03,,5905,43.2379,43.2542,0.009,9.4E-6,42.589474,0.45088464,280.86097,0.6065,385.30565,0.5687,666.16662,0.6065,0.97948491,14.154846,0.13595956,96.157927,,,1,,,,4.7400315E-5,43.013394,1813.8633,6.5946099,0
19163465.95,,5905,46.5123,46.5524,0.009,9.2E-6,45.821496,0.46223698,308.10544,0.7388,440.50526,0.6311,748.6107,0.7388,0.46314964,15.303982,0.1735694,95.456494,,,1,,,,4.9315023E-5,42.011711,2099.6095,6.7240371,0
19163729.95,,5905,46.5208,46.5414,0.009,9.4E-6,45.843567,0.47898947,306.1221,0.7055,440.83078,0.6315,746.95287,0.7055,0.18713629,15.012449,0.13951253,96.252781,,,1,,,,5.0083978E-5,45.31395,2101.6326,6.6775366,0
19164317.36,,5905,50.0489,50.0712,0.009,9.2E-6,49.342187,0.51611809,333.11985,0.7546,505.18896,0.6915,838.3088,0.7546,0.25201709,16.106148,0.15380263,96.117564,,,1,,,,5.2384193E-5,48.990409,2434.6514,6.7512177,0
19164915.89,,5905,53.8509,53.866,0.009,9.3E-6,53.089628,0.5301439,363.30773,0.8874,580.14584,0.7312,943.45356,0.8874,0.20074476,17.54652,0.20963725,95.126274,,,1,,,,5.4182185E-5,48.112052,2818.5086,6.8432901,0
19165229.2,,5905,53.8503,53.8547,0.009,9.3E-6,53.10712,0.54905232,360.8655,0.7552,580.43563,0.7313,941.30114,0.7552,0.97442773,17.249457,0.171853,95.90669,,,1,,,,5.4915671E-5,51.775638,2820.3662,6.7950493,0
19165866.2,,5905,57.9388,57.946,0.009,9.2E-6,57.166282,0.59283685,390.59486,0.8748,667.20823,0.7742,1057.8031,0.8748,0.085258307,18.465091,0.18562136,95.814568,,,1,,,,5.7631328E-5,56.6424,3267.9838,6.8326092,0
19166536.72,,5905,62.3366,62.3642,0.009,9.2E-6,61.508463,0.59782775,429.15415,2.586,768.65432,0.8288,1197.8085,2.449,0.76156217,19.800061,,,,,1,,,,6.0495191E-5,55.40037,3783.291,6.9771562,0
19166863.8,,5905,62.3374,62.3421,0.009,9.3E-6,61.532658,0.62893659,420.2917,0.9605,769.10046,0.8291,1189.3922,0.9605,0.074374967,19.798158,0.19718031,95.778767,,,1,,,,6.0409859E-5,59.425113,3786.268,6.8303843,0
19167595.48,,5905,67.0691,67.0962,0.009,9.4E-6,66.236068,0.6806876,451.70156,0.9853,889.57481,0.9003,1341.2764,0.9853,0.13160961,21.293912,0.22994865,95.338744,,,1,,,,6.3341831E-5,65.43784,4387.2167,6.8195709,0
19168349.38,,5905,72.1651,72.1867,0.009,9.2E-6,71.253503,0.6859406,496.57626,3.002,1028.3446,0.949,1524.9209,2.848,0.51040765,22.948672,,,,,1,,,,6.6449197E-5,63.705907,5077.0617,6.9691488,0
19168744.84,,5905,72.1615,72.1698,0.009,9.4E-6,71.282672,0.72265789,483.71891,1.013,1028.999,0.9492,1512.7179,1.013,0.37229742,22.839044,0.23676237,95.407648,,,1,,,,6.6563274E-5,68.559419,5081.2194,6.7859256,0
19169571.25,,5905,77.6416,77.6698,0.009,9.3E-6,76.738004,0.7850976,519.67518,1.197,1191.2233,0.9834,1710.8985,1.197,0.078565628,24.578698,0.25707251,95.245573,,,1,,,,6.9932979E-5,75.713109,5888.7212,6.7720706,0
19170451.03,,5905,83.5358,83.5731,0.009,9.4E-6,82.555564,0.80637416,562.85205,1.658,1377.9917,1.008,1940.8438,1.658,0.18471295,27.125801,0.41277852,93.035963,,,1,,,,7.2007165E-5,73.854607,6815.4211,6.8178572,0
19170933.66,,5905,83.5378,83.5538,0.009,9.2E-6,82.587971,0.8364356,554.84824,1.101,1378.7901,1.009,1933.6383,1.101,0.56369507,26.418372,0.26737486,95.249373,,,1,,,,7.3496604E-5,79.455887,6820.773,6.7182694,0
19171844.16,,5905,89.8754,89.9245,0.009,9.3E-6,88.887386,0.89863055,597.82888,1.406,1598.3601,1.052,2196.189,1.406,0.062993865,28.408137,0.29176613,95.034614,,,1,,,,7.7610871E-5,85.797,7900.9674,6.7256886,0
19172841.41,,5905,96.7073,96.7927,0.009,9.2E-6,95.651656,0.92922386,642.69754,2.034,1851.5577,1.101,2494.2553,2.034,0.13204388,31.157306,0.48578854,92.385448,,,1,,,,8.0498682E-5,85.344142,9149.2392,6.7191471,0
19173389.75,,5905,96.6976,96.7767,0.009,9.2E-6,95.689407,0.96287972,636.48875,1.199,1852.689,1.101,2489.1777,1.199,0.50923222,30.432044,0.31444669,94.815054,,,1,,,,8.2090148E-5,91.532403,9156.4626,6.6516115,0
19174455.55,,5905,104.041,104.123,0.009,9.2E-6,102.97968,1.0419121,679.93502,1.296,2141.0076,1.166,2820.9426,1.296,0.38192786,32.700314,0.35823849,94.311971,,,1,,,,8.6572154E-5,99.657548,10604.814,6.6026134,0
19175516.08,,5905,111.936,112.062,0.009,9.3E-6,110.81775,1.0702723,726.30544,2.473,2461.6501,1.308,3187.9555,2.473,0.16845942,35.483254,0.57384269,91.50547,,,1,,,,9.0284004E-5,97.558494,12280.573,6.5540535,0
19176131.17,,5905,111.936,112.053,0.009,9.2E-6,110.861,1.1080474,718.36653,1.456,2463.079,1.308,3181.4455,1.456,0.44011959,34.725704,0.35810554,94.397317,,,1,,,,9.189658E-5,104.17506,12290.162,6.4798849,0
19177297.17,,5905,120.433,120.56,0.009,9.2E-6,119.31997,1.1998457,765.56179,1.486,2821.1151,1.339,3586.6769,1.486,0.56035066,36.698545,0.32258778,95.001815,,,1,,,,9.7969834E-5,113.34814,14237.255,6.4160408,0
19178451.64,,5905,129.585,129.687,0.009,9.4E-6,128.36106,1.2355632,825.7717,2.705,3217.2384,1.337,4043.0101,2.705,0.19846046,39.772712,0.69862839,90.164893,,,1,,,,0.00010212374,110.67771,16476.563,6.4331946,0
19179093.08,,5905,129.583,129.662,0.009,9.3E-6,128.41216,1.2717204,813.63578,2.128,3219.0537,1.338,4032.6894,2.128,0.069879191,38.729523,0.36538623,94.440954,,,1,,,,0.00010437631,116.84604,16489.682,6.3361274,0
19180321.8,,5905,139.414,139.53,0.009,9.4E-6,138.23771,1.3825599,850.00894,1.559,3662.2631,1.509,4512.2721,1.559,1.5657445,40.704405,0.37946085,94.229251,,,1,,,,0.00011109782,125.26317,19109.663,6.1488936,0
19181386.84,,5905,150.015,150.116,0.009,9.4E-6,148.70324,1.4294066,919.46466,3.348,4131.0794,1.528,5050.5441,3.348,0.24906242,43.546263,0.81903915,88.699844,,,1,,,,0.00011648026,122.36876,22112.654,6.1832187,0
19182085.64,,5905,149.998,150.112,0.009,9.3E-6,148.76669,1.4669164,920.97249,2.588,4133.3862,1.528,5054.3587,2.588,0.066397625,42.56567,0.39034634,94.179967,,,1,,,,0.0001189885,127.79295,22131.529,6.1907169,0
19183109.08,,5905,149.993,150.124,0.009,9.2E-6,148.80461,1.4650248,915.72433,1.771,4135.1123,1.528,5050.8367,1.771,0.35388835,42.51467,0.38901957,94.170846,,,1,,,,0.00011904617,127.32654,22142.812,6.1538707,0
19184108.5,,5905,152.055,152.16,0.009,9.3E-6,150.81012,1.4708158,936.76655,4.01,4224.6419,1.515,5161.4084,4.01,0.15243153,43.73589,0.81797462,88.733265,,,1,,,,0.00011851615,127.01732,22743.693,6.2115629,0
19184853.31,,5905,152.039,152.155,0.009,9.3E-6,150.84597,1.4866375,899.83087,1.611,4225.7628,1.515,5125.5937,1.611,2.2644617,42.412241,0.33018497,94.879463,,,1,,,,0.00012105435,127.99122,22754.507,5.9652297,0
19185821.34,,5905,154.089,154.19,0.009,9.4E-6,152.8921,1.5180804,918.62667,2.653,4316.2975,1.505,5234.9241,2.653,0.088135494,42.709435,0.28557726,95.570633,,,1,,,,0.00012274678,131.29645,23375.994,6.0083332,0
19186781.36,,5905,156.127,156.245,0.009,9.2E-6,154.88127,1.5091968,943.34531,4.009,4404.5461,1.498,5347.8914,4.009,0.12426839,43.905023,0.65950994,90.573455,,,1,,,,0.0001222064,128.423,23988.207,6.0907644,0
19187531.02,,5905,156.109,156.235,0.009,9.4E-6,154.90993,1.5157978,937.22316,1.885,4405.4993,1.498,5342.7225,1.885,0.093775734,43.073483,0.39518842,94.01331,,,1,,,,0.0001242827,128.78554,23997.088,6.0501165,0
19188508.41,,5905,158.155,158.27,0.009,9.3E-6,156.95724,1.5586214,934.86018,2.507,4495.1303,1.5,5429.9905,2.507,0.04953525,43.119652,0.3367727,94.788623,,,1,,,,0.00012613528,133.99281,24635.574,5.9561458,0
19189531.19,,5905,160.207,160.276,0.009,9.4E-6,158.92844,1.5519914,958.38345,3.433,4581.5666,1.503,5539.95,3.433,0.10200213,44.179157,0.56314755,91.77835,,,1,,,,0.0001257379,130.56386,25258.249,6.030283,0
19190240.75,,5905,160.206,160.267,0.009,9.4E-6,158.95723,1.5597206,923.91396,2.66,4582.5269,1.503,5506.4408,2.66,0.18640939,43.183328,0.30899625,95.111877,,,1,,,,0.00012769894,130.57223,25267.4,5.8123432,0
19191219.05,,5905,162.238,162.311,0.009,9.2E-6,160.98424,1.568112,954.25711,4.047,4671.0056,1.505,5625.2627,3.756,0.2202154,43.490146,,,,,1,,,,0.00012934568,134.20122,25915.926,5.927643,0
19192241.11,,5905,164.293,164.384,0.009,9.2E-6,163.02062,1.5872618,982.46992,3.101,4759.0421,1.508,5741.512,3.101,0.23633964,44.845758,0.74286063,89.476828,,,1,,,,0.00012847632,131.62534,26575.721,6.0266605,0
19193005.66,,5905,164.295,164.371,0.009,9.2E-6,163.04681,1.5753965,960.40899,3.348,4760.2782,1.508,5720.6872,2.989,0.81500925,43.660764,,,,,1,,,,0.00013102582,132.3783,26584.264,5.8903879,0
19194038.13,,5905,166.325,166.417,0.009,9.3E-6,165.08808,1.6270909,982.76801,1.771,4847.8041,1.513,5830.5721,1.771,0.39778081,44.332845,0.41504294,93.715455,,,1,,,,0.00013177105,134.58708,27254.073,5.952992,0
19195069.98,,5905,168.364,168.433,0.009,9.3E-6,167.05401,1.6149373,998.92393,3.014,4932.582,1.524,5931.506,3.014,0.36574395,45.06489,0.79615112,88.725207,,,1,,,,0.00013210439,131.74294,27907.041,5.9796467,0
19195790.97,,5905,168.349,168.424,0.009,9.3E-6,167.08227,1.6111795,976.54442,3.777,4933.9398,1.524,5910.4843,3.456,1.65054,44.145465,,,,,1,,,,0.00013388656,132.62859,27916.486,5.844692,0
19196832.17,,5905,170.405,170.469,0.009,9.4E-6,169.12307,1.6653217,998.05477,2.242,5020.9045,1.542,6018.9593,2.242,0.099744912,44.62738,0.49730326,92.513421,,,1,,,,0.00013517493,136.30451,28602.614,5.9013519,0
19197866.19,,5905,172.462,172.538,0.009,9.2E-6,171.15389,1.6519038,1018.4081,3.463,5108.2309,1.57,6126.6389,3.463,0.23218723,45.588938,0.80674789,88.604739,,,1,,,,0.00013487491,132.29833,29293.655,5.9502479,0
19198594.05,,5905,172.449,172.538,0.009,9.4E-6,171.17872,1.6443299,1007.8236,3.345,5109.2925,1.571,6117.1161,2.953,0.17562385,44.47603,,,,,1,,,,0.00013753737,133.76213,29302.154,5.887552,0
19199637.14,,5905,174.481,174.58,0.009,9.3E-6,173.22516,1.7023867,1009.5951,2.569,5196.3455,1.61,6205.9406,2.569,0.050132641,44.950406,0.43249833,93.379133,,,1,,,,0.00013832354,136.57753,30006.957,5.828224,0
19200631.94,,5905,176.533,176.595,0.009,9.3E-6,175.20258,1.6926338,1015.877,3.712,5281.1488,1.663,6297.0259,3.712,0.10599736,45.479326,0.64671742,90.441494,,,1,,,,0.00013884545,133.3814,30695.944,5.7982994,0
19201407.94,,5905,176.535,176.584,0.009,9.3E-6,175.21971,1.6764863,1015.3305,3.919,5282.0306,1.663,6297.3611,3.549,0.51982444,44.620825,,,,,1,,,,0.00014113054,133.82814,30701.946,5.7946136,0
19202408.92,,5905,178.574,178.611,0.009,9.3E-6,177.27159,1.7272596,1027.6332,2.642,5368.9784,1.733,6396.6116,2.642,0.085306299,44.826951,0.37880014,94.084653,,,1,,,,0.00014292919,136.32596,31425.215,5.7969425,0
19203452.36,,5905,180.619,180.701,0.009,9.2E-6,179.30794,1.7316855,1043.7257,3.759,5455.8579,1.816,6499.5836,3.759,0.11042278,45.664136,0.58209972,91.32103,,,1,,,,0.00014268788,135.02652,32151.337,5.8208559,0
19204184.3,,5905,180.621,180.691,0.009,9.3E-6,179.32741,1.7136868,1025.4435,3.619,5457.0054,1.817,6482.4489,3.13,3.5358729,44.954903,,,,,1,,,,0.00014419893,134.29389,32158.32,5.7182751,0
19205187.91,,5905,182.655,182.739,0.009,9.3E-6,181.36677,1.7402211,1046.4114,3.606,5543.4245,1.911,6589.8359,3.058,0.049225255,44.975587,,,,,1,,,,0.00014652029,137.14387,32893.904,5.7695871,0
19206236.64,,5905,184.702,184.789,0.009,9.3E-6,183.37319,1.7465634,1066.082,6.036,5628.5196,2.013,6694.6016,5.69,0.13714941,45.512049,,,,,1,,,,0.00014709515,136.12371,33625.726,5.813729,0
19206971.56,,5905,184.688,184.778,0.009,9.3E-6,183.41848,1.7842733,1029.0827,3.497,5629.7365,2.014,6658.8191,3.497,0.11092321,44.872342,0.23569599,96.12814,,,1,,,,0.00014853824,136.37783,33642.341,5.6105722,0
19208020.59,,5905,186.739,186.782,0.009,9.3E-6,185.3973,1.7742446,1062.8517,4.654,5714.088,2.121,6776.9397,4.142,0.65936077,45.157492,,,,,1,,,,0.00015007343,137.38709,34372.158,5.7328327,0
19209070.23,,5905,188.784,188.858,0.009,9.2E-6,187.44509,1.8004964,1076.7456,3.664,5800.5994,2.235,6877.345,3.664,0.37186322,46.272801,0.84879634,87.728371,,,1,,,,0.00014914525,135.89395,35135.663,5.7443254,0
19209857.66,,5905,188.764,188.859,0.009,9.3E-6,187.47806,1.8068845,1052.4788,2.416,5801.6483,2.237,6854.1271,2.416,0.50577338,45.336866,0.38693055,93.820165,,,1,,,,0.00015141903,135.25815,35148.025,5.613877,0
19210911.06,,5905,190.838,190.89,0.009,9.3E-6,189.49911,1.8077228,1086.2527,4.521,5887.4677,2.351,6973.7205,3.861,0.5704161,45.258309,,,,,1,,,,0.00015408707,137.78834,35909.913,5.7322312,0
19211956.72,,5905,192.861,192.936,0.009,9.2E-6,191.50864,1.8251623,1076.4687,4.279,5972.199,2.464,7048.6677,4.279,0.062204257,45.828152,0.58514642,90.98034,,,1,,,,0.00015416675,134.70261,36675.56,5.620993,0
19212740.39,,5905,192.847,192.926,0.009,9.3E-6,191.53135,1.8116355,1065.7262,4.705,5973.2963,2.466,7039.0226,4.007,0.83306691,44.820294,,,,,1,,,,0.0001570499,136.63833,36684.257,5.5642392,0
19213788.92,,5905,194.895,194.932,0.009,9.3E-6,193.52473,1.8301952,1059.5051,4.388,6057.6072,2.575,7117.1123,3.553,0.23355353,44.959459,,,,,1,,,,0.00015830067,135.96258,37451.819,5.474779,0
19214838.33,,5905,196.941,196.969,0.009,9.3E-6,195.54567,1.8486288,1075.7325,6.998,6143.3666,2.684,7219.0991,6.462,0.25206325,45.689309,,,,,1,,,,0.00015800412,135.9695,38238.108,5.5011829,0
19215623.3,,5905,196.942,196.957,0.009,9.3E-6,195.5817,1.8885109,1053.2883,3.07,6144.3782,2.686,7197.6665,3.07,0.24559593,45.514471,0.38489103,93.64242,,,1,,,,0.00015837206,136.67971,38252.2,5.3854135,0
19216630.92,,5905,198.991,199.049,0.009,9.4E-6,197.64766,1.8688108,1076.4799,4.703,6232.9255,2.809,7309.4055,3.773,0.048824745,45.168417,,,,,1,,,,0.00016182558,136.7063,39064.596,5.4464593,0
19217680.88,,5905,201.029,201.092,0.009,9.3E-6,199.66082,1.9013011,1082.8953,4.167,6319.1281,2.936,7402.0234,4.167,0.26129799,46.349776,0.87527323,86.790011,,,1,,,,0.00016022952,135.5339,39864.442,5.4236745,0
19218419.39,,5905,201.029,201.089,0.009,9.3E-6,199.68092,1.8826134,1092.8538,5.127,6320.0905,2.938,7412.9443,4.201,0.13872344,45.432564,,,,,1,,,,0.00016316368,135.66195,39872.469,5.4730006,0
19219428.02,,5905,203.054,203.134,0.009,9.3E-6,201.72561,1.9180974,1078.2532,4.301,6407.6985,3.072,7485.9518,3.011,0.048624386,45.37215,,,,,1,,,,0.00016499002,138.121,40693.221,5.3451481,0
19220482.64,,5905,205.117,205.134,0.009,9.2E-6,203.69484,1.9116778,1103.4526,6.929,6492.2362,3.203,7595.6887,6.145,0.30973658,45.636414,,,,,1,,,,0.00016643921,136.15015,41491.59,5.4171845,0
19221215.7,,5905,205.097,205.15,0.009,9.4E-6,203.71597,1.9184782,1074.1713,4.919,6493.154,3.204,7567.3252,3.732,0.21458553,45.232817,,,,,1,,,,0.00016729723,135.78522,41500.197,5.2728869,0
19222268.77,,5905,207.143,207.19,0.009,9.3E-6,205.74748,1.9444583,1090.2818,4.662,6579.9682,3.336,7670.25,3.257,0.41525085,45.334838,,,,,1,,,,0.00016919107,137.1897,42332.024,5.2991258,0
19223321.23,,5905,209.166,209.277,0.009,9.2E-6,207.79173,1.9490068,1098.9344,7.168,6667.0077,3.464,7765.942,6.275,0.28855502,45.580204,,,,,1,,,,0.00017037971,136.47343,43177.404,5.2886337,0
19224104.73,,5905,209.202,209.253,0.009,9.2E-6,207.81797,1.955102,1086.6927,4.883,6668.0888,3.466,7754.7815,3.44,0.61988238,45.278445,,,,,1,,,,0.00017126873,136.18113,43188.307,5.2290605,0
19248307.8,,5905,205.001,205.106,0.009,9.3E-6,203.61684,1.9143537,1088.0726,4.404,6488.8272,3.197,7576.8998,3.029,0.090003086,45.163553,,,,,1,,,,0.00016776581,136.17298,41459.817,5.3437262,0
19249318.44,,5905,207.378,207.45,0.009,9.3E-6,205.96951,1.9427956,1113.7356,4.348,6589.4467,3.351,7703.1823,4.348,0.72788943,46.342056,0.99474255,85.116731,,,1,,,,0.0001668454,135.0977,42423.441,5.4072838,0
19250103.34,,5905,207.358,207.462,0.009,9.2E-6,205.99732,1.9286889,1071.0272,5.125,6590.608,3.352,7661.6352,3.876,0.97065895,44.86658,,,,,1,,,,0.00017076486,135.43167,42434.895,5.1992287,0
19251116.63,,5905,209.734,209.825,0.009,9.3E-6,208.36972,1.9638648,1098.5651,5.076,6691.3167,3.499,7789.8818,3.678,0.061411363,45.029343,,,,,1,,,,0.00017299568,138.2842,43417.942,5.2721914,0
19252174.86,,5905,212.112,212.18,0.009,9.3E-6,210.70115,1.9865499,1110.1429,4.589,6789.425,3.629,7899.5678,4.589,0.42285892,45.992985,0.79346315,87.438619,,,1,,,,0.00017225181,135.53983,44394.976,5.2688029,0
19252911.34,,5905,212.11,212.197,0.009,9.3E-6,210.72562,1.9721832,1096.2593,5.313,6790.5621,3.63,7886.8215,3.879,0.039438766,45.110979,,,,,1,,,,0.00017483153,135.87307,44405.286,5.2023068,0
19253976.66,,5905,214.474,214.509,0.009,9.2E-6,213.04143,2.0016692,1126.6279,6.133,6886.7872,3.741,8013.4151,4.859,0.55018717,45.207736,,,,,1,,,,0.00017725761,137.81123,45386.65,5.2883043,0
19254987.92,,5905,216.841,216.924,0.009,9.4E-6,215.41139,2.0020957,1128.1696,7.789,6983.8062,3.83,8111.9759,6.782,0.12060423,45.559181,,,,,1,,,,0.00017805359,134.97386,46402.065,5.2372794,0
19255766.28,,5905,216.841,216.911,0.009,9.2E-6,215.44474,2.0105744,1129.1793,5.948,6985.0522,3.831,8114.2315,4.549,2.2621486,45.111451,,,,,1,,,,0.00017987077,136.05191,46416.434,5.241155,0
19256829.89,,5905,219.205,219.286,0.009,9.2E-6,217.8001,2.0330065,1150.7887,6.397,7079.7712,3.889,8230.5599,5.08,0.51239285,45.195106,,,,,1,,,,0.00018211175,136.49924,47436.883,5.2836923,0
19257888.84,,5905,221.567,221.664,0.009,9.3E-6,220.1302,2.0434455,1168.114,7.998,7172.8015,3.912,8340.9155,6.977,0.9983966,45.624082,,,,,1,,,,0.00018281826,135.32002,48457.307,5.3064686,0
19258669.45,,5905,221.596,221.656,0.009,9.3E-6,220.16789,2.0460577,1160.6968,6.15,7174.2243,3.912,8334.9211,4.746,0.9554853,45.124924,,,,,1,,,,0.0001847077,135.51325,48473.902,5.2718714,0
19259731.23,,5905,223.944,223.99,0.009,9.2E-6,222.4732,2.0684053,1183.4152,6.114,7265.3259,3.908,8448.7411,4.702,0.21209621,45.091754,,,,,1,,,,0.00018736777,136.07709,49494.325,5.3193606,0
19260791.97,,5905,226.318,226.344,0.009,9.4E-6,224.8075,2.0752718,1206.8838,9.235,7356.8079,3.883,8563.6917,8.379,0.43106869,45.477613,,,,,1,,,,0.00018830565,134.96578,50538.412,5.3685211,0
19261570.7,,5905,226.317,226.339,0.009,9.4E-6,224.83953,2.0866772,1172.0651,5.441,7357.9941,3.883,8530.0592,3.812,0.28418194,44.901745,,,,,1,,,,0.00018997166,135.44478,50552.815,5.212896,0
19262584.66,,5905,228.699,228.743,0.009,9.3E-6,227.24091,2.1215061,1198.65,4.965,7450.8122,3.843,8649.4623,3.144,0.032796026,44.932623,,,,,1,,,,0.00019249849,138.0866,51638.432,5.2747986,0
19263588.77,,5905,231.052,231.127,0.009,9.4E-6,229.55384,2.1121063,1213.8322,11.18,7539.378,3.799,8753.2102,10.52,0.52859233,45.249738,,,,,1,,,,0.00019344223,133.94347,52694.966,5.2877888,0
19264364.89,,5905,231.063,231.109,0.009,9.2E-6,229.59052,2.1221902,1193.1286,5.414,7540.6578,3.799,8733.7864,3.857,0.24316571,44.736642,,,,,1,,,,0.00019522669,134.97526,52711.808,5.1967678,0
19265371.17,,5905,233.413,233.483,0.009,9.3E-6,231.95455,2.1539671,1192.9705,5.771,7629.7108,3.755,8822.6813,4.382,0.069282987,44.744792,,,,,1,,,,0.00019717784,135.75175,53802.912,5.143122,0
19266420.64,,5905,235.776,235.817,0.009,9.3E-6,234.23104,2.154714,1208.7643,7.027,7714.1909,3.721,8922.9553,5.962,0.41468089,44.972965,,,,,1,,,,0.00019840709,133.69102,54864.182,5.1605641,0
19267189.92,,5905,235.785,235.797,0.009,9.4E-6,234.25934,2.1583061,1180.4778,5.478,7715.1516,3.72,8895.6294,4.021,0.40565552,44.421524,,,,,1,,,,0.00020025494,133.43203,54877.44,5.039192,0
19268239.86,,5905,238.164,238.159,0.009,9.2E-6,236.6202,2.193804,1195.0253,5.21,7801.1438,3.7,8996.1692,3.668,0.10338294,44.576994,,,,,1,,,,0.00020181193,134.62535,55989.121,5.0503943,0
19269245.17,,5905,240.523,240.565,0.009,9.3E-6,238.99209,2.1947769,1220.838,9.945,7885.8729,3.702,9106.7109,9.23,0.21316741,44.642697,,,,,1,,,,0.00020399106,133.41704,57117.221,5.1082777,0
19269916.94,,5905,240.524,240.552,0.009,9.3E-6,239.02276,2.1975324,1192.7026,6.151,7886.9537,3.702,9079.6563,4.912,0.063541266,44.230617,,,,,1,,,,0.00020527989,132.5165,57131.88,4.9899123,0
19270920.47,,5905,242.884,242.948,0.009,9.2E-6,241.3931,2.2293756,1182.4628,5.114,7969.743,3.734,9152.2058,3.495,0.016590469,44.021223,,,,,1,,,,0.0002079044,133.66519,58270.629,4.8984946,0
19271960.3,,5905,245.264,245.316,0.009,9.2E-6,243.71934,2.2311182,1223.7381,8.957,8049.3968,3.794,9273.1349,8.114,0.50992797,44.257333,,,,,1,,,,0.00020952765,132.23252,59399.119,5.0210955,0
19272672.31,,5905,245.271,245.311,0.009,9.2E-6,243.75459,2.2402091,1215.4632,5.018,8050.5959,3.795,9266.0591,3.283,0.053256785,44.149055,,,,,1,,,,0.00020988125,131.66852,59416.298,4.9864219,0
19273710.7,,5905,247.631,247.641,0.009,9.3E-6,246.06647,2.2635975,1204.6592,5.364,8128.0679,3.876,9332.7271,3.708,0.12078983,43.797694,,,,,1,,,,0.00021308718,132.09236,60548.707,4.8956659,0
19274754.72,,5905,249.998,250.018,0.009,9.3E-6,248.41014,2.2683926,1234.8778,7.149,8205.0817,3.977,9439.9595,5.94,0.15079506,43.773292,,,,,1,,,,0.00021565569,131.71139,61707.598,4.9711247,0
19275459.56,,5905,250.004,250.005,0.009,9.2E-6,248.43378,2.2682911,1209.4547,5.841,8205.8977,3.978,9415.3523,4.277,0.23708585,43.383835,,,,,1,,,,0.00021702444,130.47734,61719.341,4.8683181,0
19276507.02,,5905,250.002,250.057,0.009,9.4E-6,248.4909,2.2711685,1189.1346,5.38,8207.6844,3.98,9396.819,3.62,0.027882201,43.223864,,,,,1,,,,0.00021739886,130.98031,61747.73,4.7854249,0
19277625.36,,5905,255.557,255.617,0.009,9.4E-6,253.96175,2.3189586,1268.9177,13.52,8381.9311,4.256,9650.8488,12.83,0.35964056,43.646739,,,,,1,,,,0.00022111271,130.77107,64496.571,4.9964912,0
19278327.72,,5905,255.553,255.599,0.009,9.3E-6,254.01718,2.3234682,1193.3625,5.484,8383.6825,4.259,9577.0451,3.455,0.13773906,43.046182,,,,,1,,,,0.00022248303,129.33391,64524.728,4.6979599,0
19279440.81,,5905,261.095,261.16,0.009,9.4E-6,259.53574,2.3740631,1238.5747,6.457,8552.1401,4.54,9790.7148,4.592,0.30886323,42.682877,,,,,1,,,,0.00022938273,129.47948,67358.799,4.7722704,0
19280544.17,,5905,266.67,266.657,0.009,9.4E-6,264.98128,2.400417,1283.5119,12.12,8712.3309,4.756,9995.8427,11.15,0.34609922,42.508391,,,,,1,,,,0.00023514987,127.46174,70215.08,4.8437831,0
19281231.38,,5905,266.672,266.65,0.009,9.3E-6,265.022,2.4058189,1262.1388,8.383,8713.5953,4.757,9975.7341,6.902,0.24609185,42.318274,,,,,1,,,,0.00023573112,126.29138,70236.661,4.7623926,0
19282286.27,,5905,272.226,272.259,0.009,9.2E-6,270.60848,2.4475044,1284.8355,6.784,8872.2886,4.862,10157.124,4.731,0.063873533,41.585507,,,,,1,,,,0.00024424673,125.69163,73228.951,4.7479498,0
19283327.97,,5905,277.767,277.789,0.009,9.3E-6,276.08823,2.4915529,1397.9333,6.59,9022.0553,4.898,10419.989,6.59,1.3193598,42.345878,1.4160785,77.458495,,,1,,,,0.00024740225,124.54913,76224.712,5.0633569,0
19284005.48,,5905,277.778,277.781,0.009,9.3E-6,276.14413,2.4742931,1366.015,9.222,9023.4641,4.898,10389.479,7.814,1.3148041,41.193382,,,,,1,,,,0.00025221234,123.48057,76255.582,4.9467464,0
19285090.34,,5905,283.331,283.284,0.009,9.4E-6,281.62231,2.5216641,1456.0596,15.42,9166.6758,4.881,10622.735,14.63,1.5875391,40.585316,,,,,1,,,,0.00026173839,124.74503,79311.125,5.1702564,0
19286162.86,,5905,288.888,288.882,0.009,9.4E-6,287.13665,2.5459117,1571.1888,7.18,9305.2025,4.809,10876.391,7.18,1.3628154,41.996081,2.4403852,67.556315,,,1,,,,0.00026174335,122.27721,82447.456,5.4719202,0
19286880.58,,5905,288.893,288.88,0.009,9.4E-6,287.21341,2.5850827,1528.5648,6.261,9306.4556,4.808,10835.02,6.261,1.1231143,40.686995,0.95644197,83.643772,,,1,,,,0.00026736327,123.40014,82491.542,5.3220525,0
19287946.39,,5905,294.45,294.367,0.009,9.3E-6,292.66549,2.6052083,1472.6348,12.62,9436.8343,4.683,10909.469,11.72,1.4731672,39.769691,,,,,1,,,,0.00027431616,119.30087,85653.092,5.031802,0
19289004.5,,5905,300,299.977,0.009,9.4E-6,298.22356,2.6820525,1325.1436,9.526,9563.1991,4.502,10888.343,8.395,0.25611313,39.196654,,,,,1,,,,0.00027778756,118.58508,88937.292,4.4434573,0
19289642.63,,5905,300.006,299.964,0.009,9.2E-6,298.25996,2.6787653,1311.1806,5.922,9564.0691,4.501,10875.25,3.849,0.24942895,39.004162,,,,,1,,,,0.0002788228,116.82091,88959.004,4.3961001,0
19297349.08,,5905,269.999,270.024,0.009,9.4E-6,268.37356,2.4325696,1240.1838,5.819,8809.4845,4.831,10049.668,3.243,0.016513435,41.727654,,,,,1,,,,0.00024083952,125.77616,72024.366,4.6211105,0
19298421.2,,5905,280.012,280.013,0.009,9.2E-6,278.24925,2.5107012,1470.7403,8.544,9079.5337,4.898,10550.274,8.544,0.59722435,42.663331,1.9684639,71.904045,,,1,,,,0.00024926075,125.99946,77422.643,5.2856938,0
19299054.28,,5905,279.994,280.007,0.009,9.3E-6,278.31792,2.4865538,1382.1565,8.505,9081.0834,4.898,10463.24,6.953,0.071201319,40.884168,,,,,1,,,,0.000255924,122.91174,77460.863,4.9661066,0
19300177.19,,5905,289.994,289.936,0.009,9.2E-6,288.22652,2.6239022,1548.9581,6.671,9331.2822,4.789,10880.24,6.671,1.0186871,41.243801,1.4740145,77.138472,,,1,,,,0.00026544674,126.11685,83074.529,5.3740999,0
19301221.36,,5905,300.008,300.004,0.009,9.3E-6,298.19726,2.7241739,1369.6034,12.54,9562.5584,4.503,10932.162,11.7,0.20028893,39.645113,,,,,1,,,,0.00027575055,122.65993,88921.607,4.5929443,0
19301821.52,,5905,299.978,299.984,0.009,9.3E-6,298.24355,2.6757511,1296.5158,5.868,9563.6819,4.501,10860.198,3.765,0.024309051,38.866647,,,,,1,,,,0.00027942203,116.90349,88949.215,4.3471714,0