File: TGA/PDC_LDFZ_20200720_1_217_(PTF1_20200715)-SMB_TGA_underO2.txt
CLOSED
Version	2.0
Language	English
Run	1
RunSerial	456
Instrument	SDT Q600 V20.9 Build 20
Module	DSC-TGA Standard
InstSerial	0600-1830
Operator	SMB
File	\\Q600dtadsc\ta\Data\PARADIM-2023\20230726-SMB\PDC_LDFZ_20200720_1_217_(PTF1_20200715)-SMB_TGA_underO2.002
Sample	PDC_LDFZ_20200720_1_217-SMBb
Size	15.8000	mg
ProcName	Oxide oxygen deficiency
Method	Oxide oxygen deficiency
Comment	Ground BiWO6 under O2 for mass gain
Xcomment	Pan: Alumina
Xcomment	Gas1: Nitrogen 100.0 ml/min
Xcomment	Gas2: Nitrogen 0.0 ml/min
Text	Ground BiWO6 under O2 for mass gain 15 mg, torched pans
Exotherm	Up
Kcell	1.07500
InstCalDate	Weight: 2023-07-12  Time: 10:41:45 TempRange 200.02 to 998.86 °C
InstCalFile	Weight: \\Q600dtadsc\ta\Data\PARADIM-2023\20230710-calibration\noweightcalibration.dav
InstCalDate	Heat Flow: 2022-08-03  Time: 16:54:07 TempRange 200.04 to 1387.92 °C
InstCalFile	Heat Flow: \\Q600dtadsc\ta\Data\PARADIM_2022\calibration\no-weight-calib-20220802.003 \\Q600dtadsc\ta\Data\PARADIM_2022\calibration\no-weight-calib-20220802.004InstCalDate DTA Baseline: 2022-11-17  Time: 16:00:32 TempRange 52.92 to 1473.93 °C
InstCalFile	DTA Baseline: \\Q600dtadsc\ta\Data\PARADIM_2022\calibration\no-weight-DTA-calib-20221028.001
TempCal	0	pts
Controls	Gas 1  Event OFF  Sampling 0.5 sec/pt
AutoAnalysis	Off
MacroFile
Nsig	7
Sig1	Time (min)
Sig2	Temperature (°C)
Sig3	Weight (mg)
Sig4	Heat Flow (mW)
Sig5	Temperature Difference (°C)
Sig6	Temperature Difference (µV)
Sig7	Sample Purge Flow (mL/min)
Date	2023-07-26
Time	19:52:59
OrgMethod	1: Data storage On
OrgMethod	2: Ramp 10.00 °C/min to 300.00 °C
OrgMethod	3: Isothermal for 60.00 min
OrgMethod	4: Ramp 2.00 °C/min to 1000.00 °C
OrgMethod	5: Isothermal for 240.00 min
OrgMethod	6: Data storage Off
OrgMethod	7: Jump to 20.00 °C
OrgFile	C:\TA\Data\PARADIM-2023\20230726-SMB\PDC_LDFZ_20200720_1_217_(PTF1_20200715)-SMB_TGA_underO2.002
StartOfData
7.77778E-4	265.2631	15.80019	77.81750	4.385644	38.62384	100.0027
0.8416668	264.3030	15.78850	70.55842	3.865825	33.99328	99.97858
1.700000	277.0870	15.78153	66.69226	3.416805	30.37631	99.97489
2.558334	286.8734	15.77827	63.85754	3.102222	27.80664	99.95414
3.416667	294.2146	15.77589	60.26067	2.779102	25.05592	99.95384
4.275000	299.7286	15.77553	57.70718	2.555392	23.14368	100.0161
5.133333	299.7598	15.77613	54.90562	2.370257	21.47002	100.0010
5.991668	299.4869	15.77571	52.42554	2.208868	20.00297	99.92558
6.850000	300.2697	15.77514	51.09660	2.114940	19.16360	100.0830
7.708332	300.9194	15.77499	50.21128	2.051704	18.59975	100.0062
8.566666	301.1624	15.77484	49.36642	1.994378	18.08346	100.0549
9.425000	301.3123	15.77460	48.62859	1.944830	17.63613	100.0333
10.28333	301.4630	15.77456	48.03406	1.904730	17.27443	100.0137
11.14166	301.5685	15.77451	47.54138	1.871663	16.97588	100.0076
12.00000	301.6242	15.77458	47.11992	1.843632	16.72234	100.0268
12.85417	301.6600	15.77451	46.75754	1.819620	16.50498	99.99549
13.71250	301.6842	15.77458	46.44683	1.799081	16.31899	99.99680
14.56667	301.6951	15.77442	46.17772	1.781361	16.15839	100.0426
15.42500	301.7023	15.77458	45.94918	1.766326	16.02208	99.99188
16.28333	301.7097	15.77464	45.75842	1.753769	15.90828	100.0167
17.14167	301.7070	15.77466	45.58746	1.742577	15.80670	99.98519
18.00000	301.7038	15.77477	45.44530	1.733276	15.72233	99.98257
18.85833	301.7042	15.77482	45.32135	1.725148	15.64861	99.95601
19.71666	301.7016	15.77498	45.21220	1.718004	15.58374	99.94678
20.57500	301.6962	15.77519	45.11723	1.711815	15.52758	100.0301
21.43333	301.6970	15.77517	45.04210	1.706881	15.48279	99.97675
22.29167	301.6947	15.77530	44.97678	1.702614	15.44406	99.99371
23.15000	301.6922	15.77534	44.91526	1.698594	15.40757	99.99244
24.00833	301.6916	15.77524	44.86361	1.695212	15.37688	100.0245
24.86667	301.6868	15.77534	44.82074	1.692432	15.35164	99.94103
25.72500	301.6855	15.77548	44.78383	1.690020	15.32973	99.97789
26.58334	301.6838	15.77542	44.75278	1.687996	15.31138	100.0292
27.43750	301.6838	15.77551	44.72054	1.685880	15.29215	99.99791
28.29584	301.6812	15.77573	44.69474	1.684206	15.27696	99.99200
29.15000	301.6824	15.77570	44.67764	1.683076	15.26671	99.98410
30.00834	301.6810	15.77575	44.66340	1.682151	15.25830	99.98726
30.86666	301.6792	15.77577	44.64546	1.680986	15.24773	100.0058
31.72500	301.6781	15.77576	44.63183	1.680100	15.23967	100.0774
32.58334	301.6791	15.77585	44.62244	1.679478	15.23404	99.99666
33.44166	301.6753	15.77591	44.60994	1.678682	15.22678	99.97704
34.30000	301.6772	15.77592	44.59936	1.677977	15.22042	100.0397
35.15833	301.6791	15.77601	44.59071	1.677397	15.21516	100.0471
36.01666	301.6754	15.77595	44.58384	1.676970	15.21126	99.98311
36.87500	301.6752	15.77600	44.57802	1.676589	15.20779	99.97312
37.73334	301.6774	15.77608	44.57395	1.676309	15.20528	99.97711
38.59167	301.6758	15.77611	44.56908	1.676000	15.20246	99.94009
39.45000	301.6736	15.77606	44.56436	1.675703	15.19974	99.94593
40.30834	301.6702	15.77605	44.56217	1.675583	15.19863	100.0440
41.16667	301.6753	15.77617	44.56250	1.675573	15.19861	100.0375
42.02083	301.6759	15.77612	44.56104	1.675472	15.19767	99.99597
42.87916	301.6719	15.77620	44.55538	1.675127	15.19452	100.0088
43.73334	301.6678	15.77602	44.55214	1.674941	15.19278	100.0424
44.59167	301.6744	15.77618	44.55216	1.674898	15.19244	99.93954
45.45000	301.6736	15.77602	44.55576	1.675140	15.19464	99.98514
46.30834	301.6707	15.77612	44.55418	1.675054	15.19381	99.94369
47.16667	301.6751	15.77612	44.55090	1.674811	15.19164	100.0551
48.02500	301.6733	15.77610	44.54950	1.674731	15.19091	99.97098
48.88333	301.6740	15.77609	44.54722	1.674579	15.18955	99.97820
49.74166	301.6730	15.77613	44.55043	1.674794	15.19149	99.97887
50.60000	301.6770	15.77595	44.55614	1.675143	15.19467	100.0071
51.45834	301.6705	15.77600	44.54852	1.674686	15.19048	99.99030
52.31666	301.6765	15.77599	44.55008	1.674748	15.19110	99.97599
53.17500	301.6775	15.77602	44.54706	1.674545	15.18929	100.0341
54.03332	301.6762	15.77592	44.54546	1.674447	15.18837	100.0316
54.89166	301.6754	15.77583	44.54146	1.674191	15.18604	100.0834
55.75000	301.6744	15.77586	44.54223	1.674247	15.18654	100.0566
56.60418	301.6713	15.77585	44.54310	1.674326	15.18725	100.0037
57.46250	301.6730	15.77587	44.54490	1.674432	15.18821	99.99244
58.31666	301.6784	15.77576	44.54644	1.674497	15.18885	100.0381
59.17500	301.6748	15.77575	44.54167	1.674208	15.18619	100.0080
60.03332	301.6755	15.77552	44.54033	1.674116	15.18536	100.0117
60.89166	301.6728	15.77568	44.53350	1.673685	15.18144	99.96996
61.75000	301.6702	15.77567	44.53188	1.673598	15.18062	99.99601
62.60832	301.6764	15.77558	44.52776	1.673286	15.17785	100.0226
63.46668	301.6747	15.77548	44.52684	1.673236	15.17736	99.98842
64.32500	302.2387	15.77516	44.56859	1.672344	15.17486	99.98016
65.18334	304.0604	15.77424	44.93705	1.684810	15.30802	100.0205
66.04166	305.9373	15.77380	45.27471	1.694834	15.42042	99.96576
66.90000	307.5822	15.77327	45.40435	1.692822	15.42068	100.0096
67.75832	309.2467	15.77302	45.50436	1.688821	15.40289	99.96880
68.61668	310.9724	15.77246	45.63836	1.686666	15.40256	100.0409
69.47500	312.6958	15.77175	45.77374	1.684662	15.40356	100.0018
70.33332	314.4005	15.77145	45.89748	1.682087	15.39912	100.0208
71.18750	316.0998	15.77110	46.01877	1.679446	15.39393	99.99988
72.04582	317.8196	15.77055	46.14383	1.676976	15.39044	99.99934
72.90000	319.5244	15.77009	46.26269	1.674278	15.38470	100.0322
73.75832	321.2284	15.76974	46.37918	1.671600	15.37814	99.94394
74.61668	322.9425	15.76926	46.49481	1.668929	15.37125	100.0163
75.47500	324.6546	15.76875	46.60960	1.666294	15.36463	99.98266
76.33332	326.3622	15.76838	46.72436	1.663761	15.35886	99.99618
77.19166	328.0735	15.76772	46.83980	1.661327	15.35399	100.0087
78.05000	329.7838	15.76728	46.94781	1.658534	15.34572	99.98731
78.90832	331.5020	15.76700	47.05604	1.655798	15.33799	99.92905
79.76668	333.2102	15.76647	47.16058	1.652988	15.32944	100.0115
80.62500	334.9170	15.76599	47.25738	1.649821	15.31749	100.0192
81.48334	336.6302	15.76532	47.35660	1.646862	15.30746	100.0466
82.34168	338.3421	15.76514	47.44694	1.643489	15.29351	100.0816
83.20000	340.0510	15.76454	47.53457	1.640084	15.27915	99.93704
84.05834	341.7606	15.76416	47.62094	1.636806	15.26502	100.0082
84.91666	343.4712	15.76383	47.70496	1.633506	15.25065	100.0564
85.77084	345.1726	15.76331	47.77791	1.629723	15.23156	99.99749
86.62916	346.8841	15.76286	47.85600	1.626312	15.21601	99.99988
87.48334	348.5816	15.76244	47.93125	1.622926	15.20049	100.0336
88.34168	350.2911	15.76201	47.99863	1.619155	15.18138	100.0078
89.20000	352.0022	15.76170	48.06504	1.615458	15.16292	99.93728
90.05834	353.7100	15.76119	48.12119	1.611325	15.14026	100.0438
90.91666	355.4200	15.76084	48.17564	1.607226	15.11783	99.99186
91.77500	357.1302	15.76032	48.23296	1.603423	15.09812	99.99488
92.63334	358.8364	15.76006	48.28087	1.599257	15.07490	99.99125
93.49168	360.5482	15.75950	48.32562	1.595061	15.05109	100.0466
94.35001	362.2614	15.75910	48.36802	1.590945	15.02734	100.0071
95.20832	363.9664	15.75865	48.41198	1.587094	15.00595	99.93614
96.06666	365.6742	15.75835	48.44630	1.582855	14.98084	99.96048
96.92500	367.3814	15.75797	48.47940	1.578701	14.95644	100.0234
97.78332	369.0891	15.75763	48.51050	1.574590	14.93239	99.99563
98.64168	370.8045	15.75710	48.54594	1.570841	14.91174	99.95309
99.50000	372.5115	15.75678	48.56854	1.566582	14.88610	100.0031
100.3542	374.2102	15.75636	48.58438	1.562157	14.85875	100.0085
101.2125	375.9181	15.75605	48.60090	1.557895	14.83294	100.0025
102.0667	377.6198	15.75560	48.61270	1.553559	14.80628	99.98444
102.9250	379.3276	15.75529	48.62328	1.549312	14.78047	99.98038
103.7833	381.0384	15.75497	48.62816	1.544965	14.75321	99.91351
104.6417	382.7452	15.75452	48.62778	1.540548	14.72484	100.0732
105.5000	384.4550	15.75409	48.61940	1.535880	14.69402	100.0263
106.3584	386.1602	15.75361	48.60970	1.531335	14.66428	100.0416
107.2166	387.8714	15.75334	48.59508	1.526689	14.63352	100.0573
108.0750	389.5794	15.75288	48.57163	1.521763	14.59994	99.97499
108.9334	391.2866	15.75264	48.55168	1.517208	14.56987	99.99681
109.7916	392.9938	15.75205	48.52356	1.512408	14.53735	99.99156
110.6500	394.7036	15.75180	48.49025	1.507517	14.50389	99.99516
111.5084	396.4153	15.75147	48.45492	1.502698	14.47102	99.96992
112.3667	398.1249	15.75103	48.41230	1.497702	14.43639	100.0437
113.2250	399.8300	15.75073	48.37359	1.493085	14.40524	100.0399
114.0833	401.5373	15.75036	48.32926	1.488423	14.37312	100.0383
114.9375	403.2400	15.74992	48.27862	1.483637	14.33960	99.99018
115.7958	404.9480	15.74958	48.21866	1.478564	14.30325	99.99612
116.6500	406.6462	15.74907	48.16142	1.473814	14.26988	99.94669
117.5084	408.3570	15.74872	48.10025	1.469030	14.23620	99.95666
118.3667	410.0634	15.74842	48.03528	1.464226	14.20217	99.95366
119.2250	411.7734	15.74809	47.97774	1.459954	14.17327	99.95220
120.0833	413.4797	15.74774	47.90839	1.455284	14.14043	100.0226
120.9416	415.1865	15.74741	47.83043	1.450357	14.10500	99.97753
121.8000	416.8975	15.74698	47.75218	1.445568	14.07083	100.0129
122.6584	418.6076	15.74669	47.66722	1.440621	14.03505	100.0255
123.5167	420.3142	15.74629	47.57570	1.435523	13.99764	99.97574
124.3750	422.0224	15.74584	47.48261	1.430545	13.96104	100.0107
125.2334	423.7300	15.74572	47.39462	1.425961	13.92819	100.0392
126.0916	425.4394	15.74545	47.30356	1.421385	13.89537	99.99650
126.9500	427.1465	15.74498	47.20512	1.416610	13.86050	100.0559
127.8084	428.8553	15.74453	47.10567	1.411930	13.82649	99.95968
128.6666	430.5671	15.74418	46.99936	1.407068	13.79063	100.0309
129.5208	432.2624	15.74400	46.90300	1.402834	13.76077	100.0016
130.3792	433.9720	15.74376	46.79169	1.398027	13.72528	99.99894
131.2334	435.6714	15.74341	46.67563	1.393138	13.68884	99.98684
132.0917	437.3781	15.74308	46.55598	1.388222	13.65211	100.0258
132.9500	439.0877	15.74275	46.43544	1.383401	13.61626	99.98332
133.8084	440.7956	15.74250	46.31064	1.378533	13.57964	100.0345
134.6666	442.5062	15.74214	46.18487	1.373779	13.54384	100.0372
135.5250	444.2148	15.74178	46.06228	1.369310	13.51079	99.94701
136.3833	445.9214	15.74153	45.93204	1.364610	13.47534	100.0187
137.2417	447.6308	15.74112	45.80348	1.360130	13.44205	100.0090
138.1000	449.3377	15.74098	45.67024	1.355541	13.40756	99.93842
138.9583	451.0438	15.74060	45.53581	1.351018	13.37364	100.0072
139.8166	452.7568	15.74016	45.39682	1.346413	13.33888	99.97972
140.6750	454.4637	15.73993	45.25350	1.341736	13.30332	99.97492
141.5333	456.1758	15.73970	45.10916	1.337119	13.26828	99.99434
142.3916	457.8810	15.73927	44.95688	1.332258	13.23072	100.0118
143.2500	459.5902	15.73897	44.80705	1.327630	13.19542	100.0081
144.1042	461.2924	15.73877	44.65507	1.323026	13.16002	100.0030
144.9625	462.9972	15.73854	44.49754	1.318295	13.12321	100.0117
145.8166	464.6969	15.73830	44.34381	1.313836	13.08901	100.0385
146.6750	466.4040	15.73795	44.18100	1.309084	13.05186	100.0097
147.5333	468.1135	15.73752	44.02124	1.304575	13.01706	100.0152
148.3916	469.8234	15.73730	43.86484	1.300324	12.98478	99.97081
149.2500	471.5320	15.73697	43.70391	1.295961	12.95130	99.93664
150.1084	473.2412	15.73679	43.53701	1.291433	12.91610	99.96941
150.9667	474.9502	15.73648	43.36978	1.286993	12.88174	100.0340
151.8250	476.6600	15.73614	43.21179	1.283054	12.85230	99.95508
152.6834	478.3652	15.73588	43.04304	1.278728	12.81892	100.0855
153.5416	480.0754	15.73558	42.86641	1.274151	12.78296	99.96109
154.4000	481.7840	15.73517	42.69347	1.269832	12.74943	99.94030
155.2583	483.4930	15.73506	42.51666	1.265428	12.71496	100.0507
156.1167	485.2050	15.73481	42.33468	1.260886	12.67905	99.97601
156.9750	486.9091	15.73454	42.15598	1.256571	12.64534	99.93391
157.8333	488.6197	15.73421	41.97572	1.252278	12.61180	100.0121
158.6875	490.3211	15.73391	41.79717	1.248115	12.57944	99.97098
159.5458	492.0262	15.73364	41.61088	1.243702	12.54454	99.98442
160.4000	493.7322	15.73342	41.43585	1.239865	12.51537	100.0364
161.2583	495.4374	15.73298	41.25053	1.235656	12.48240	99.98132
162.1167	497.1484	15.73301	41.07450	1.231930	12.45425	99.98319
162.9750	498.8536	15.73260	40.89094	1.227939	12.42336	100.0006
163.8333	500.5684	15.73238	40.70140	1.223783	12.39075	100.0203
164.6916	502.2761	15.73215	40.52094	1.220086	12.36263	100.0350
165.5500	503.9824	15.73192	40.33920	1.216398	12.33453	99.97687
166.4083	505.6926	15.73168	40.15049	1.212481	12.30407	100.0302
167.2666	507.4038	15.73133	39.96036	1.208575	12.27367	99.94566
168.1250	509.1127	15.73105	39.76836	1.204647	12.24297	99.98046
168.9834	510.8191	15.73101	39.57947	1.200916	12.21420	100.0475
169.8417	512.5284	15.73070	39.38794	1.197141	12.18494	100.0201
170.7000	514.2484	15.73042	39.19792	1.193527	12.15733	99.93182
171.5583	515.9804	15.73014	39.00048	1.189684	12.12736	99.98204
172.4166	517.7044	15.73001	38.80771	1.186091	12.09987	100.0341
173.2708	519.4234	15.72974	38.61390	1.182504	12.07236	99.99152
174.1292	521.1466	15.72946	38.41844	1.178933	12.04486	100.0161
174.9834	522.8661	15.72918	38.23336	1.175865	12.02236	100.0263
175.8417	524.5919	15.72912	38.03882	1.172474	11.99653	99.99941
176.7000	526.3155	15.72889	37.83778	1.168854	11.96830	99.91246
177.5583	528.0421	15.72842	37.63706	1.165323	11.94094	100.0768
178.4166	529.7675	15.72838	37.43580	1.161825	11.91387	99.99092
179.2750	531.4942	15.72815	37.22708	1.158058	11.88396	99.98275
180.1333	533.2186	15.72788	37.02738	1.154747	11.85871	99.97699
180.9917	534.9413	15.72773	36.81910	1.151115	11.83008	100.0498
181.8500	536.6708	15.72737	36.62409	1.148126	11.80803	100.0439
182.7083	538.3940	15.72720	36.42603	1.145052	11.78506	100.0421
183.5666	540.1207	15.72688	36.21668	1.141558	11.75770	99.94803
184.4250	541.8447	15.72678	36.00732	1.138126	11.73084	99.93874
185.2834	543.5707	15.72660	35.81034	1.135283	11.71002	99.93516
186.1416	545.2988	15.72637	35.60808	1.132269	11.68739	100.0168
187.0000	547.0211	15.72615	35.40816	1.129400	11.66620	99.96332
187.8542	548.7406	15.72588	35.21039	1.126657	11.64624	99.97720
188.7125	550.4665	15.72586	35.01316	1.124018	11.62734	99.96509
189.5666	552.1853	15.72564	34.80644	1.120996	11.60442	99.95141
190.4250	553.9084	15.72516	34.60212	1.118164	11.58346	100.0096
191.2834	555.6349	15.72498	34.40520	1.115681	11.56605	100.0204
192.1416	557.3606	15.72488	34.20400	1.113085	11.54745	99.95875
193.0000	559.0879	15.72454	34.00247	1.110518	11.52911	100.0312
193.8584	560.8164	15.72439	33.80336	1.108126	11.51250	100.0165
194.7167	562.5394	15.72418	33.59384	1.105330	11.49151	99.98028
195.5750	564.2662	15.72397	33.38819	1.102754	11.47278	100.0152
196.4333	565.9941	15.72356	33.18576	1.100366	11.45598	100.0066
197.2916	567.7211	15.72349	32.97369	1.097623	11.43545	99.93785
198.1500	569.4426	15.72330	32.77346	1.095412	11.42040	99.99947
199.0083	571.1722	15.72325	32.56138	1.092762	11.40077	99.96772
199.8667	572.8958	15.72294	32.35726	1.090481	11.38493	99.96606
200.7250	574.6240	15.72257	32.15096	1.088175	11.36882	100.0385
201.5833	576.3500	15.72254	31.94513	1.085922	11.35320	99.97285
202.4375	578.0683	15.72230	31.74097	1.083750	11.33837	99.97566
203.2958	579.7945	15.72217	31.53238	1.081472	11.32245	99.99966
204.1500	581.5132	15.72181	31.32564	1.079295	11.30744	100.0128
205.0083	583.2402	15.72176	31.11793	1.077152	11.29278	100.0272
205.8667	584.9682	15.72146	30.90420	1.074801	11.27589	100.0502
206.7250	586.6930	15.72140	30.68648	1.072313	11.25754	100.0442
207.5833	588.4188	15.72114	30.46999	1.069918	11.24011	99.95551
208.4417	590.1438	15.72116	30.25528	1.067647	11.22398	100.0087
209.3000	591.8720	15.72085	30.03793	1.065307	11.20708	100.0578
210.1584	593.5985	15.72069	29.81627	1.062827	11.18868	99.93586
211.0166	595.3226	15.72056	29.59282	1.060300	11.16973	100.0316
211.8750	597.0497	15.72042	29.35926	1.057392	11.14673	100.0544
212.7334	598.7754	15.72019	29.13485	1.054910	11.12820	100.0188
213.5917	600.5012	15.72001	28.90124	1.052084	11.10590	100.0076
214.4500	602.2258	15.71985	28.67345	1.049551	11.08640	99.92795
215.3083	603.9503	15.71952	28.43404	1.046586	11.06231	100.0140
216.1666	605.6782	15.71972	28.19664	1.043730	11.03933	99.99695
217.0208	607.3966	15.71911	27.95935	1.040879	11.01633	99.97272
217.8792	609.1230	15.71914	27.72232	1.038101	10.99409	99.99422
218.7334	610.8416	15.71902	27.48128	1.035148	10.96993	99.99155
219.5917	612.5684	15.71878	27.24373	1.032397	10.94791	99.97686
220.4500	614.2920	15.71872	27.00072	1.029442	10.92368	100.0479
221.3083	616.0150	15.71854	26.76260	1.026711	10.90178	100.0196
222.1666	617.7450	15.71837	26.51791	1.023737	10.87727	99.95734
223.0250	619.4710	15.71822	26.26932	1.020613	10.85113	100.0396
223.8833	621.1952	15.71796	26.02613	1.017598	10.82742	99.96743
224.7417	622.9239	15.71798	25.77911	1.014390	10.80233	99.92601
225.6000	624.6443	15.71784	25.52330	1.010792	10.77300	99.95910
226.4583	626.3699	15.71744	25.27877	1.007702	10.74904	100.0839
227.3167	628.0980	15.71726	25.03247	1.004560	10.72449	100.0058
228.1750	629.8168	15.71731	24.78354	1.001286	10.69842	100.0519
229.0334	631.5479	15.71713	24.52724	0.9977422	10.66946	99.94811
229.8916	633.2755	15.71697	24.27222	0.9942561	10.64105	99.97818
230.7500	634.9980	15.71694	24.01914	0.9908349	10.61325	100.0324
231.6042	636.7134	15.71650	23.77530	0.9877816	10.58930	99.99751
232.4625	638.4402	15.71651	23.52860	0.9846600	10.56461	100.0117
233.3167	640.1564	15.71646	23.27322	0.9811188	10.53526	100.0532
234.1750	641.8858	15.71635	23.02764	0.9781469	10.51106	100.0437
235.0334	643.6084	15.71611	22.78340	0.9752087	10.48715	100.0112
235.8916	645.3328	15.71595	22.54103	0.9723422	10.46397	100.0245
236.7500	647.0609	15.71586	22.29224	0.9692025	10.43780	100.0457
237.6084	648.7865	15.71575	22.05317	0.9664770	10.41606	100.0430
238.4667	650.5124	15.71557	21.81447	0.9637618	10.39438	99.98392
239.3250	652.2379	15.71536	21.57536	0.9610116	10.37228	100.0149
240.1833	653.9618	15.71546	21.34203	0.9584985	10.35269	100.0222
241.0416	655.6910	15.71538	21.10725	0.9559234	10.33241	99.99324
241.9000	657.4165	15.71506	20.86797	0.9531232	10.30963	100.0469
242.7583	659.1440	15.71501	20.62923	0.9503445	10.28706	100.0076
243.6167	660.8688	15.71494	20.39210	0.9476093	10.26491	99.96460
244.4750	662.5947	15.71464	20.15766	0.9449684	10.24373	99.96753
245.3333	664.3213	15.71456	19.91249	0.9418574	10.21742	99.94812
246.1875	666.0356	15.71448	19.67025	0.9387926	10.19151	100.0134
247.0458	667.7639	15.71450	19.42815	0.9357672	10.16604	100.0385
247.9000	669.4775	15.71438	19.18901	0.9327899	10.14098	100.0166
248.7583	671.2032	15.71435	18.95335	0.9299826	10.11777	100.0439
249.6167	672.9306	15.71424	18.70970	0.9268142	10.09060	99.90978
250.4750	674.6593	15.71413	18.47091	0.9238324	10.06541	99.99694
251.3333	676.3822	15.71403	18.23124	0.9207641	10.03922	100.0264
252.1917	678.1084	15.71389	17.99366	0.9177668	10.01376	100.0275
253.0500	679.8342	15.71383	17.75328	0.9146130	9.986538	100.0151
253.9084	681.5582	15.71374	17.52112	0.9117828	9.962803	99.94851
254.7666	683.2855	15.71351	17.28742	0.9088569	9.937981	99.97616
255.6250	685.0102	15.71351	17.04864	0.9056756	9.910324	100.0378
256.4833	686.7331	15.71345	16.81333	0.9025968	9.883725	99.93503
257.3416	688.4636	15.71323	16.57932	0.8995659	9.857628	99.93289
258.2000	690.1881	15.71326	16.35561	0.8969239	9.835722	99.99816
259.0583	691.9142	15.71304	16.13338	0.8943219	9.814225	100.0063
259.9166	693.6368	15.71313	15.91148	0.8916840	9.792284	100.0464
260.7708	695.3569	15.71312	15.69436	0.8892024	9.772001	99.96061
261.6292	697.0832	15.71294	15.46494	0.8861600	9.745538	100.0307
262.4833	698.8028	15.71280	15.24626	0.8835249	9.723484	99.97728
263.3416	700.5280	15.71276	15.02687	0.8808380	9.700800	100.0507
264.2000	702.2553	15.71265	14.81283	0.8783695	9.680392	100.0348
265.0583	703.9801	15.71266	14.60268	0.8760196	9.661241	99.95098
265.9166	705.7086	15.71242	14.39213	0.8736241	9.641563	100.0346
266.7750	707.4347	15.71247	14.18276	0.8712299	9.621851	100.0142
267.6333	709.1597	15.71230	13.97920	0.8690528	9.604501	100.0045
268.4917	710.8848	15.71236	13.76745	0.8664765	9.582706	100.0296
269.3500	712.6113	15.71221	13.55426	0.8637974	9.559736	100.0454
270.2084	714.3340	15.71228	13.34365	0.8611906	9.537518	99.97562
271.0666	716.0632	15.71217	13.15489	0.8595459	9.525938	100.0307
271.9250	717.7921	15.71216	12.94883	0.8570880	9.505311	100.0092
272.7833	719.5172	15.71190	12.74844	0.8548414	9.486984	99.94051
273.6417	721.2426	15.71200	12.55541	0.8528900	9.471894	99.98955
274.5000	722.9712	15.71204	12.35560	0.8506158	9.453201	99.99931
275.3541	724.6874	15.71198	12.15674	0.8483132	9.434119	100.0294
276.2125	726.4162	15.71193	11.96239	0.8462215	9.417381	99.96609
277.0666	728.1344	15.71174	11.77013	0.8441626	9.400946	100.0565
277.9250	729.8584	15.71177	11.57741	0.8420742	9.384171	100.0603
278.7833	731.5859	15.71194	11.38943	0.8401916	9.369676	99.95122
279.6417	733.3136	15.71182	11.20957	0.8386493	9.358941	100.0503
280.5000	735.0388	15.71168	11.01956	0.8366195	9.342742	100.0400
281.3583	736.7682	15.71169	10.82828	0.8345061	9.325574	99.98218
282.2166	738.4955	15.71145	10.64504	0.8327430	9.312298	99.97366
283.0750	740.2196	15.71146	10.45844	0.8307844	9.296791	100.0245
283.9333	741.9460	15.71155	10.25896	0.8282256	9.274541	100.0549
284.7916	743.6730	15.71163	10.07579	0.8263955	9.260422	99.98809
285.6500	745.3995	15.71150	9.891876	0.8245062	9.245606	100.0513
286.5083	747.1272	15.71138	9.707484	0.8225790	9.230338	99.94672
287.3667	748.8528	15.71144	9.525489	0.8207480	9.216126	99.99120
288.2250	750.5806	15.71142	9.336968	0.8185876	9.198175	99.95868
289.0834	752.3084	15.71141	9.156876	0.8168060	9.184452	99.99316
289.9375	754.0247	15.71139	8.980575	0.8151501	9.172092	99.99866
290.7959	755.7524	15.71149	8.805305	0.8135586	9.160454	99.94468
291.6500	757.4702	15.71129	8.627306	0.8117884	9.146747	99.99553
292.5083	759.1981	15.71138	8.460105	0.8105518	9.139069	100.0620
293.3667	760.9249	15.71135	8.299430	0.8096103	9.134668	100.0799
294.2250	762.6528	15.71142	8.133938	0.8084304	9.127520	100.0420
295.0834	764.3806	15.71133	7.966757	0.8071724	9.119485	99.93901
295.9416	766.1058	15.71134	7.800696	0.8059424	9.111736	100.0548
296.8000	767.8356	15.71139	7.637778	0.8048613	9.105658	100.0241
297.6583	769.5624	15.71140	7.484718	0.8042316	9.104670	99.99162
298.5167	771.2926	15.71138	7.333062	0.8036749	9.104512	99.97445
299.3750	773.0205	15.71132	7.178554	0.8029729	9.102694	99.99399
300.2333	774.7472	15.71137	7.024710	0.8022871	9.101038	100.0298
301.0916	776.4769	15.71156	6.876556	0.8018830	9.102584	99.96911
301.9500	778.2034	15.71140	6.725030	0.8013040	9.102124	99.97870
302.8083	779.9318	15.71131	6.572757	0.8006910	9.101276	99.95024
303.6666	781.6606	15.71148	6.426889	0.8003881	9.103882	99.95259
304.5209	783.3812	15.71144	6.282787	0.8001444	9.107134	99.96579
305.3792	785.1072	15.71147	6.132666	0.7996300	9.107314	99.98910
306.2333	786.8290	15.71165	5.987130	0.7993197	9.109797	99.96962
307.0916	788.5556	15.71159	5.848222	0.7993472	9.116147	99.93538
307.9500	790.2845	15.71163	5.706549	0.7992554	9.121141	100.0587
308.8083	792.0142	15.71159	5.560918	0.7989756	9.123986	100.0027
309.6666	793.7422	15.71168	5.412113	0.7985401	9.125046	99.99751
310.5250	795.4694	15.71180	5.267164	0.7982960	9.128288	99.95458
311.3833	797.1997	15.71179	5.124050	0.7981515	9.132669	100.0239
312.2417	798.9262	15.71178	4.976183	0.7977753	9.134394	99.93348
313.1000	800.6548	15.71184	4.821952	0.7970972	9.132632	99.98105
313.9584	802.3822	15.71193	4.666566	0.7963612	9.130145	100.0205
314.8166	804.1110	15.71203	4.513638	0.7957515	9.129101	99.93649
315.6750	805.8384	15.71179	4.355881	0.7949092	9.125382	100.0271
316.5333	807.5680	15.71203	4.198420	0.7940852	9.121866	100.0487
317.3917	809.2934	15.71191	4.041107	0.7932482	9.118172	99.97501
318.2500	811.0216	15.71204	3.874553	0.7919585	9.109269	100.0705
319.1041	812.7400	15.71210	3.702780	0.7903652	9.096819	99.97399
319.9625	814.4688	15.71226	3.532737	0.7888782	9.085601	100.0456
320.8166	816.1868	15.71230	3.356433	0.7870358	9.070232	99.96750
321.6750	817.9124	15.71252	3.173581	0.7848679	9.051101	99.94938
322.5333	819.6379	15.71283	2.985759	0.7824439	9.028992	99.93356
323.3917	821.3632	15.71300	2.804251	0.7803157	9.010262	100.0157
324.2500	823.0914	15.71322	2.613331	0.7776905	8.985756	100.0324
325.1083	824.8158	15.71324	2.414474	0.7746390	8.956281	99.97163
325.9666	826.5418	15.71358	2.207955	0.7711710	8.921938	100.0676
326.8250	828.2642	15.71389	1.997977	0.7674897	8.885069	100.0321
327.6833	829.9911	15.71399	1.784994	0.7636318	8.846106	99.98082
328.5416	831.7139	15.71412	1.564846	0.7593602	8.802281	99.97134
329.4000	833.4405	15.71452	1.343282	0.7549958	8.757331	99.95207
330.2583	835.1639	15.71444	1.109579	0.7499563	8.704468	100.0519
331.1167	836.8853	15.71464	0.8811770	0.7451407	8.654125	99.93409
331.9750	838.6082	15.71502	0.6386421	0.7395558	8.594774	99.96536
332.8334	840.3332	15.71521	0.4006700	0.7341668	8.537616	99.97754
333.6875	842.0468	15.71544	0.1537464	0.7282148	8.473731	100.0088
334.5459	843.7699	15.71570	-0.1028018	0.7217694	8.404056	100.0080
335.4000	845.4839	15.71574	-0.3549860	0.7154430	8.335639	99.99616
336.2583	847.2032	15.71606	-0.6264401	0.7081005	8.255310	100.0595
337.1167	848.9262	15.71649	-0.8957751	0.7008035	8.175401	100.0340
337.9750	850.6476	15.71649	-1.169998	0.6931837	8.091614	99.96691
338.8334	852.3680	15.71675	-1.462082	0.6845734	7.996148	99.94455
339.6916	854.0868	15.71706	-1.753130	0.6759374	7.900247	99.97672
340.5500	855.8062	15.71736	-2.048611	0.6669946	7.800631	100.0264
341.4083	857.5280	15.71749	-2.333896	0.6585218	7.706389	100.0341
342.2667	859.2445	15.71800	-2.630194	0.6493857	7.604249	100.0023
343.1250	860.9656	15.71817	-2.929636	0.6400157	7.499238	100.0684
343.9834	862.6842	15.71848	-3.234344	0.6302818	7.389816	100.0172
344.8416	864.4006	15.71865	-3.540649	0.6203842	7.278331	100.0057
345.7000	866.1216	15.71893	-3.851225	0.6101865	7.163181	100.0247
346.5583	867.8388	15.71924	-4.161380	0.5999271	7.047156	100.0094
347.4167	869.5562	15.71966	-4.487330	0.5887374	6.920038	100.0107
348.2709	871.2644	15.72012	-4.810184	0.5775951	6.793294	100.0162
349.1292	872.9842	15.72015	-5.132202	0.5664516	6.666398	100.0452
349.9834	874.6901	15.72055	-5.461954	0.5547632	6.532893	99.92456
350.8416	876.4106	15.72086	-5.782808	0.5435095	6.404370	99.95063
351.7000	878.1239	15.72115	-6.110978	0.5317570	6.269786	100.0534
352.5583	879.8436	15.72157	-6.451060	0.5192844	6.126543	99.98334
353.4167	881.5584	15.72178	-6.791864	0.5066826	5.981516	99.95460
354.2750	883.2736	15.72203	-7.127896	0.4942451	5.838236	100.0618
355.1333	884.9918	15.72250	-7.472766	0.4812466	5.688150	99.98348
355.9917	886.7050	15.72292	-7.819174	0.4680596	5.535642	99.93801
356.8500	888.4230	15.72305	-8.168735	0.4546234	5.380004	100.0558
357.7084	890.1338	15.72336	-8.519758	0.4410012	5.221962	100.0061
358.5666	891.8507	15.72376	-8.873819	0.4271324	5.060810	99.98951
359.4250	893.5640	15.72424	-9.223609	0.4133869	4.900911	99.94342
360.2833	895.2795	15.72470	-9.573586	0.3995498	4.739734	100.0002
361.1417	896.9951	15.72478	-9.937710	0.3848555	4.568186	100.0083
362.0000	898.7086	15.72532	-10.29183	0.3706038	4.401678	100.0676
362.8541	900.4191	15.72572	-10.64997	0.3560376	4.231230	100.0349
363.7125	902.1251	15.72640	-11.00286	0.3416503	4.062714	99.96803
364.5666	903.8352	15.72661	-11.35555	0.3271948	3.893183	99.99628
365.4250	905.5480	15.72702	-11.70677	0.3127527	3.723612	99.95599
366.2833	907.2612	15.72729	-12.07084	0.2975064	3.544247	99.99144
367.1417	908.9753	15.72819	-12.42102	0.2829447	3.372824	99.97720
368.0000	910.6901	15.72832	-12.77496	0.2680921	3.197720	99.97969
368.8584	912.4038	15.72887	-13.12350	0.2534492	3.024901	99.97222
369.7166	914.1182	15.72922	-13.47165	0.2387444	2.851132	99.98108
370.5750	915.8321	15.72942	-13.80858	0.2245790	2.683596	99.96309
371.4333	917.5474	15.72964	-14.15058	0.2100566	2.511588	100.0010
372.2917	919.2606	15.73017	-14.49305	0.1954081	2.337855	100.0225
373.1500	920.9734	15.73048	-14.82596	0.1812179	2.169383	100.0162
374.0083	922.6892	15.73077	-15.16383	0.1666808	1.996542	99.97899
374.8667	924.4038	15.73119	-15.48836	0.1527990	1.831346	100.0350
375.7250	926.1163	15.73155	-15.79537	0.1398281	1.676878	99.98884
376.5834	927.8376	15.73192	-16.04448	0.1300329	1.560336	99.99876
377.4375	929.5550	15.73210	-16.16216	0.1275518	1.531470	100.0533
378.2959	931.2853	15.73263	-16.22778	0.1279770	1.537492	100.0577
379.1500	933.0145	15.73293	-16.15595	0.1361038	1.636101	100.0079
380.0083	934.7568	15.73326	-16.00241	0.1488349	1.790213	99.99755
380.8667	936.4975	15.73346	-15.82702	0.1627867	1.959203	100.0642
381.7250	938.2381	15.73394	-15.71998	0.1728539	2.081610	99.98476
382.5834	939.9820	15.73451	-15.48849	0.1899476	2.288834	99.95438
383.4416	941.7176	15.73476	-15.43428	0.1969596	2.374740	99.93974
384.3000	943.4512	15.73524	-15.40803	0.2023532	2.441225	99.94768
385.1583	945.1858	15.73565	-15.34427	0.2098352	2.532994	99.99371
386.0167	946.9205	15.73598	-15.30564	0.2158490	2.607140	99.99116
386.8750	948.6590	15.73646	-15.21864	0.2245808	2.714224	99.97280
387.7334	950.3985	15.73677	-15.09692	0.2352548	2.844920	100.0019
388.5916	952.1344	15.73712	-14.99486	0.2447706	2.961755	99.98797
389.4500	953.8759	15.73755	-14.86826	0.2556514	3.095255	99.98828
390.3083	955.6155	15.73802	-14.71248	0.2681645	3.248688	100.0486
391.1667	957.3572	15.73827	-14.53940	0.2816292	3.413836	100.0625
392.0209	959.0918	15.73863	-14.36240	0.2952680	3.581282	99.98436
392.8792	960.8332	15.73909	-14.20510	0.3077563	3.734960	99.94731
393.7334	962.5616	15.73933	-14.11068	0.3165738	3.844210	100.0628
394.5916	964.2966	15.73984	-14.07413	0.3220285	3.912734	100.0294
395.4500	966.0311	15.74022	-14.04388	0.3270651	3.976250	99.96756
396.3083	967.7606	15.74058	-14.02871	0.3311716	4.028520	99.99882
397.1667	969.4931	15.74105	-14.02637	0.3344806	4.071143	99.98528
398.0250	971.2211	15.74136	-14.06016	0.3356406	4.087638	99.94320
398.8833	972.9508	15.74194	-14.12134	0.3351540	4.084085	99.99265
399.7417	974.6789	15.74234	-14.18966	0.3341794	4.074571	99.98347
400.6000	976.4062	15.74274	-14.26589	0.3326785	4.058624	100.0034
401.4584	978.1340	15.74312	-14.33994	0.3312276	4.043266	99.96562
402.3166	979.8586	15.74350	-14.41662	0.3295453	4.025058	100.0335
403.1750	981.5882	15.74405	-14.49706	0.3275718	4.003270	99.96246
404.0333	983.3149	15.74447	-14.57684	0.3255554	3.980926	100.0478
404.8917	985.0394	15.74480	-14.67138	0.3226065	3.947146	99.98902
405.7500	986.7632	15.74532	-14.76847	0.3194278	3.910509	99.96164
406.6041	988.4801	15.74572	-14.86091	0.3164248	3.875970	99.96192
407.4625	990.2062	15.74629	-14.96344	0.3127622	3.833313	99.99268
408.3166	991.9239	15.74657	-15.06006	0.3093484	3.793648	100.0302
409.1750	993.6464	15.74720	-15.17642	0.3047128	3.738949	100.0062
410.0333	995.3708	15.74766	-15.29562	0.2998190	3.681014	99.99769
410.8917	997.0920	15.74822	-15.41893	0.2946009	3.619026	100.0509
411.7500	998.8192	15.74839	-15.53887	0.2894916	3.558308	99.97934
412.6084	999.8568	15.74926	-15.49263	0.2933946	3.607617	99.98254
413.4666	999.9538	15.75052	-15.41086	0.2982622	3.667590	100.0596
414.3250	1000.059	15.75180	-15.37704	0.3003453	3.693335	99.98384
415.1833	1000.129	15.75298	-15.35515	0.3016968	3.710043	100.0022
416.0417	1000.180	15.75413	-15.33118	0.3031466	3.727933	100.0305
416.9000	1000.214	15.75523	-15.29645	0.3052106	3.753362	99.96618
417.7584	1000.243	15.75627	-15.26493	0.3070746	3.776318	99.95441
418.6166	1000.263	15.75721	-15.23004	0.3091285	3.801602	99.99001
419.4750	1000.279	15.75820	-15.20456	0.3106314	3.820105	100.0165
420.3334	1000.290	15.75923	-15.17856	0.3121584	3.838898	100.0106
421.1875	1000.298	15.76042	-15.15780	0.3133767	3.853890	100.0583
422.0459	1000.305	15.76147	-15.13011	0.3149980	3.873839	100.0165
422.9000	1000.310	15.76247	-15.10035	0.3167383	3.895247	100.0258
423.7584	1000.314	15.76365	-15.07104	0.3184490	3.916290	99.99649
424.6166	1000.316	15.76464	-15.04062	0.3202269	3.938158	99.99150
425.4750	1000.320	15.76571	-15.01442	0.3217581	3.956994	100.0166
426.3334	1000.322	15.76670	-14.99576	0.3228458	3.970371	99.99518
427.1916	1000.323	15.76760	-14.98897	0.3232445	3.975278	100.0018
428.0500	1000.326	15.76861	-14.97324	0.3241643	3.986593	100.0072
428.9083	1000.328	15.76945	-14.94984	0.3255298	4.003388	100.0323
429.7667	1000.328	15.77041	-14.92263	0.3271148	4.022878	99.95207
430.6250	1000.328	15.77138	-14.90631	0.3280691	4.034619	100.0191
431.4834	1000.329	15.77234	-14.89517	0.3287183	4.042602	99.99122
432.3416	1000.330	15.77335	-14.87779	0.3297320	4.055070	99.99181
433.2000	1000.334	15.77418	-14.85762	0.3309070	4.069522	100.0048
434.0583	1000.332	15.77524	-14.84450	0.3316764	4.078987	99.99379
434.9167	1000.334	15.77617	-14.82600	0.3327556	4.092261	99.99852
435.7709	1000.334	15.77707	-14.81475	0.3334112	4.100324	99.97079
436.6292	1000.334	15.77805	-14.80644	0.3338951	4.106274	99.98895
437.4834	1000.334	15.77887	-14.79445	0.3345945	4.114876	99.99100
438.3416	1000.336	15.77981	-14.78278	0.3352785	4.123291	99.99004
439.2000	1000.337	15.78072	-14.76975	0.3360351	4.132594	99.98349
440.0583	1000.339	15.78146	-14.75224	0.3370575	4.145170	99.99368
440.9167	1000.338	15.78239	-14.73736	0.3379266	4.155859	100.0196
441.7750	1000.339	15.78328	-14.72558	0.3386138	4.164311	100.0253
442.6334	1000.339	15.78410	-14.71500	0.3392310	4.171902	99.99704
443.4916	1000.341	15.78495	-14.70112	0.3400396	4.181848	100.0040
444.3500	1000.340	15.78588	-14.69155	0.3405981	4.188715	99.99951
445.2084	1000.341	15.78659	-14.68288	0.3411042	4.194942	100.0009
446.0666	1000.341	15.78743	-14.67871	0.3413490	4.197953	100.0112
446.9250	1000.342	15.78833	-14.67002	0.3418543	4.204167	99.98707
447.7833	1000.344	15.78904	-14.66416	0.3421979	4.208395	99.99211
448.6417	1000.343	15.78981	-14.65669	0.3426340	4.213759	99.98218
449.5000	1000.341	15.79056	-14.65370	0.3428059	4.215870	99.99413
450.3541	1000.344	15.79134	-14.64815	0.3431312	4.219874	100.0106
451.2125	1000.343	15.79211	-14.64006	0.3436028	4.225674	100.0082
452.0666	1000.342	15.79292	-14.63962	0.3436272	4.225970	99.96991
452.9250	1000.344	15.79362	-14.63182	0.3440850	4.231602	99.98655
453.7833	1000.346	15.79442	-14.62647	0.3443962	4.235432	99.99564
454.6417	1000.345	15.79503	-14.61957	0.3448008	4.240408	100.0115
455.5000	1000.346	15.79568	-14.61345	0.3451575	4.244797	99.99100
456.3584	1000.345	15.79646	-14.61209	0.3452345	4.245741	99.99640
457.2166	1000.347	15.79714	-14.59952	0.3459690	4.254778	100.0022
458.0750	1000.348	15.79786	-14.59110	0.3464622	4.260844	100.0021
458.9333	1000.346	15.79847	-14.58599	0.3467580	4.264480	100.0025
459.7917	1000.347	15.79914	-14.57488	0.3474054	4.272442	99.97665
460.6500	1000.349	15.79990	-14.56552	0.3479538	4.279190	100.0267
461.5084	1000.348	15.80054	-14.55622	0.3484966	4.285866	99.98371
462.3666	1000.348	15.80112	-14.54953	0.3488855	4.290646	99.99276
463.2250	1000.349	15.80180	-14.53926	0.3494859	4.298032	100.0166
464.0834	1000.348	15.80244	-14.53789	0.3495648	4.299002	99.97366
464.9375	1000.348	15.80304	-14.53226	0.3498936	4.303046	99.97062
465.7959	1000.351	15.80374	-14.53007	0.3500226	4.304634	99.97853
466.6500	1000.351	15.80431	-14.53048	0.3499972	4.304321	100.0122
467.5084	1000.350	15.80483	-14.52725	0.3501862	4.306646	100.0293
468.3666	1000.350	15.80538	-14.51790	0.3507324	4.313364	99.99734
469.2250	1000.350	15.80601	-14.51240	0.3510544	4.317325	99.99684
470.0834	1000.353	15.80658	-14.50405	0.3515380	4.323272	99.99140
470.9416	1000.351	15.80719	-14.49984	0.3517842	4.326300	100.0326
471.8000	1000.351	15.80769	-14.49398	0.3521288	4.330540	100.0130
472.6583	1000.352	15.80824	-14.48866	0.3524381	4.334343	99.98301
473.5167	1000.353	15.80880	-14.48449	0.3526804	4.337324	99.98382
474.3750	1000.350	15.80929	-14.48325	0.3527520	4.338201	100.0191
475.2334	1000.352	15.80943	-14.48734	0.3525152	4.335292	99.99395
476.0916	1000.352	15.80996	-14.48692	0.3525386	4.335579	99.99626
476.9500	1000.354	15.81052	-14.48417	0.3527002	4.337568	99.99819
477.8083	1000.353	15.81101	-14.47591	0.3531820	4.343492	100.0412
478.6667	1000.354	15.81164	-14.47512	0.3532274	4.344050	100.0337
479.5209	1000.354	15.81206	-14.47014	0.3535161	4.347602	99.97332
480.3792	1000.354	15.81264	-14.46431	0.3538578	4.351803	100.0166
481.2334	1000.354	15.81323	-14.45831	0.3542088	4.356123	100.0019
482.0916	1000.353	15.81369	-14.45561	0.3543657	4.358051	99.99441
482.9500	1000.354	15.81423	-14.45170	0.3545929	4.360844	99.96369
483.8083	1000.354	15.81460	-14.44674	0.3548838	4.364424	99.97780
484.6667	1000.354	15.81505	-14.45066	0.3546542	4.361600	100.0220
485.5250	1000.356	15.81559	-14.44283	0.3551098	4.367203	100.0030
486.3834	1000.356	15.81608	-14.43768	0.3554124	4.370926	99.96119
487.2416	1000.356	15.81642	-14.43156	0.3557720	4.375351	100.0385
488.1000	1000.355	15.81682	-14.43207	0.3557376	4.374924	99.96512
488.9584	1000.356	15.81729	-14.43361	0.3556484	4.373828	100.0375
489.8166	1000.356	15.81779	-14.43545	0.3555428	4.372530	100.0247
490.6750	1000.356	15.81822	-14.43582	0.3555212	4.372265	99.97306
491.5333	1000.355	15.81852	-14.43298	0.3556888	4.374328	100.0369
492.3917	1000.354	15.81900	-14.43179	0.3557552	4.375140	99.98697
493.2500	1000.357	15.81932	-14.42474	0.3561680	4.380222	100.0307
494.1041	1000.358	15.81978	-14.41852	0.3565312	4.384689	99.99792
494.9625	1000.358	15.82009	-14.41750	0.3565902	4.385414	99.96961
495.8166	1000.358	15.82046	-14.41605	0.3566763	4.386474	100.0248
496.6750	1000.357	15.82090	-14.41642	0.3566528	4.386183	99.98806
497.5333	1000.355	15.82120	-14.40929	0.3570703	4.391317	99.97068
498.3917	1000.358	15.82162	-14.41027	0.3570144	4.390633	100.0002
499.2500	1000.356	15.82202	-14.40951	0.3570571	4.391156	99.97606
500.1084	1000.356	15.82236	-14.40579	0.3572728	4.393808	99.98758
500.9666	1000.356	15.82278	-14.40615	0.3572510	4.393538	99.99712
501.8250	1000.359	15.82314	-14.39839	0.3577050	4.399125	100.0022
502.6833	1000.359	15.82338	-14.40086	0.3575617	4.397363	100.0496
503.5417	1000.357	15.82380	-14.39972	0.3576275	4.398170	99.96734
504.4000	1000.358	15.82407	-14.39308	0.3580159	4.402948	99.94368
505.2584	1000.360	15.82437	-14.38855	0.3582790	4.406187	99.99028
506.1166	1000.356	15.82478	-14.38864	0.3582730	4.406109	100.0077
506.9750	1000.359	15.82515	-14.38444	0.3585190	4.409136	99.98700
507.8334	1000.359	15.82532	-14.37527	0.3590530	4.415703	100.0413
508.6875	1000.360	15.82565	-14.37700	0.3589528	4.414470	100.0211
509.5459	1000.358	15.82598	-14.38306	0.3586006	4.410141	100.0046
510.4000	1000.358	15.82620	-14.38038	0.3587570	4.412063	99.98944
511.2584	1000.360	15.82641	-14.37984	0.3587872	4.412436	99.98398
512.1167	1000.360	15.82681	-14.37703	0.3589534	4.414481	99.95344
512.9750	1000.362	15.82698	-14.38090	0.3587263	4.411689	100.0013
513.8334	1000.360	15.82714	-14.37811	0.3588892	4.413692	99.98606
514.6916	1000.357	15.82756	-14.37354	0.3591558	4.416968	100.0262
515.5500	1000.361	15.82790	-14.37273	0.3592029	4.417550	100.0019
516.4083	1000.359	15.82818	-14.37028	0.3593450	4.419296	100.0372
517.2666	1000.359	15.82832	-14.36818	0.3594676	4.420804	100.0032
518.1250	1000.362	15.82851	-14.36383	0.3597220	4.423934	99.98507
518.9834	1000.360	15.82870	-14.36377	0.3597269	4.423994	99.98641
519.8417	1000.363	15.82887	-14.35202	0.3604090	4.432382	99.98986
520.7000	1000.362	15.82907	-14.34300	0.3609400	4.438916	99.99278
521.5584	1000.362	15.82939	-14.33728	0.3612700	4.442972	99.94978
522.4167	1000.361	15.82952	-14.33808	0.3612240	4.442407	100.0250
523.2708	1000.362	15.82986	-14.34296	0.3609415	4.438934	99.97684
524.1291	1000.359	15.82994	-14.34575	0.3607773	4.436912	100.0328
524.9834	1000.361	15.83028	-14.34834	0.3606254	4.435044	99.97343
525.8418	1000.359	15.83044	-14.34850	0.3606157	4.434924	100.0151
526.7000	1000.362	15.83070	-14.34717	0.3606931	4.435877	99.99718
527.5584	1000.359	15.83079	-14.34442	0.3608533	4.437846	100.0065
528.4168	1000.360	15.83119	-14.33936	0.3611488	4.441481	99.99266
529.2750	1000.362	15.83126	-14.33328	0.3615048	4.445862	100.0165
530.1332	1000.361	15.83161	-14.32777	0.3618250	4.449799	100.0051
530.9918	1000.361	15.83162	-14.32581	0.3619415	4.451232	99.98292
531.8500	1000.363	15.83189	-14.32404	0.3620420	4.452466	99.98994
532.7084	1000.361	15.83212	-14.32544	0.3619615	4.451477	99.99109
533.5666	1000.363	15.83221	-14.32628	0.3619141	4.450898	99.99109
534.4250	1000.364	15.83234	-14.32378	0.3620609	4.452702	99.98504
535.2832	1000.363	15.83249	-14.32170	0.3621810	4.454180	99.96201
536.1416	1000.362	15.83264	-14.32791	0.3618187	4.449722	99.97772
537.0000	1000.364	15.83276	-14.32252	0.3621344	4.453606	100.0562
537.8542	1000.364	15.83299	-14.32025	0.3622650	4.455212	99.97076
538.7125	1000.363	15.83317	-14.31673	0.3624704	4.457736	99.96332
539.5666	1000.361	15.83325	-14.31224	0.3627319	4.460952	99.99744
540.4250	1000.362	15.83335	-14.31301	0.3626882	4.460417	99.98791
541.2832	1000.360	15.83357	-14.31506	0.3625660	4.458909	100.0064
542.1416	1000.361	15.83383	-14.31813	0.3623874	4.456714	100.0764
543.0000	1000.363	15.83389	-14.31060	0.3628274	4.462128	99.99176
543.8584	1000.364	15.83404	-14.30597	0.3630969	4.465442	100.0234
544.7168	1000.363	15.83417	-14.30324	0.3632575	4.467418	100.0078
545.5750	1000.364	15.83438	-14.30770	0.3629968	4.464211	99.99624
546.4334	1000.362	15.83453	-14.30801	0.3629796	4.464000	100.0362
547.2918	1000.362	15.83459	-14.31156	0.3627710	4.461434	100.0162
548.1500	1000.363	15.83479	-14.31186	0.3627542	4.461230	99.99101
549.0082	1000.363	15.83486	-14.30542	0.3631314	4.465868	100.0211
549.8668	1000.362	15.83495	-14.30874	0.3629344	4.463440	99.99524
550.7250	1000.362	15.83485	-14.30301	0.3632713	4.467588	99.98569
551.5834	1000.364	15.83521	-14.30983	0.3628726	4.462684	99.98174
552.4375	1000.362	15.83523	-14.30990	0.3628685	4.462633	99.95890
553.2959	1000.362	15.83528	-14.30630	0.3630765	4.465190	100.0154
554.1500	1000.362	15.83550	-14.30673	0.3630540	4.464914	100.0101
555.0082	1000.361	15.83569	-14.30581	0.3631083	4.465583	99.97969
555.8668	1000.363	15.83564	-14.30732	0.3630167	4.464454	99.95909
556.7250	1000.362	15.83578	-14.30332	0.3632531	4.467364	100.0539
557.5834	1000.362	15.83585	-14.29900	0.3635042	4.470451	100.0141
558.4416	1000.363	15.83599	-14.29428	0.3637812	4.473860	100.0003
559.3000	1000.366	15.83610	-14.29366	0.3638174	4.474308	99.99243
560.1582	1000.364	15.83619	-14.28960	0.3640520	4.477188	100.0137
561.0166	1000.364	15.83622	-14.29593	0.3636843	4.472668	100.0260
561.8750	1000.364	15.83639	-14.29687	0.3636300	4.472000	100.0069
562.7334	1000.364	15.83630	-14.29323	0.3638433	4.474625	99.98955
563.5918	1000.363	15.83644	-14.28945	0.3640613	4.477304	100.0014
564.4500	1000.364	15.83651	-14.28430	0.3643621	4.481004	100.0341
565.3084	1000.366	15.83652	-14.27992	0.3646183	4.484156	100.0322
566.1668	1000.367	15.83680	-14.28168	0.3645172	4.482916	100.0087
567.0208	1000.364	15.83672	-14.28090	0.3645613	4.483455	100.0198
567.8791	1000.366	15.83684	-14.27508	0.3648995	4.487614	100.0280
568.7334	1000.364	15.83692	-14.27938	0.3646480	4.484519	99.99756
569.5918	1000.364	15.83710	-14.28165	0.3645160	4.482895	99.99609
570.4500	1000.362	15.83716	-14.27979	0.3646236	4.484218	100.0264
571.3084	1000.366	15.83718	-14.27551	0.3648763	4.487330	99.99676
572.1668	1000.366	15.83722	-14.27419	0.3649530	4.488274	100.0051
573.0250	1000.366	15.83731	-14.27022	0.3651828	4.491098	100.0328
573.8832	1000.364	15.83744	-14.26850	0.3652848	4.492354	100.0293
574.7418	1000.365	15.83741	-14.26353	0.3655735	4.495903	100.0141
575.6000	1000.366	15.83749	-14.26318	0.3655957	4.496178	100.0314
576.4584	1000.365	15.83751	-14.25876	0.3658526	4.499336	100.0131
577.3166	1000.366	15.83742	-14.25592	0.3660183	4.501375	100.0650
578.1750	1000.367	15.83760	-14.26080	0.3657349	4.497891	100.0159
579.0332	1000.366	15.83760	-14.26142	0.3656977	4.497433	99.99395
579.8916	1000.367	15.83766	-14.25744	0.3659291	4.500278	100.0074
580.7500	1000.367	15.83776	-14.25561	0.3660372	4.501609	100.0079
581.6042	1000.366	15.83768	-14.25052	0.3663335	4.505252	99.97894
582.4625	1000.368	15.83781	-14.24934	0.3664026	4.506104	100.0243
583.3166	1000.364	15.83779	-14.25181	0.3662570	4.504308	100.0103
584.1750	1000.366	15.83778	-14.25496	0.3660761	4.502089	100.0113
585.0332	1000.366	15.83792	-14.26051	0.3657498	4.498071	99.97430
585.8916	1000.366	15.83788	-14.25341	0.3661648	4.503176	100.0021
586.7500	1000.367	15.83799	-14.25145	0.3662802	4.504598	100.0288
587.6084	1000.366	15.83782	-14.24096	0.3668936	4.512142	100.0034
588.4668	1000.367	15.83801	-14.23383	0.3673072	4.517228	100.0449
589.3250	1000.369	15.83805	-14.22813	0.3676403	4.521325	100.0216
590.1834	1000.367	15.83807	-14.23448	0.3672690	4.516758	99.99926
591.0418	1000.368	15.83811	-14.24071	0.3669068	4.512304	99.98312
591.9000	1000.363	15.83821	-14.24499	0.3666548	4.509200	100.0142
592.7582	1000.366	15.83821	-14.24057	0.3669134	4.512384	100.0124
593.6168	1000.368	15.83812	-14.24390	0.3667202	4.510010	99.99868
594.4750	1000.367	15.83804	-14.24272	0.3667880	4.510840	99.99241
595.3334	1000.368	15.83818	-14.23751	0.3670919	4.514580	100.0058
596.1875	1000.368	15.83822	-14.24045	0.3669221	4.512493	100.0028
597.0459	1000.366	15.83832	-14.24235	0.3668106	4.511120	100.0193
597.9000	1000.367	15.83833	-14.23609	0.3671760	4.515616	99.98622
598.7582	1000.369	15.83826	-14.23591	0.3671870	4.515752	99.99298
599.6168	1000.367	15.83828	-14.23376	0.3673108	4.517271	100.0482
600.4750	1000.369	15.83835	-14.22952	0.3675590	4.520326	100.0139
601.3334	1000.368	15.83836	-14.22321	0.3679274	4.524856	100.0077
602.1916	1000.368	15.83838	-14.21653	0.3683156	4.529629	100.0117
603.0500	1000.370	15.83833	-14.21166	0.3686025	4.533162	99.98218
603.9082	1000.368	15.83827	-14.21562	0.3683682	4.530276	100.0016
604.7666	1000.369	15.83842	-14.21487	0.3684146	4.530852	99.99862
605.6250	1000.368	15.83842	-14.21368	0.3684839	4.531702	100.0004
606.4834	1000.369	15.83843	-14.20931	0.3687392	4.534844	99.99901
607.3418	1000.369	15.83841	-14.21834	0.3682128	4.528370	100.0278
608.2000	1000.366	15.83841	-14.22156	0.3680215	4.526010	99.98292
609.0584	1000.370	15.83834	-14.21787	0.3682382	4.528680	100.0294
609.9168	1000.369	15.83840	-14.21626	0.3683318	4.529830	99.96961
610.7708	1000.367	15.83844	-14.21540	0.3683822	4.530450	99.96788
611.6291	1000.369	15.83839	-14.20624	0.3689172	4.537032	100.0014
612.4834	1000.370	15.83839	-14.19856	0.3693674	4.542570	100.0213
613.3418	1000.369	15.83848	-14.19727	0.3694412	4.543474	99.98816
614.2000	1000.370	15.83837	-14.19238	0.3697246	4.546960	100.0022
615.0584	1000.370	15.83844	-14.19325	0.3696765	4.546372	99.98682
615.9168	1000.367	15.83833	-14.19844	0.3693709	4.542609	100.0542
616.7750	1000.369	15.83831	-14.20762	0.3688348	4.536016	99.95768
617.6332	1000.369	15.83832	-14.20742	0.3688482	4.536182	99.99308
618.4918	1000.370	15.83848	-14.20785	0.3688256	4.535907	99.97501
619.3500	1000.369	15.83830	-14.20839	0.3687928	4.535502	100.0050
620.2084	1000.367	15.83840	-14.20426	0.3690328	4.538452	100.0472
621.0666	1000.371	15.83836	-14.19999	0.3692814	4.541511	100.0154
621.9250	1000.370	15.83837	-14.19812	0.3693920	4.542872	99.99922
622.7832	1000.370	15.83831	-14.19625	0.3695007	4.544209	99.97152
623.6416	1000.369	15.83832	-14.19766	0.3694176	4.543186	99.98725
624.5000	1000.370	15.83824	-14.20134	0.3692044	4.540566	99.95356
625.3542	1000.368	15.83823	-14.19956	0.3693066	4.541820	100.0112
626.2125	1000.370	15.83815	-14.19527	0.3695593	4.544931	100.0084
627.0666	1000.368	15.83826	-14.20086	0.3692325	4.540909	100.0201
627.9250	1000.370	15.83820	-14.20406	0.3690475	4.538635	100.0216
628.7832	1000.368	15.83805	-14.19872	0.3693551	4.542415	100.0021
629.6416	1000.371	15.83806	-14.19068	0.3698269	4.548222	99.98801
630.5000	1000.370	15.83809	-14.18419	0.3702026	4.552840	100.0090
631.3584	1000.370	15.83798	-14.18698	0.3700430	4.550880	100.0075
632.2168	1000.369	15.83801	-14.18868	0.3699400	4.549609	100.0243
633.0750	1000.371	15.83804	-14.18755	0.3700090	4.550461	99.99518
633.9334	1000.369	15.83803	-14.18320	0.3702625	4.553576	100.0141
634.7918	1000.371	15.83794	-14.18144	0.3703664	4.554859	100.0022
635.6500	1000.370	15.83786	-14.17282	0.3708666	4.561008	99.99609
636.5082	1000.371	15.83792	-14.16832	0.3711292	4.564238	100.0169
637.3668	1000.370	15.83777	-14.16369	0.3713986	4.567550	99.99766
638.2250	1000.372	15.83776	-14.16118	0.3715478	4.569387	99.97674
639.0834	1000.371	15.83782	-14.16687	0.3712137	4.565276	100.0076
639.9375	1000.370	15.83780	-14.16959	0.3710553	4.563328	99.99211
640.7959	1000.373	15.83784	-14.17426	0.3707847	4.560002	99.99412
641.6500	1000.370	15.83776	-14.17277	0.3708694	4.561042	99.99804
642.5082	1000.369	15.83770	-14.16879	0.3711030	4.563916	100.0026
643.3668	1000.371	15.83778	-14.16624	0.3712512	4.565738	99.94806
644.2250	1000.372	15.83758	-14.16629	0.3712490	4.565713	100.0104
645.0834	1000.372	15.83761	-14.16500	0.3713246	4.566643	100.0340
645.9416	1000.372	15.83759	-14.16895	0.3710925	4.563785	100.0107
646.8000	1000.370	15.83749	-14.17124	0.3709600	4.562156	99.99768
647.6582	1000.371	15.83744	-14.17244	0.3708892	4.561286	99.99231
648.5166	1000.372	15.83740	-14.16704	0.3712057	4.565181	99.99813
649.3750	1000.373	15.83737	-14.16193	0.3715045	4.568857	100.0068
650.2334	1000.371	15.83738	-14.16206	0.3714963	4.568753	100.0413
651.0918	1000.370	15.83728	-14.16425	0.3713672	4.567164	100.0011
651.9500	1000.370	15.83742	-14.16831	0.3711293	4.564238	100.0186
-1.000000	1000.370	0.0000000	0.0000000	0.0000000	0.0000000	0.0000000